Workbook

Sheet PAINEL
B2: PAINEL DE NAVEGAÇÃO
B3: Clique em um botão para ir direto à aba
B5: 🔎 GERAL
B7: ▶ BUSCA DE CUSTO | D7: ▶ EVOLUÇÃO DE CUSTOS - MP | F7: ▶ EVOLUÇÃO DE CUSTOS - PRODUTOS
B8: ▶ PARÂMETROS
B11: 🔩 PIG MANDRIL | D11: 🧽 PIG EM ESPUMA | F11: 🧪 PIGS E ACESSÓRIOS PU
B12: ▶ LBD | D12: ▶ H | F12: ▶ PU CAST
B13: ▶ LUN | D13: ▶ HS | F13: ▶ SUPERFLEX
B14: ▶ PIGS EM BORRACHA | D14: ▶ HL
B15: ▶ CORPO MANDRIL | D15: ▶ HLR | F15: 📄 OUTROS PRODUTOS
B16: ▶ ELC_MG_PC | D16: ▶ HLR X | F16: ▶ SILICONE
D17: ▶ HLR V
D18: ▶ HLR R
D19: ▶ HLB
D20: ▶ HDISC
D21: ▶ HLCC
D22: ▶ HLCC PC

Sheet BUSCA DE CUSTO
A1: ⬅ PAINEL
B2: 🔎 BUSCA DE CUSTO POR PRODUTO
B3: Selecione o produto (Família + Descrição + DN) no menu suspenso abaixo. O custo é buscado automaticamente na aba de origem — sempre atualizado.
B5: PRODUTO:
B6: PIG LUN-CP3 EPDM | Corpo completo (Eixo+Cabeçote+Nylon+Porca+Flange+Copo) | DN 6''
B8: CUSTO TOTAL (R$): | E8: CUSTO TOTAL + ALOJAMENTO (R$):
B9: =IFERROR(INDEX($F$19:$F$829,MATCH($B$6,$B$19:$B$829,0)),"Selecione um produto acima") -> 837.3 | E9: =IFERROR(IF(INDEX($H$19:$H$829,MATCH($B$6,$B$19:$B$829,0))="—","Não se aplica",INDEX($H$19:$H$829,MATCH($B$6,$B$19:$B$829,0))),"Selecione um produto acima") -> Não se aplica
B12: OBSERVAÇÃO: | E12: ESCALONADO PADRÃO (pçs): | F12: =IFERROR(INDEX($I$19:$I$829,MATCH($B$6,$B$19:$B$829,0)),"—") -> —
B13: =IFERROR(IF(INDEX($G$19:$G$829,MATCH($B$6,$B$19:$B$829,0))="","—",INDEX($G$19:$G$829,MATCH($B$6,$B$19:$B$829,0))),"—") -> — | E13: ESCALONADO PERSONALIZADO (pçs): | F13: 2
E14: CUSTO C/ ESC. PERSONALIZADO (R$): | F14: =IF(OR($F$13="",$F$13<=0),$B$9,IFERROR(INDEX($L$19:$L$829,MATCH($B$6,$B$19:$B$829,0))+INDEX($M$19:$M$829,MATCH($B$6,$B$19:$B$829,0))/$F$13,"—")) -> 777.3
B17: ÍNDICE COMPLETO DE CUSTOS (todas as abas) — pode filtrar/pesquisar livremente nesta tabela
B18: CHAVE DE BUSCA (Família + Descrição + DN) | C18: FAMÍLIA | D18: DESCRIÇÃO/VARIANTE | E18: DN | F18: CUSTO TOTAL (R$) | G18: OBSERVAÇÃO | H18: CUSTO TOTAL + ALOJAMENTO (R$) | I18: ESCALONADO PADRÃO (pçs) | J18: ESCALONADO PERSONALIZADO (pçs) | K18: CUSTO C/ ESC. PERSONALIZADO (R$) | L18: CUSTO MP (R$) | M18: CUSTO HH / CICLO (R$)
B19: PIG LUN-CP3 EPDM | Corpo completo (Eixo+Cabeçote+Nylon+Porca+Flange+Copo) | DN 6'' | C19: PIG LUN-CP3 EPDM | D19: Corpo completo (Eixo+Cabeçote+Nylon+Porca+Flange+Copo) | E19: 6'' | F19: ='PIGS EM BORRACHA'!B13 -> 837.3 | H19: — | I19: — | K19: =IF(OR($J19="",$J19<=0),$F19,$L19+$M19/$J19) -> 837.3 | L19: =$F19-$M19 -> 717.3 | M19: ='PIGS EM BORRACHA'!B12 -> 120
B20: PIG LUN-CP3 EPDM | Corpo completo (Eixo+Cabeçote+Nylon+Porca+Flange+Copo) | DN 8'' | C20: PIG LUN-CP3 EPDM | D20: Corpo completo (Eixo+Cabeçote+Nylon+Porca+Flange+Copo) | E20: 8'' | F20: ='PIGS EM BORRACHA'!C13 -> 1022.8 | H20: — | I20: — | K20: =IF(OR($J20="",$J20<=0),$F20,$L20+$M20/$J20) -> 1022.8 | L20: =$F20-$M20 -> 902.8 | M20: ='PIGS EM BORRACHA'!C12 -> 120
B21: PIG LUN-CP3 EPDM | Corpo completo (Eixo+Cabeçote+Nylon+Porca+Flange+Copo) | DN 10'' | C21: PIG LUN-CP3 EPDM | D21: Corpo completo (Eixo+Cabeçote+Nylon+Porca+Flange+Copo) | E21: 10'' | F21: ='PIGS EM BORRACHA'!D13 -> 1118.7 | H21: — | I21: — | K21: =IF(OR($J21="",$J21<=0),$F21,$L21+$M21/$J21) -> 1118.7 | L21: =$F21-$M21 -> 998.7 | M21: ='PIGS EM BORRACHA'!D12 -> 120
B22: PIG LUN-CP3 EPDM | Corpo completo (Eixo+Cabeçote+Nylon+Porca+Flange+Copo) | DN 12'' | C22: PIG LUN-CP3 EPDM | D22: Corpo completo (Eixo+Cabeçote+Nylon+Porca+Flange+Copo) | E22: 12'' | F22: ='PIGS EM BORRACHA'!E13 -> 1332.1 | H22: — | I22: — | K22: =IF(OR($J22="",$J22<=0),$F22,$L22+$M22/$J22) -> 1332.1 | L22: =$F22-$M22 -> 1212.1 | M22: ='PIGS EM BORRACHA'!E12 -> 120
B23: PIG LUN-CP3 EPDM | Corpo completo (Eixo+Cabeçote+Nylon+Porca+Flange+Copo) | DN 14'' | C23: PIG LUN-CP3 EPDM | D23: Corpo completo (Eixo+Cabeçote+Nylon+Porca+Flange+Copo) | E23: 14'' | F23: ='PIGS EM BORRACHA'!F13 -> 1656.4 | H23: — | I23: — | K23: =IF(OR($J23="",$J23<=0),$F23,$L23+$M23/$J23) -> 1656.4 | L23: =$F23-$M23 -> 1536.4 | M23: ='PIGS EM BORRACHA'!F12 -> 120
B24: PIG LUN-CP3 BUNA N | Corpo completo (Eixo+Cabeçote+Nylon+Porca+Flange+Copo) | DN 6'' | C24: PIG LUN-CP3 BUNA N | D24: Corpo completo (Eixo+Cabeçote+Nylon+Porca+Flange+Copo) | E24: 6'' | F24: ='PIGS EM BORRACHA'!B24 -> 939.3 | H24: — | I24: — | K24: =IF(OR($J24="",$J24<=0),$F24,$L24+$M24/$J24) -> 939.3 | L24: =$F24-$M24 -> 819.3 | M24: ='PIGS EM BORRACHA'!B23 -> 120
B25: PIG LUN-CP3 BUNA N | Corpo completo (Eixo+Cabeçote+Nylon+Porca+Flange+Copo) | DN 8'' | C25: PIG LUN-CP3 BUNA N | D25: Corpo completo (Eixo+Cabeçote+Nylon+Porca+Flange+Copo) | E25: 8'' | F25: ='PIGS EM BORRACHA'!C24 -> 1157.8 | H25: — | I25: — | K25: =IF(OR($J25="",$J25<=0),$F25,$L25+$M25/$J25) -> 1157.8 | L25: =$F25-$M25 -> 1037.8 | M25: ='PIGS EM BORRACHA'!C23 -> 120
B26: PIG LUN-CP3 BUNA N | Corpo completo (Eixo+Cabeçote+Nylon+Porca+Flange+Copo) | DN 10'' | C26: PIG LUN-CP3 BUNA N | D26: Corpo completo (Eixo+Cabeçote+Nylon+Porca+Flange+Copo) | E26: 10'' | F26: ='PIGS EM BORRACHA'!D24 -> 1271.7 | H26: — | I26: — | K26: =IF(OR($J26="",$J26<=0),$F26,$L26+$M26/$J26) -> 1271.7 | L26: =$F26-$M26 -> 1151.7 | M26: ='PIGS EM BORRACHA'!D23 -> 120
B27: PIG LUN-CP3 BUNA N | Corpo completo (Eixo+Cabeçote+Nylon+Porca+Flange+Copo) | DN 12'' | C27: PIG LUN-CP3 BUNA N | D27: Corpo completo (Eixo+Cabeçote+Nylon+Porca+Flange+Copo) | E27: 12'' | F27: ='PIGS EM BORRACHA'!E24 -> 1488.1 | H27: — | I27: — | K27: =IF(OR($J27="",$J27<=0),$F27,$L27+$M27/$J27) -> 1488.1 | L27: =$F27-$M27 -> 1368.1 | M27: ='PIGS EM BORRACHA'!E23 -> 120
B28: PIG LUN-CP3 BUNA N | Corpo completo (Eixo+Cabeçote+Nylon+Porca+Flange+Copo) | DN 14'' | C28: PIG LUN-CP3 BUNA N | D28: Corpo completo (Eixo+Cabeçote+Nylon+Porca+Flange+Copo) | E28: 14'' | F28: ='PIGS EM BORRACHA'!F24 -> 1836.4 | H28: — | I28: — | K28: =IF(OR($J28="",$J28<=0),$F28,$L28+$M28/$J28) -> 1836.4 | L28: =$F28-$M28 -> 1716.4 | M28: ='PIGS EM BORRACHA'!F23 -> 120
B29: PIG LUN-CP4 BUNA N | Corpo completo (Eixo+Cabeçote+Nylon+Porca+Flange+Copo) | DN 6'' | C29: PIG LUN-CP4 BUNA N | D29: Corpo completo (Eixo+Cabeçote+Nylon+Porca+Flange+Copo) | E29: 6'' | F29: ='PIGS EM BORRACHA'!B35 -> 1083.3 | H29: — | I29: — | K29: =IF(OR($J29="",$J29<=0),$F29,$L29+$M29/$J29) -> 1083.3 | L29: =$F29-$M29 -> 963.3 | M29: ='PIGS EM BORRACHA'!B34 -> 120
B30: PIG LUN-CP4 BUNA N | Corpo completo (Eixo+Cabeçote+Nylon+Porca+Flange+Copo) | DN 8'' | C30: PIG LUN-CP4 BUNA N | D30: Corpo completo (Eixo+Cabeçote+Nylon+Porca+Flange+Copo) | E30: 8'' | F30: ='PIGS EM BORRACHA'!C35 -> 1352.8 | H30: — | I30: — | K30: =IF(OR($J30="",$J30<=0),$F30,$L30+$M30/$J30) -> 1352.8 | L30: =$F30-$M30 -> 1232.8 | M30: ='PIGS EM BORRACHA'!C34 -> 120
B31: PIG LUN-CP4 BUNA N | Corpo completo (Eixo+Cabeçote+Nylon+Porca+Flange+Copo) | DN 10'' | C31: PIG LUN-CP4 BUNA N | D31: Corpo completo (Eixo+Cabeçote+Nylon+Porca+Flange+Copo) | E31: 10'' | F31: ='PIGS EM BORRACHA'!D35 -> 1491.7 | H31: — | I31: — | K31: =IF(OR($J31="",$J31<=0),$F31,$L31+$M31/$J31) -> 1491.7 | L31: =$F31-$M31 -> 1371.7 | M31: ='PIGS EM BORRACHA'!D34 -> 120
B32: PIG LUN-CP4 BUNA N | Corpo completo (Eixo+Cabeçote+Nylon+Porca+Flange+Copo) | DN 12'' | C32: PIG LUN-CP4 BUNA N | D32: Corpo completo (Eixo+Cabeçote+Nylon+Porca+Flange+Copo) | E32: 12'' | F32: ='PIGS EM BORRACHA'!E35 -> 1760.1 | H32: — | I32: — | K32: =IF(OR($J32="",$J32<=0),$F32,$L32+$M32/$J32) -> 1760.1 | L32: =$F32-$M32 -> 1640.1 | M32: ='PIGS EM BORRACHA'!E34 -> 120
B33: PIG LUN-CP4 BUNA N | Corpo completo (Eixo+Cabeçote+Nylon+Porca+Flange+Copo) | DN 14'' | C33: PIG LUN-CP4 BUNA N | D33: Corpo completo (Eixo+Cabeçote+Nylon+Porca+Flange+Copo) | E33: 14'' | F33: ='PIGS EM BORRACHA'!F35 -> 2186.4 | H33: — | I33: — | K33: =IF(OR($J33="",$J33<=0),$F33,$L33+$M33/$J33) -> 2186.4 | L33: =$F33-$M33 -> 2066.4 | M33: ='PIGS EM BORRACHA'!F34 -> 120
B34: PIG LUN-CP3 VITON | Corpo completo (Eixo+Cabeçote+Nylon+Porca+Flange+Copo) | DN 6'' | C34: PIG LUN-CP3 VITON | D34: Corpo completo (Eixo+Cabeçote+Nylon+Porca+Flange+Copo) | E34: 6'' | F34: ='PIGS EM BORRACHA'!B46 -> 3150.3 | H34: — | I34: — | K34: =IF(OR($J34="",$J34<=0),$F34,$L34+$M34/$J34) -> 3150.3 | L34: =$F34-$M34 -> 3030.3 | M34: ='PIGS EM BORRACHA'!B45 -> 120
B35: PIG LUN-CP3 VITON | Corpo completo (Eixo+Cabeçote+Nylon+Porca+Flange+Copo) | DN 8'' | C35: PIG LUN-CP3 VITON | D35: Corpo completo (Eixo+Cabeçote+Nylon+Porca+Flange+Copo) | E35: 8'' | F35: ='PIGS EM BORRACHA'!C46 -> 3812.8 | H35: — | I35: — | K35: =IF(OR($J35="",$J35<=0),$F35,$L35+$M35/$J35) -> 3812.8 | L35: =$F35-$M35 -> 3692.8 | M35: ='PIGS EM BORRACHA'!C45 -> 120
B36: PIG LUN-CP3 VITON | Corpo completo (Eixo+Cabeçote+Nylon+Porca+Flange+Copo) | DN 10'' | C36: PIG LUN-CP3 VITON | D36: Corpo completo (Eixo+Cabeçote+Nylon+Porca+Flange+Copo) | E36: 10'' | F36: ='PIGS EM BORRACHA'!D46 -> 5087.7 | H36: — | I36: — | K36: =IF(OR($J36="",$J36<=0),$F36,$L36+$M36/$J36) -> 5087.7 | L36: =$F36-$M36 -> 4967.7 | M36: ='PIGS EM BORRACHA'!D45 -> 120
B37: PIG LUN-CP3 VITON | Corpo completo (Eixo+Cabeçote+Nylon+Porca+Flange+Copo) | DN 12'' | C37: PIG LUN-CP3 VITON | D37: Corpo completo (Eixo+Cabeçote+Nylon+Porca+Flange+Copo) | E37: 12'' | F37: ='PIGS EM BORRACHA'!E46 -> 6342.1 | H37: — | I37: — | K37: =IF(OR($J37="",$J37<=0),$F37,$L37+$M37/$J37) -> 6342.1 | L37: =$F37-$M37 -> 6222.1 | M37: ='PIGS EM BORRACHA'!E45 -> 120
B38: PIG LUN-CP3 VITON | Corpo completo (Eixo+Cabeçote+Nylon+Porca+Flange+Copo) | DN 14'' | C38: PIG LUN-CP3 VITON | D38: Corpo completo (Eixo+Cabeçote+Nylon+Porca+Flange+Copo) | E38: 14'' | F38: ='PIGS EM BORRACHA'!F46 -> 7761.4 | H38: — | I38: — | K38: =IF(OR($J38="",$J38<=0),$F38,$L38+$M38/$J38) -> 7761.4 | L38: =$F38-$M38 -> 7641.4 | M38: ='PIGS EM BORRACHA'!F45 -> 120
B39: ELC (AÇO) | Produção (matéria-prima + HH) | DN 2 | C39: ELC (AÇO) | D39: Produção (matéria-prima + HH) | E39: 2 | F39: =ELC_MG_PC!J4 -> 39.47 | H39: — | I39: =ELC_MG_PC!H4 -> 1 | K39: =IF(OR($J39="",$J39<=0),$F39,$L39+$M39/$J39) -> 39.47 | L39: =$F39-ELC_MG_PC!I4 -> 39.47 | M39: =IFERROR(ELC_MG_PC!I4*ELC_MG_PC!H4,0) -> 0
B40: ELC (AÇO) | Produção (matéria-prima + HH) | DN 3 | C40: ELC (AÇO) | D40: Produção (matéria-prima + HH) | E40: 3 | F40: =ELC_MG_PC!J5 -> 44.52 | H40: — | I40: =ELC_MG_PC!H5 -> 1 | K40: =IF(OR($J40="",$J40<=0),$F40,$L40+$M40/$J40) -> 44.52 | L40: =$F40-ELC_MG_PC!I5 -> 44.52 | M40: =IFERROR(ELC_MG_PC!I5*ELC_MG_PC!H5,0) -> 0
B41: ELC (AÇO) | Produção (matéria-prima + HH) | DN 4 | C41: ELC (AÇO) | D41: Produção (matéria-prima + HH) | E41: 4 | F41: =ELC_MG_PC!J6 -> 90.22 | H41: — | I41: =ELC_MG_PC!H6 -> 1 | K41: =IF(OR($J41="",$J41<=0),$F41,$L41+$M41/$J41) -> 90.22 | L41: =$F41-ELC_MG_PC!I6 -> 90.22 | M41: =IFERROR(ELC_MG_PC!I6*ELC_MG_PC!H6,0) -> 0
B42: ELC (AÇO) | Produção (matéria-prima + HH) | DN 6 | C42: ELC (AÇO) | D42: Produção (matéria-prima + HH) | E42: 6 | F42: =ELC_MG_PC!J7 -> 195.47 | H42: — | I42: =ELC_MG_PC!H7 -> 1 | K42: =IF(OR($J42="",$J42<=0),$F42,$L42+$M42/$J42) -> 195.47 | L42: =$F42-ELC_MG_PC!I7 -> 195.47 | M42: =IFERROR(ELC_MG_PC!I7*ELC_MG_PC!H7,0) -> 0
B43: ELC (AÇO) | Produção (matéria-prima + HH) | DN 8 | C43: ELC (AÇO) | D43: Produção (matéria-prima + HH) | E43: 8 | F43: =ELC_MG_PC!J8 -> 216.86 | H43: — | I43: =ELC_MG_PC!H8 -> 1 | K43: =IF(OR($J43="",$J43<=0),$F43,$L43+$M43/$J43) -> 216.86 | L43: =$F43-ELC_MG_PC!I8 -> 16.86 | M43: =IFERROR(ELC_MG_PC!I8*ELC_MG_PC!H8,0) -> 200
B44: ELC (AÇO) | Produção (matéria-prima + HH) | DN 10 | C44: ELC (AÇO) | D44: Produção (matéria-prima + HH) | E44: 10 | F44: =ELC_MG_PC!J9 -> 245.24 | H44: — | I44: =ELC_MG_PC!H9 -> 1 | K44: =IF(OR($J44="",$J44<=0),$F44,$L44+$M44/$J44) -> 245.24 | L44: =$F44-ELC_MG_PC!I9 -> 45.24 | M44: =IFERROR(ELC_MG_PC!I9*ELC_MG_PC!H9,0) -> 200
B45: ELC (AÇO) | Produção (matéria-prima + HH) | DN 12 | C45: ELC (AÇO) | D45: Produção (matéria-prima + HH) | E45: 12 | F45: =ELC_MG_PC!J10 -> 292.75 | H45: — | I45: =ELC_MG_PC!H10 -> 1 | K45: =IF(OR($J45="",$J45<=0),$F45,$L45+$M45/$J45) -> 292.75 | L45: =$F45-ELC_MG_PC!I10 -> 92.75 | M45: =IFERROR(ELC_MG_PC!I10*ELC_MG_PC!H10,0) -> 200
B46: ELC (AÇO) | Produção (matéria-prima + HH) | DN 14 | C46: ELC (AÇO) | D46: Produção (matéria-prima + HH) | E46: 14 | F46: =ELC_MG_PC!J11 -> 312.66 | H46: — | I46: =ELC_MG_PC!H11 -> 1 | K46: =IF(OR($J46="",$J46<=0),$F46,$L46+$M46/$J46) -> 312.66 | L46: =$F46-ELC_MG_PC!I11 -> 112.66 | M46: =IFERROR(ELC_MG_PC!I11*ELC_MG_PC!H11,0) -> 200
...

Sheet EVOLUÇÃO DE CUSTOS - PRODUTOS
A1: ⬅ PAINEL
B2: 📦 EVOLUÇÃO DE CUSTOS — PRODUTOS (PIGS E SOBRESSALENTES)
B3: Toda vez que o custo de um produto mudar, adicione uma nova linha na tabela "REGISTRO DE ATUALIZAÇÕES" (à direita). A matriz mensal e o painel de consulta abaixo são atualizados automaticamente — nada precisa ser recalculado à mão.
B4: 🔵 Texto azul = você pode digitar/editar aqui | ⚫ Texto preto = calculado automaticamente (não editar) | 🟢 Texto verde = puxado de outra aba
B5: 🔎 CONSULTAR EVOLUÇÃO DE UM PRODUTO
B6: Produto (pig / sobressalente): | C6: PIG H | PIG H — BAIXA D26 (CUSTO COMPLETO H COM SELO) | DN 10''
B8: Custo atual calculado (aba BUSCA DE CUSTO): | C8: =IFERROR(INDEX('BUSCA DE CUSTO'!$F$19:$F$834,MATCH($C$6,'BUSCA DE CUSTO'!$B$19:$B$834,0)),"Selecione um produto") -> 40.178157
B9: Custo registrado mais recente (R$): | C9: =IFERROR(INDEX($J$21:$J$1200,MATCH($C$6&"|"&TEXT(_xlfn.MAXIFS($F$21:$F$1200,$H$21:$H$1200,$C$6,$F$21:$F$1200,"<="&TODAY()),"0"),$N$21:$N$1200,0)),"Selecione um produto") -> 57.821801
B10: Data do registro mais recente: | C10: =IFERROR(_xlfn.MAXIFS($F$21:$F$1200,$H$21:$H$1200,$C$6,$F$21:$F$1200,"<="&TODAY()),"") -> 46241
B11: Custo anterior (R$): | C11: =IFERROR(INDEX($J$21:$J$1200,MATCH($C$6&"|"&TEXT(_xlfn.MAXIFS($F$21:$F$1200,$H$21:$H$1200,$C$6,$F$21:$F$1200,"<"&$C$10),"0"),$N$21:$N$1200,0)),"—") -> —
B12: Data do custo anterior: | C12: =IFERROR(_xlfn.MAXIFS($F$21:$F$1200,$H$21:$H$1200,$C$6,$F$21:$F$1200,"<"&$C$10),"") -> 0
B13: Variação (último vs. anterior): | C13: =IF(OR($C$11="—",$C$11=""),"",($C$9-$C$11)/$C$11)
B14: Custo no 1º registro (R$): | C14: =IFERROR(INDEX($J$21:$J$1200,MATCH($C$6&"|"&TEXT(_xlfn.MINIFS($F$21:$F$1200,$H$21:$H$1200,$C$6),"0"),$N$21:$N$1200,0)),"") -> 57.821801
B15: Data do 1º registro: | C15: =IFERROR(_xlfn.MINIFS($F$21:$F$1200,$H$21:$H$1200,$C$6),"") -> 46241
B16: Variação total (desde o 1º registro): | C16: =IF(OR($C$14="",$C$14=0),"",($C$9-$C$14)/$C$14) -> 0
B17: Nº de atualizações registradas: | C17: =COUNTIF($H$21:$H$1200,$C$6) -> 1
B19: 🗓 MATRIZ DE EVOLUÇÃO MENSAL — CUSTO DO PRODUTO NO FIM DE CADA MÊS (R$) | F19: 📝 REGISTRO DE ATUALIZAÇÕES DE CUSTO (LOG) — adicione uma linha nova a cada atualização
B20: PRODUTO (PIG / SOBRESSALENTE) | C20: TIPO | D20: ='EVOLUÇÃO DE CUSTOS - MP'!D$19 -> 46235 | F20: DATA | G20: TIPO | H20: PRODUTO (use o mesmo nome da matriz à esquerda) | I20: ORIGEM / FONTE | J20: CUSTO (R$) | K20: CUSTO ANTERIOR (R$) | L20: VARIAÇÃO (%) | M20: OBSERVAÇÃO | N20: CHAVE (auto)
B21: PIG LUN-CP3 EPDM | Corpo completo (Eixo+Cabeçote+Nylon+Porca+Flange+Copo) | DN 6'' | C21: Pig | D21: =IF($B21="","",IFERROR(INDEX($J$21:$J$1200,MATCH($B21&"|"&TEXT(_xlfn.MAXIFS($F$21:$F$1200,$H$21:$H$1200,$B21,$F$21:$F$1200,"<="&EOMONTH(D$20,0)),"0"),$N$21:$N$1200,0)),"-")) -> 837.3 | F21: 46241 | G21: Pig | H21: PIG LUN-CP3 EPDM | Corpo completo (Eixo+Cabeçote+Nylon+Porca+Flange+Copo) | DN 6'' | I21: Cálculo interno (aba de origem) | J21: 837.3 | K21: =IF($H21="","",IFERROR(INDEX($J$21:$J$1200,MATCH($H21&"|"&TEXT(_xlfn.MAXIFS($F$21:$F$1200,$H$21:$H$1200,$H21,$F$21:$F$1200,"<"&$F21),"0"),$N$21:$N$1200,0)),"1º registro")) -> 1º registro | L21: =IF(OR($H21="",$K21="1º registro"),"",IFERROR(($J21-$K21)/$K21,"")) | M21: Carga inicial (snapshot do índice 'BUSCA DE CUSTO') | N21: =IF($H21="","",$H21&"|"&TEXT($F21,"0")) -> PIG LUN-CP3 EPDM | Corpo completo (Eixo+Cabeçote+Nylon+Porca+Flange+Copo) | DN 6''|46241
B22: PIG LUN-CP3 EPDM | Corpo completo (Eixo+Cabeçote+Nylon+Porca+Flange+Copo) | DN 8'' | C22: Pig | D22: =IF($B22="","",IFERROR(INDEX($J$21:$J$1200,MATCH($B22&"|"&TEXT(_xlfn.MAXIFS($F$21:$F$1200,$H$21:$H$1200,$B22,$F$21:$F$1200,"<="&EOMONTH(D$20,0)),"0"),$N$21:$N$1200,0)),"-")) -> 1022.8 | F22: 46241 | G22: Pig | H22: PIG LUN-CP3 EPDM | Corpo completo (Eixo+Cabeçote+Nylon+Porca+Flange+Copo) | DN 8'' | I22: Cálculo interno (aba de origem) | J22: 1022.8 | K22: =IF($H22="","",IFERROR(INDEX($J$21:$J$1200,MATCH($H22&"|"&TEXT(_xlfn.MAXIFS($F$21:$F$1200,$H$21:$H$1200,$H22,$F$21:$F$1200,"<"&$F22),"0"),$N$21:$N$1200,0)),"1º registro")) -> 1º registro | L22: =IF(OR($H22="",$K22="1º registro"),"",IFERROR(($J22-$K22)/$K22,"")) | M22: Carga inicial (snapshot do índice 'BUSCA DE CUSTO') | N22: =IF($H22="","",$H22&"|"&TEXT($F22,"0")) -> PIG LUN-CP3 EPDM | Corpo completo (Eixo+Cabeçote+Nylon+Porca+Flange+Copo) | DN 8''|46241
B23: PIG LUN-CP3 EPDM | Corpo completo (Eixo+Cabeçote+Nylon+Porca+Flange+Copo) | DN 10'' | C23: Pig | D23: =IF($B23="","",IFERROR(INDEX($J$21:$J$1200,MATCH($B23&"|"&TEXT(_xlfn.MAXIFS($F$21:$F$1200,$H$21:$H$1200,$B23,$F$21:$F$1200,"<="&EOMONTH(D$20,0)),"0"),$N$21:$N$1200,0)),"-")) -> 1118.7 | F23: 46241 | G23: Pig | H23: PIG LUN-CP3 EPDM | Corpo completo (Eixo+Cabeçote+Nylon+Porca+Flange+Copo) | DN 10'' | I23: Cálculo interno (aba de origem) | J23: 1118.7 | K23: =IF($H23="","",IFERROR(INDEX($J$21:$J$1200,MATCH($H23&"|"&TEXT(_xlfn.MAXIFS($F$21:$F$1200,$H$21:$H$1200,$H23,$F$21:$F$1200,"<"&$F23),"0"),$N$21:$N$1200,0)),"1º registro")) -> 1º registro | L23: =IF(OR($H23="",$K23="1º registro"),"",IFERROR(($J23-$K23)/$K23,"")) | M23: Carga inicial (snapshot do índice 'BUSCA DE CUSTO') | N23: =IF($H23="","",$H23&"|"&TEXT($F23,"0")) -> PIG LUN-CP3 EPDM | Corpo completo (Eixo+Cabeçote+Nylon+Porca+Flange+Copo) | DN 10''|46241
B24: PIG LUN-CP3 EPDM | Corpo completo (Eixo+Cabeçote+Nylon+Porca+Flange+Copo) | DN 12'' | C24: Pig | D24: =IF($B24="","",IFERROR(INDEX($J$21:$J$1200,MATCH($B24&"|"&TEXT(_xlfn.MAXIFS($F$21:$F$1200,$H$21:$H$1200,$B24,$F$21:$F$1200,"<="&EOMONTH(D$20,0)),"0"),$N$21:$N$1200,0)),"-")) -> 1332.1 | F24: 46241 | G24: Pig | H24: PIG LUN-CP3 EPDM | Corpo completo (Eixo+Cabeçote+Nylon+Porca+Flange+Copo) | DN 12'' | I24: Cálculo interno (aba de origem) | J24: 1332.1 | K24: =IF($H24="","",IFERROR(INDEX($J$21:$J$1200,MATCH($H24&"|"&TEXT(_xlfn.MAXIFS($F$21:$F$1200,$H$21:$H$1200,$H24,$F$21:$F$1200,"<"&$F24),"0"),$N$21:$N$1200,0)),"1º registro")) -> 1º registro | L24: =IF(OR($H24="",$K24="1º registro"),"",IFERROR(($J24-$K24)/$K24,"")) | M24: Carga inicial (snapshot do índice 'BUSCA DE CUSTO') | N24: =IF($H24="","",$H24&"|"&TEXT($F24,"0")) -> PIG LUN-CP3 EPDM | Corpo completo (Eixo+Cabeçote+Nylon+Porca+Flange+Copo) | DN 12''|46241
B25: PIG LUN-CP3 EPDM | Corpo completo (Eixo+Cabeçote+Nylon+Porca+Flange+Copo) | DN 14'' | C25: Pig | D25: =IF($B25="","",IFERROR(INDEX($J$21:$J$1200,MATCH($B25&"|"&TEXT(_xlfn.MAXIFS($F$21:$F$1200,$H$21:$H$1200,$B25,$F$21:$F$1200,"<="&EOMONTH(D$20,0)),"0"),$N$21:$N$1200,0)),"-")) -> 1656.4 | F25: 46241 | G25: Pig | H25: PIG LUN-CP3 EPDM | Corpo completo (Eixo+Cabeçote+Nylon+Porca+Flange+Copo) | DN 14'' | I25: Cálculo interno (aba de origem) | J25: 1656.4 | K25: =IF($H25="","",IFERROR(INDEX($J$21:$J$1200,MATCH($H25&"|"&TEXT(_xlfn.MAXIFS($F$21:$F$1200,$H$21:$H$1200,$H25,$F$21:$F$1200,"<"&$F25),"0"),$N$21:$N$1200,0)),"1º registro")) -> 1º registro | L25: =IF(OR($H25="",$K25="1º registro"),"",IFERROR(($J25-$K25)/$K25,"")) | M25: Carga inicial (snapshot do índice 'BUSCA DE CUSTO') | N25: =IF($H25="","",$H25&"|"&TEXT($F25,"0")) -> PIG LUN-CP3 EPDM | Corpo completo (Eixo+Cabeçote+Nylon+Porca+Flange+Copo) | DN 14''|46241
B26: PIG LUN-CP3 BUNA N | Corpo completo (Eixo+Cabeçote+Nylon+Porca+Flange+Copo) | DN 6'' | C26: Pig | D26: =IF($B26="","",IFERROR(INDEX($J$21:$J$1200,MATCH($B26&"|"&TEXT(_xlfn.MAXIFS($F$21:$F$1200,$H$21:$H$1200,$B26,$F$21:$F$1200,"<="&EOMONTH(D$20,0)),"0"),$N$21:$N$1200,0)),"-")) -> 939.3 | F26: 46241 | G26: Pig | H26: PIG LUN-CP3 BUNA N | Corpo completo (Eixo+Cabeçote+Nylon+Porca+Flange+Copo) | DN 6'' | I26: Cálculo interno (aba de origem) | J26: 939.3 | K26: =IF($H26="","",IFERROR(INDEX($J$21:$J$1200,MATCH($H26&"|"&TEXT(_xlfn.MAXIFS($F$21:$F$1200,$H$21:$H$1200,$H26,$F$21:$F$1200,"<"&$F26),"0"),$N$21:$N$1200,0)),"1º registro")) -> 1º registro | L26: =IF(OR($H26="",$K26="1º registro"),"",IFERROR(($J26-$K26)/$K26,"")) | M26: Carga inicial (snapshot do índice 'BUSCA DE CUSTO') | N26: =IF($H26="","",$H26&"|"&TEXT($F26,"0")) -> PIG LUN-CP3 BUNA N | Corpo completo (Eixo+Cabeçote+Nylon+Porca+Flange+Copo) | DN 6''|46241
B27: PIG LUN-CP3 BUNA N | Corpo completo (Eixo+Cabeçote+Nylon+Porca+Flange+Copo) | DN 8'' | C27: Pig | D27: =IF($B27="","",IFERROR(INDEX($J$21:$J$1200,MATCH($B27&"|"&TEXT(_xlfn.MAXIFS($F$21:$F$1200,$H$21:$H$1200,$B27,$F$21:$F$1200,"<="&EOMONTH(D$20,0)),"0"),$N$21:$N$1200,0)),"-")) -> 1157.8 | F27: 46241 | G27: Pig | H27: PIG LUN-CP3 BUNA N | Corpo completo (Eixo+Cabeçote+Nylon+Porca+Flange+Copo) | DN 8'' | I27: Cálculo interno (aba de origem) | J27: 1157.8 | K27: =IF($H27="","",IFERROR(INDEX($J$21:$J$1200,MATCH($H27&"|"&TEXT(_xlfn.MAXIFS($F$21:$F$1200,$H$21:$H$1200,$H27,$F$21:$F$1200,"<"&$F27),"0"),$N$21:$N$1200,0)),"1º registro")) -> 1º registro | L27: =IF(OR($H27="",$K27="1º registro"),"",IFERROR(($J27-$K27)/$K27,"")) | M27: Carga inicial (snapshot do índice 'BUSCA DE CUSTO') | N27: =IF($H27="","",$H27&"|"&TEXT($F27,"0")) -> PIG LUN-CP3 BUNA N | Corpo completo (Eixo+Cabeçote+Nylon+Porca+Flange+Copo) | DN 8''|46241
B28: PIG LUN-CP3 BUNA N | Corpo completo (Eixo+Cabeçote+Nylon+Porca+Flange+Copo) | DN 10'' | C28: Pig | D28: =IF($B28="","",IFERROR(INDEX($J$21:$J$1200,MATCH($B28&"|"&TEXT(_xlfn.MAXIFS($F$21:$F$1200,$H$21:$H$1200,$B28,$F$21:$F$1200,"<="&EOMONTH(D$20,0)),"0"),$N$21:$N$1200,0)),"-")) -> 1271.7 | F28: 46241 | G28: Pig | H28: PIG LUN-CP3 BUNA N | Corpo completo (Eixo+Cabeçote+Nylon+Porca+Flange+Copo) | DN 10'' | I28: Cálculo interno (aba de origem) | J28: 1271.7 | K28: =IF($H28="","",IFERROR(INDEX($J$21:$J$1200,MATCH($H28&"|"&TEXT(_xlfn.MAXIFS($F$21:$F$1200,$H$21:$H$1200,$H28,$F$21:$F$1200,"<"&$F28),"0"),$N$21:$N$1200,0)),"1º registro")) -> 1º registro | L28: =IF(OR($H28="",$K28="1º registro"),"",IFERROR(($J28-$K28)/$K28,"")) | M28: Carga inicial (snapshot do índice 'BUSCA DE CUSTO') | N28: =IF($H28="","",$H28&"|"&TEXT($F28,"0")) -> PIG LUN-CP3 BUNA N | Corpo completo (Eixo+Cabeçote+Nylon+Porca+Flange+Copo) | DN 10''|46241
B29: PIG LUN-CP3 BUNA N | Corpo completo (Eixo+Cabeçote+Nylon+Porca+Flange+Copo) | DN 12'' | C29: Pig | D29: =IF($B29="","",IFERROR(INDEX($J$21:$J$1200,MATCH($B29&"|"&TEXT(_xlfn.MAXIFS($F$21:$F$1200,$H$21:$H$1200,$B29,$F$21:$F$1200,"<="&EOMONTH(D$20,0)),"0"),$N$21:$N$1200,0)),"-")) -> 1488.1 | F29: 46241 | G29: Pig | H29: PIG LUN-CP3 BUNA N | Corpo completo (Eixo+Cabeçote+Nylon+Porca+Flange+Copo) | DN 12'' | I29: Cálculo interno (aba de origem) | J29: 1488.1 | K29: =IF($H29="","",IFERROR(INDEX($J$21:$J$1200,MATCH($H29&"|"&TEXT(_xlfn.MAXIFS($F$21:$F$1200,$H$21:$H$1200,$H29,$F$21:$F$1200,"<"&$F29),"0"),$N$21:$N$1200,0)),"1º registro")) -> 1º registro | L29: =IF(OR($H29="",$K29="1º registro"),"",IFERROR(($J29-$K29)/$K29,"")) | M29: Carga inicial (snapshot do índice 'BUSCA DE CUSTO') | N29: =IF($H29="","",$H29&"|"&TEXT($F29,"0")) -> PIG LUN-CP3 BUNA N | Corpo completo (Eixo+Cabeçote+Nylon+Porca+Flange+Copo) | DN 12''|46241
B30: PIG LUN-CP3 BUNA N | Corpo completo (Eixo+Cabeçote+Nylon+Porca+Flange+Copo) | DN 14'' | C30: Pig | D30: =IF($B30="","",IFERROR(INDEX($J$21:$J$1200,MATCH($B30&"|"&TEXT(_xlfn.MAXIFS($F$21:$F$1200,$H$21:$H$1200,$B30,$F$21:$F$1200,"<="&EOMONTH(D$20,0)),"0"),$N$21:$N$1200,0)),"-")) -> 1836.4 | F30: 46241 | G30: Pig | H30: PIG LUN-CP3 BUNA N | Corpo completo (Eixo+Cabeçote+Nylon+Porca+Flange+Copo) | DN 14'' | I30: Cálculo interno (aba de origem) | J30: 1836.4 | K30: =IF($H30="","",IFERROR(INDEX($J$21:$J$1200,MATCH($H30&"|"&TEXT(_xlfn.MAXIFS($F$21:$F$1200,$H$21:$H$1200,$H30,$F$21:$F$1200,"<"&$F30),"0"),$N$21:$N$1200,0)),"1º registro")) -> 1º registro | L30: =IF(OR($H30="",$K30="1º registro"),"",IFERROR(($J30-$K30)/$K30,"")) | M30: Carga inicial (snapshot do índice 'BUSCA DE CUSTO') | N30: =IF($H30="","",$H30&"|"&TEXT($F30,"0")) -> PIG LUN-CP3 BUNA N | Corpo completo (Eixo+Cabeçote+Nylon+Porca+Flange+Copo) | DN 14''|46241
B31: PIG LUN-CP4 BUNA N | Corpo completo (Eixo+Cabeçote+Nylon+Porca+Flange+Copo) | DN 6'' | C31: Pig | D31: =IF($B31="","",IFERROR(INDEX($J$21:$J$1200,MATCH($B31&"|"&TEXT(_xlfn.MAXIFS($F$21:$F$1200,$H$21:$H$1200,$B31,$F$21:$F$1200,"<="&EOMONTH(D$20,0)),"0"),$N$21:$N$1200,0)),"-")) -> 1083.3 | F31: 46241 | G31: Pig | H31: PIG LUN-CP4 BUNA N | Corpo completo (Eixo+Cabeçote+Nylon+Porca+Flange+Copo) | DN 6'' | I31: Cálculo interno (aba de origem) | J31: 1083.3 | K31: =IF($H31="","",IFERROR(INDEX($J$21:$J$1200,MATCH($H31&"|"&TEXT(_xlfn.MAXIFS($F$21:$F$1200,$H$21:$H$1200,$H31,$F$21:$F$1200,"<"&$F31),"0"),$N$21:$N$1200,0)),"1º registro")) -> 1º registro | L31: =IF(OR($H31="",$K31="1º registro"),"",IFERROR(($J31-$K31)/$K31,"")) | M31: Carga inicial (snapshot do índice 'BUSCA DE CUSTO') | N31: =IF($H31="","",$H31&"|"&TEXT($F31,"0")) -> PIG LUN-CP4 BUNA N | Corpo completo (Eixo+Cabeçote+Nylon+Porca+Flange+Copo) | DN 6''|46241
B32: PIG LUN-CP4 BUNA N | Corpo completo (Eixo+Cabeçote+Nylon+Porca+Flange+Copo) | DN 8'' | C32: Pig | D32: =IF($B32="","",IFERROR(INDEX($J$21:$J$1200,MATCH($B32&"|"&TEXT(_xlfn.MAXIFS($F$21:$F$1200,$H$21:$H$1200,$B32,$F$21:$F$1200,"<="&EOMONTH(D$20,0)),"0"),$N$21:$N$1200,0)),"-")) -> 1352.8 | F32: 46241 | G32: Pig | H32: PIG LUN-CP4 BUNA N | Corpo completo (Eixo+Cabeçote+Nylon+Porca+Flange+Copo) | DN 8'' | I32: Cálculo interno (aba de origem) | J32: 1352.8 | K32: =IF($H32="","",IFERROR(INDEX($J$21:$J$1200,MATCH($H32&"|"&TEXT(_xlfn.MAXIFS($F$21:$F$1200,$H$21:$H$1200,$H32,$F$21:$F$1200,"<"&$F32),"0"),$N$21:$N$1200,0)),"1º registro")) -> 1º registro | L32: =IF(OR($H32="",$K32="1º registro"),"",IFERROR(($J32-$K32)/$K32,"")) | M32: Carga inicial (snapshot do índice 'BUSCA DE CUSTO') | N32: =IF($H32="","",$H32&"|"&TEXT($F32,"0")) -> PIG LUN-CP4 BUNA N | Corpo completo (Eixo+Cabeçote+Nylon+Porca+Flange+Copo) | DN 8''|46241
... B831: PU CAST COPO PISTAO | Copo pistão em poliuretano fundido (MP + HH) | DN 46 | C831: Sobressalente | D831: =IF($B831="","",IFERROR(INDEX($J$21:$J$1200,MATCH($B831&"|"&TEXT(_xlfn.MAXIFS($F$21:$F$1200,$H$21:$H$1200,$B831,$F$21:$F$1200,"<="&EOMONTH(D$20,0)),"0"),$N$21:$N$1200,0)),"-")) -> 2436.9208 | F831: 46241 | G831: Sobressalente | H831: PU CAST COPO PISTAO | Copo pistão em poliuretano fundido (MP + HH) | DN 46 | I831: Cálculo interno (aba de origem) | J831: 2436.9208 | K831: =IF($H831="","",IFERROR(INDEX($J$21:$J$1200,MATCH($H831&"|"&TEXT(_xlfn.MAXIFS($F$21:$F$1200,$H$21:$H$1200,$H831,$F$21:$F$1200,"<"&$F831),"0"),$N$21:$N$1200,0)),"1º registro")) -> 1º registro | L831: =IF(OR($H831="",$K831="1º registro"),"",IFERROR(($J831-$K831)/$K831,"")) | M831: Carga inicial (snapshot do índice 'BUSCA DE CUSTO') | N831: =IF($H831="","",$H831&"|"&TEXT($F831,"0")) -> PU CAST COPO PISTAO | Copo pistão em poliuretano fundido (MP + HH) | DN 46|46241

Sheet EVOLUÇÃO DE CUSTOS - MP
A1: ⬅ PAINEL
B2: 📈 EVOLUÇÃO DE CUSTOS — HISTÓRICO DE PREÇOS (MATÉRIA-PRIMA E PRODUTO)
B3: Toda vez que o preço de uma matéria-prima ou produto mudar, adicione uma nova linha na tabela "REGISTRO DE ATUALIZAÇÕES" (à direita). A matriz mensal e o painel de consulta abaixo são atualizados automaticamente — nada precisa ser recalculado à mão.
B4: 🔵 Texto azul = você pode digitar/editar aqui | ⚫ Texto preto = calculado automaticamente (não editar)
B5: 🔎 CONSULTAR EVOLUÇÃO DE UM ITEM
B6: Item (matéria-prima ou produto): | C6: 12-70 A PRÉ-POLÍMERO TDI
B8: Preço mais recente (R$): | C8: =IFERROR(INDEX($J$21:$J$170,MATCH($C$6&"|"&TEXT(_xlfn.MAXIFS($F$21:$F$170,$H$21:$H$170,$C$6,$F$21:$F$170,"<="&TODAY()),"0"),$N$21:$N$170,0)),"Selecione um item") -> 38.08
B9: Data do preço mais recente: | C9: =IFERROR(_xlfn.MAXIFS($F$21:$F$170,$H$21:$H$170,$C$6,$F$21:$F$170,"<="&TODAY()),"") -> 46143
B10: Preço anterior (R$): | C10: =IFERROR(INDEX($J$21:$J$170,MATCH($C$6&"|"&TEXT(_xlfn.MAXIFS($F$21:$F$170,$H$21:$H$170,$C$6,$F$21:$F$170,"<"&$C$9),"0"),$N$21:$N$170,0)),"—") -> —
B11: Data do preço anterior: | C11: =IFERROR(_xlfn.MAXIFS($F$21:$F$170,$H$21:$H$170,$C$6,$F$21:$F$170,"<"&$C$9),"") -> 0
B12: Variação (último vs. anterior): | C12: =IF(OR($C$10="—",$C$10=""),"",($C$8-$C$10)/$C$10)
B13: Preço no 1º registro (R$): | C13: =IFERROR(INDEX($J$21:$J$170,MATCH($C$6&"|"&TEXT(_xlfn.MINIFS($F$21:$F$170,$H$21:$H$170,$C$6),"0"),$N$21:$N$170,0)),"") -> 38.08
B14: Data do 1º registro: | C14: =IFERROR(_xlfn.MINIFS($F$21:$F$170,$H$21:$H$170,$C$6),"") -> 46143
B15: Variação total (desde o 1º registro): | C15: =IF(OR($C$13="",$C$13=0),"",($C$8-$C$13)/$C$13) -> 0
B16: Nº de atualizações registradas: | C16: =COUNTIF($H$21:$H$170,$C$6) -> 1
B18: 🗓 MATRIZ DE EVOLUÇÃO MENSAL — PREÇO NO FIM DE CADA MÊS (R$) | F18: 📝 REGISTRO DE ATUALIZAÇÕES DE PREÇO (LOG) — adicione uma linha nova a cada atualização
B19: ITEM (MATÉRIA-PRIMA / PRODUTO) | C19: TIPO | D19: 46235 | F19: DATA | G19: TIPO | H19: ITEM (use o mesmo nome da matriz à esquerda) | I19: FORNECEDOR / FONTE | J19: PREÇO (R$) | K19: PREÇO ANTERIOR (R$) | L19: VARIAÇÃO (%) | M19: OBSERVAÇÃO | N19: CHAVE (auto)
B20: 12-70 A PRÉ-POLÍMERO TDI | C20: Matéria-Prima | D20: =IF($B20="","",IFERROR(INDEX($J$21:$J$170,MATCH($B20&"|"&TEXT(_xlfn.MAXIFS($F$21:$F$170,$H$21:$H$170,$B20,$F$21:$F$170,"<="&EOMONTH(D$19,0)),"0"),$N$21:$N$170,0)),"-")) -> 38.08
B21: 12-83 PRÉ-POLÍMERO TDI | C21: Matéria-Prima | D21: =IF($B21="","",IFERROR(INDEX($J$21:$J$170,MATCH($B21&"|"&TEXT(_xlfn.MAXIFS($F$21:$F$170,$H$21:$H$170,$B21,$F$21:$F$170,"<="&EOMONTH(D$19,0)),"0"),$N$21:$N$170,0)),"-")) -> 34.22 | F21: 46143 | G21: Matéria-Prima | H21: 12-70 A PRÉ-POLÍMERO TDI | I21: COIM | J21: 38.08 | K21: =IF($H21="","",IFERROR(INDEX($J$21:$J$170,MATCH($H21&"|"&TEXT(_xlfn.MAXIFS($F$21:$F$170,$H$21:$H$170,$H21,$F$21:$F$170,"<"&$F21),"0"),$N$21:$N$170,0)),"1º registro")) -> 1º registro | L21: =IF(OR($H21="",$K21="1º registro"),"",IFERROR(($J21-$K21)/$K21,"")) | M21: Carga inicial (migrado da aba 'PARÂMETROS') | N21: =IF($H21="","",$H21&"|"&TEXT($F21,"0")) -> 12-70 A PRÉ-POLÍMERO TDI|46143
B22: MOCA CURATIVO TDI | C22: Matéria-Prima | D22: =IF($B22="","",IFERROR(INDEX($J$21:$J$170,MATCH($B22&"|"&TEXT(_xlfn.MAXIFS($F$21:$F$170,$H$21:$H$170,$B22,$F$21:$F$170,"<="&EOMONTH(D$19,0)),"0"),$N$21:$N$170,0)),"-")) -> 27.97 | F22: 46143 | G22: Matéria-Prima | H22: 12-83 PRÉ-POLÍMERO TDI | I22: COIM/AMINO | J22: 34.22 | K22: =IF($H22="","",IFERROR(INDEX($J$21:$J$170,MATCH($H22&"|"&TEXT(_xlfn.MAXIFS($F$21:$F$170,$H$21:$H$170,$H22,$F$21:$F$170,"<"&$F22),"0"),$N$21:$N$170,0)),"1º registro")) -> 1º registro | L22: =IF(OR($H22="",$K22="1º registro"),"",IFERROR(($J22-$K22)/$K22,"")) | M22: Carga inicial (migrado da aba 'PARÂMETROS') | N22: =IF($H22="","",$H22&"|"&TEXT($F22,"0")) -> 12-83 PRÉ-POLÍMERO TDI|46143
B23: 8086 PRÉ-POLÍMERO TDI | C23: Matéria-Prima | D23: =IF($B23="","",IFERROR(INDEX($J$21:$J$170,MATCH($B23&"|"&TEXT(_xlfn.MAXIFS($F$21:$F$170,$H$21:$H$170,$B23,$F$21:$F$170,"<="&EOMONTH(D$19,0)),"0"),$N$21:$N$170,0)),"-")) -> 18.31 | F23: 46143 | G23: Matéria-Prima | H23: MOCA CURATIVO TDI | I23: COIM | J23: 27.97 | K23: =IF($H23="","",IFERROR(INDEX($J$21:$J$170,MATCH($H23&"|"&TEXT(_xlfn.MAXIFS($F$21:$F$170,$H$21:$H$170,$H23,$F$21:$F$170,"<"&$F23),"0"),$N$21:$N$170,0)),"1º registro")) -> 1º registro | L23: =IF(OR($H23="",$K23="1º registro"),"",IFERROR(($J23-$K23)/$K23,"")) | M23: Carga inicial (migrado da aba 'PARÂMETROS') | N23: =IF($H23="","",$H23&"|"&TEXT($F23,"0")) -> MOCA CURATIVO TDI|46143
B24: 18Q PRÉ-POLÍMERO MDI | C24: Matéria-Prima | D24: =IF($B24="","",IFERROR(INDEX($J$21:$J$170,MATCH($B24&"|"&TEXT(_xlfn.MAXIFS($F$21:$F$170,$H$21:$H$170,$B24,$F$21:$F$170,"<="&EOMONTH(D$19,0)),"0"),$N$21:$N$170,0)),"-")) -> 50.95 | F24: 46143 | G24: Matéria-Prima | H24: 8086 PRÉ-POLÍMERO TDI | I24: LANXESS | J24: 18.31 | K24: =IF($H24="","",IFERROR(INDEX($J$21:$J$170,MATCH($H24&"|"&TEXT(_xlfn.MAXIFS($F$21:$F$170,$H$21:$H$170,$H24,$F$21:$F$170,"<"&$F24),"0"),$N$21:$N$170,0)),"1º registro")) -> 1º registro | L24: =IF(OR($H24="",$K24="1º registro"),"",IFERROR(($J24-$K24)/$K24,"")) | M24: Carga inicial (migrado da aba 'PARÂMETROS') | N24: =IF($H24="","",$H24&"|"&TEXT($F24,"0")) -> 8086 PRÉ-POLÍMERO TDI|46143
B25: IMUCURE GS234-960 MDI | C25: Matéria-Prima | D25: =IF($B25="","",IFERROR(INDEX($J$21:$J$170,MATCH($B25&"|"&TEXT(_xlfn.MAXIFS($F$21:$F$170,$H$21:$H$170,$B25,$F$21:$F$170,"<="&EOMONTH(D$19,0)),"0"),$N$21:$N$170,0)),"-")) -> 44.74 | F25: 45658 | G25: Matéria-Prima | H25: 18Q PRÉ-POLÍMERO MDI | I25: COIM | J25: 50.95 | K25: =IF($H25="","",IFERROR(INDEX($J$21:$J$170,MATCH($H25&"|"&TEXT(_xlfn.MAXIFS($F$21:$F$170,$H$21:$H$170,$H25,$F$21:$F$170,"<"&$F25),"0"),$N$21:$N$170,0)),"1º registro")) -> 1º registro | L25: =IF(OR($H25="",$K25="1º registro"),"",IFERROR(($J25-$K25)/$K25,"")) | M25: Carga inicial (migrado da aba 'PARÂMETROS') | N25: =IF($H25="","",$H25&"|"&TEXT($F25,"0")) -> 18Q PRÉ-POLÍMERO MDI|45658
B26: IMUCURE GR 45 1,4 BUTANODIOL | C26: Matéria-Prima | D26: =IF($B26="","",IFERROR(INDEX($J$21:$J$170,MATCH($B26&"|"&TEXT(_xlfn.MAXIFS($F$21:$F$170,$H$21:$H$170,$B26,$F$21:$F$170,"<="&EOMONTH(D$19,0)),"0"),$N$21:$N$170,0)),"-")) -> 60.06 | F26: 45658 | G26: Matéria-Prima | H26: IMUCURE GS234-960 MDI | I26: COIM | J26: 44.74 | K26: =IF($H26="","",IFERROR(INDEX($J$21:$J$170,MATCH($H26&"|"&TEXT(_xlfn.MAXIFS($F$21:$F$170,$H$21:$H$170,$H26,$F$21:$F$170,"<"&$F26),"0"),$N$21:$N$170,0)),"1º registro")) -> 1º registro | L26: =IF(OR($H26="",$K26="1º registro"),"",IFERROR(($J26-$K26)/$K26,"")) | M26: Carga inicial (migrado da aba 'PARÂMETROS') | N26: =IF($H26="","",$H26&"|"&TEXT($F26,"0")) -> IMUCURE GS234-960 MDI|45658
B27: 8086 BUMPER PRÉ-POLÍMERO TDI | C27: Matéria-Prima | D27: =IF($B27="","",IFERROR(INDEX($J$21:$J$170,MATCH($B27&"|"&TEXT(_xlfn.MAXIFS($F$21:$F$170,$H$21:$H$170,$B27,$F$21:$F$170,"<="&EOMONTH(D$19,0)),"0"),$N$21:$N$170,0)),"-")) -> 38 | F27: 45658 | G27: Matéria-Prima | H27: IMUCURE GR 45 1,4 BUTANODIOL | I27: COIM | J27: 60.06 | K27: =IF($H27="","",IFERROR(INDEX($J$21:$J$170,MATCH($H27&"|"&TEXT(_xlfn.MAXIFS($F$21:$F$170,$H$21:$H$170,$H27,$F$21:$F$170,"<"&$F27),"0"),$N$21:$N$170,0)),"1º registro")) -> 1º registro | L27: =IF(OR($H27="",$K27="1º registro"),"",IFERROR(($J27-$K27)/$K27,"")) | M27: Carga inicial (migrado da aba 'PARÂMETROS') | N27: =IF($H27="","",$H27&"|"&TEXT($F27,"0")) -> IMUCURE GR 45 1,4 BUTANODIOL|45658
B28: ATS 75 PRÉ-POLÍMERO (AMINO) TDI | C28: Matéria-Prima | D28: =IF($B28="","",IFERROR(INDEX($J$21:$J$170,MATCH($B28&"|"&TEXT(_xlfn.MAXIFS($F$21:$F$170,$H$21:$H$170,$B28,$F$21:$F$170,"<="&EOMONTH(D$19,0)),"0"),$N$21:$N$170,0)),"-")) -> 34.13 | F28: 45658 | G28: Matéria-Prima | H28: 8086 BUMPER PRÉ-POLÍMERO TDI | I28: COIM | J28: 38 | K28: =IF($H28="","",IFERROR(INDEX($J$21:$J$170,MATCH($H28&"|"&TEXT(_xlfn.MAXIFS($F$21:$F$170,$H$21:$H$170,$H28,$F$21:$F$170,"<"&$F28),"0"),$N$21:$N$170,0)),"1º registro")) -> 1º registro | L28: =IF(OR($H28="",$K28="1º registro"),"",IFERROR(($J28-$K28)/$K28,"")) | M28: Carga inicial (migrado da aba 'PARÂMETROS') | N28: =IF($H28="","",$H28&"|"&TEXT($F28,"0")) -> 8086 BUMPER PRÉ-POLÍMERO TDI|45658
B29: ATP 85 PRÉ-POLÍMERO (AMINO) TDI | C29: Matéria-Prima | D29: =IF($B29="","",IFERROR(INDEX($J$21:$J$170,MATCH($B29&"|"&TEXT(_xlfn.MAXIFS($F$21:$F$170,$H$21:$H$170,$B29,$F$21:$F$170,"<="&EOMONTH(D$19,0)),"0"),$N$21:$N$170,0)),"-")) -> 23.95 | F29: 46143 | G29: Matéria-Prima | H29: ATP 85 PRÉ-POLÍMERO (AMINO) TDI | I29: AMINO | J29: 23.95 | K29: =IF($H29="","",IFERROR(INDEX($J$21:$J$170,MATCH($H29&"|"&TEXT(_xlfn.MAXIFS($F$21:$F$170,$H$21:$H$170,$H29,$F$21:$F$170,"<"&$F29),"0"),$N$21:$N$170,0)),"1º registro")) -> 1º registro | L29: =IF(OR($H29="",$K29="1º registro"),"",IFERROR(($J29-$K29)/$K29,"")) | M29: Carga inicial (migrado da aba 'PARÂMETROS') | N29: =IF($H29="","",$H29&"|"&TEXT($F29,"0")) -> ATP 85 PRÉ-POLÍMERO (AMINO) TDI|46143
B30: ATS 85 PRÉ-POLÍMERO (AMINO) TDI | C30: Matéria-Prima | D30: =IF($B30="","",IFERROR(INDEX($J$21:$J$170,MATCH($B30&"|"&TEXT(_xlfn.MAXIFS($F$21:$F$170,$H$21:$H$170,$B30,$F$21:$F$170,"<="&EOMONTH(D$19,0)),"0"),$N$21:$N$170,0)),"-")) -> 31.39 | F30: 46143 | G30: Matéria-Prima | H30: ATS 85 PRÉ-POLÍMERO (AMINO) TDI | I30: AMINO | J30: 31.39 | K30: =IF($H30="","",IFERROR(INDEX($J$21:$J$170,MATCH($H30&"|"&TEXT(_xlfn.MAXIFS($F$21:$F$170,$H$21:$H$170,$H30,$F$21:$F$170,"<"&$F30),"0"),$N$21:$N$170,0)),"1º registro")) -> 1º registro | L30: =IF(OR($H30="",$K30="1º registro"),"",IFERROR(($J30-$K30)/$K30,"")) | M30: Carga inicial (migrado da aba 'PARÂMETROS') | N30: =IF($H30="","",$H30&"|"&TEXT($F30,"0")) -> ATS 85 PRÉ-POLÍMERO (AMINO) TDI|46143
B31: BLOCO ESPUMA D26 (DINATEC) | C31: Matéria-Prima | D31: =IF($B31="","",IFERROR(INDEX($J$21:$J$170,MATCH($B31&"|"&TEXT(_xlfn.MAXIFS($F$21:$F$170,$H$21:$H$170,$B31,$F$21:$F$170,"<="&EOMONTH(D$19,0)),"0"),$N$21:$N$170,0)),"-")) -> 696.52 | F31: 46143 | G31: Matéria-Prima | H31: BLOCO ESPUMA D26 (DINATEC) | I31: DINATEC | J31: 696.52 | K31: =IF($H31="","",IFERROR(INDEX($J$21:$J$170,MATCH($H31&"|"&TEXT(_xlfn.MAXIFS($F$21:$F$170,$H$21:$H$170,$H31,$F$21:$F$170,"<"&$F31),"0"),$N$21:$N$170,0)),"1º registro")) -> 1º registro | L31: =IF(OR($H31="",$K31="1º registro"),"",IFERROR(($J31-$K31)/$K31,"")) | M31: Carga inicial (migrado da aba 'PARÂMETROS') | N31: =IF($H31="","",$H31&"|"&TEXT($F31,"0")) -> BLOCO ESPUMA D26 (DINATEC)|46143
B32: BLOCO ESPUMA D45 (DINATEC) | C32: Matéria-Prima | D32: =IF($B32="","",IFERROR(INDEX($J$21:$J$170,MATCH($B32&"|"&TEXT(_xlfn.MAXIFS($F$21:$F$170,$H$21:$H$170,$B32,$F$21:$F$170,"<="&EOMONTH(D$19,0)),"0"),$N$21:$N$170,0)),"-")) -> 1205.52 | F32: 46143 | G32: Matéria-Prima | H32: BLOCO ESPUMA D45 (DINATEC) | I32: DINATEC | J32: 1205.52 | K32: =IF($H32="","",IFERROR(INDEX($J$21:$J$170,MATCH($H32&"|"&TEXT(_xlfn.MAXIFS($F$21:$F$170,$H$21:$H$170,$H32,$F$21:$F$170,"<"&$F32),"0"),$N$21:$N$170,0)),"1º registro")) -> 1º registro | L32: =IF(OR($H32="",$K32="1º registro"),"",IFERROR(($J32-$K32)/$K32,"")) | M32: Carga inicial (migrado da aba 'PARÂMETROS') | N32: =IF($H32="","",$H32&"|"&TEXT($F32,"0")) -> BLOCO ESPUMA D45 (DINATEC)|46143
... B50: BUMPER PU - COIM (kg) | C50: Matéria-Prima | D50: =IF($B50="","",IFERROR(INDEX($J$21:$J$170,MATCH($B50&"|"&TEXT(_xlfn.MAXIFS($F$21:$F$170,$H$21:$H$170,$B50,$F$21:$F$170,"<="&EOMONTH(D$19,0)),"0"),$N$21:$N$170,0)),"-")) -> 55 | F50: 45658 | G50: Matéria-Prima | H50: BUMPER PU - COIM (kg) | I50: COMERCIAL | J50: 55 | K50: =IF($H50="","",IFERROR(INDEX($J$21:$J$170,MATCH($H50&"|"&TEXT(_xlfn.MAXIFS($F$21:$F$170,$H$21:$H$170,$H50,$F$21:$F$170,"<"&$F50),"0"),$N$21:$N$170,0)),"1º registro")) -> 1º registro | L50: =IF(OR($H50="",$K50="1º registro"),"",IFERROR(($J50-$K50)/$K50,"")) | M50: Carga inicial (migrado da aba 'PARÂMETROS') | N50: =IF($H50="","",$H50&"|"&TEXT($F50,"0")) -> BUMPER PU - COIM (kg)|45658
D51: =IF($B51="","",IFERROR(INDEX($J$21:$J$170,MATCH($B51&"|"&TEXT(_xlfn.MAXIFS($F$21:$F$170,$H$21:$H$170,$B51,$F$21:$F$170,"<="&EOMONTH(D$19,0)),"0"),$N$21:$N$170,0)),"-")) | F51: 46246 | G51: Matéria-Prima | H51: ATS 75 PRÉ-POLÍMERO (AMINO) TDI | I51: AMINO | J51: 34.13 | K51: =IF($H51="","",IFERROR(INDEX($J$21:$J$170,MATCH($H51&"|"&TEXT(_xlfn.MAXIFS($F$21:$F$170,$H$21:$H$170,$H51,$F$21:$F$170,"<"&$F51),"0"),$N$21:$N$170,0)),"1º registro")) -> 1º registro | L51: =IF(OR($H51="",$K51="1º registro"),"",IFERROR(($J51-$K51)/$K51,"")) | M51: Inclusão de nova matéria-prima (PARÂMETROS) | N51: =IF($H51="","",$H51&"|"&TEXT($F51,"0")) -> ATS 75 PRÉ-POLÍMERO (AMINO) TDI|46246
D52: =IF($B52="","",IFERROR(INDEX($J$21:$J$170,MATCH($B52&"|"&TEXT(_xlfn.MAXIFS($F$21:$F$170,$H$21:$H$170,$B52,$F$21:$F$170,"<="&EOMONTH(D$19,0)),"0"),$N$21:$N$170,0)),"-")) | K52: =IF($H52="","",IFERROR(INDEX($J$21:$J$170,MATCH($H52&"|"&TEXT(_xlfn.MAXIFS($F$21:$F$170,$H$21:$H$170,$H52,$F$21:$F$170,"<"&$F52),"0"),$N$21:$N$170,0)),"1º registro")) | L52: =IF(OR($H52="",$K52="1º registro"),"",IFERROR(($J52-$K52)/$K52,"")) | N52: =IF($H52="","",$H52&"|"&TEXT($F52,"0"))
D53: =IF($B53="","",IFERROR(INDEX($J$21:$J$170,MATCH($B53&"|"&TEXT(_xlfn.MAXIFS($F$21:$F$170,$H$21:$H$170,$B53,$F$21:$F$170,"<="&EOMONTH(D$19,0)),"0"),$N$21:$N$170,0)),"-")) | K53: =IF($H53="","",IFERROR(INDEX($J$21:$J$170,MATCH($H53&"|"&TEXT(_xlfn.MAXIFS($F$21:$F$170,$H$21:$H$170,$H53,$F$21:$F$170,"<"&$F53),"0"),$N$21:$N$170,0)),"1º registro")) | L53: =IF(OR($H53="",$K53="1º registro"),"",IFERROR(($J53-$K53)/$K53,"")) | N53: =IF($H53="","",$H53&"|"&TEXT($F53,"0"))
D54: =IF($B54="","",IFERROR(INDEX($J$21:$J$170,MATCH($B54&"|"&TEXT(_xlfn.MAXIFS($F$21:$F$170,$H$21:$H$170,$B54,$F$21:$F$170,"<="&EOMONTH(D$19,0)),"0"),$N$21:$N$170,0)),"-")) | K54: =IF($H54="","",IFERROR(INDEX($J$21:$J$170,MATCH($H54&"|"&TEXT(_xlfn.MAXIFS($F$21:$F$170,$H$21:$H$170,$H54,$F$21:$F$170,"<"&$F54),"0"),$N$21:$N$170,0)),"1º registro")) | L54: =IF(OR($H54="",$K54="1º registro"),"",IFERROR(($J54-$K54)/$K54,"")) | N54: =IF($H54="","",$H54&"|"&TEXT($F54,"0"))
D55: =IF($B55="","",IFERROR(INDEX($J$21:$J$170,MATCH($B55&"|"&TEXT(_xlfn.MAXIFS($F$21:$F$170,$H$21:$H$170,$B55,$F$21:$F$170,"<="&EOMONTH(D$19,0)),"0"),$N$21:$N$170,0)),"-")) | K55: =IF($H55="","",IFERROR(INDEX($J$21:$J$170,MATCH($H55&"|"&TEXT(_xlfn.MAXIFS($F$21:$F$170,$H$21:$H$170,$H55,$F$21:$F$170,"<"&$F55),"0"),$N$21:$N$170,0)),"1º registro")) | L55: =IF(OR($H55="",$K55="1º registro"),"",IFERROR(($J55-$K55)/$K55,"")) | N55: =IF($H55="","",$H55&"|"&TEXT($F55,"0"))
D56: =IF($B56="","",IFERROR(INDEX($J$21:$J$170,MATCH($B56&"|"&TEXT(_xlfn.MAXIFS($F$21:$F$170,$H$21:$H$170,$B56,$F$21:$F$170,"<="&EOMONTH(D$19,0)),"0"),$N$21:$N$170,0)),"-")) | K56: =IF($H56="","",IFERROR(INDEX($J$21:$J$170,MATCH($H56&"|"&TEXT(_xlfn.MAXIFS($F$21:$F$170,$H$21:$H$170,$H56,$F$21:$F$170,"<"&$F56),"0"),$N$21:$N$170,0)),"1º registro")) | L56: =IF(OR($H56="",$K56="1º registro"),"",IFERROR(($J56-$K56)/$K56,"")) | N56: =IF($H56="","",$H56&"|"&TEXT($F56,"0"))
D57: =IF($B57="","",IFERROR(INDEX($J$21:$J$170,MATCH($B57&"|"&TEXT(_xlfn.MAXIFS($F$21:$F$170,$H$21:$H$170,$B57,$F$21:$F$170,"<="&EOMONTH(D$19,0)),"0"),$N$21:$N$170,0)),"-")) | K57: =IF($H57="","",IFERROR(INDEX($J$21:$J$170,MATCH($H57&"|"&TEXT(_xlfn.MAXIFS($F$21:$F$170,$H$21:$H$170,$H57,$F$21:$F$170,"<"&$F57),"0"),$N$21:$N$170,0)),"1º registro")) | L57: =IF(OR($H57="",$K57="1º registro"),"",IFERROR(($J57-$K57)/$K57,"")) | N57: =IF($H57="","",$H57&"|"&TEXT($F57,"0"))
D58: =IF($B58="","",IFERROR(INDEX($J$21:$J$170,MATCH($B58&"|"&TEXT(_xlfn.MAXIFS($F$21:$F$170,$H$21:$H$170,$B58,$F$21:$F$170,"<="&EOMONTH(D$19,0)),"0"),$N$21:$N$170,0)),"-")) | K58: =IF($H58="","",IFERROR(INDEX($J$21:$J$170,MATCH($H58&"|"&TEXT(_xlfn.MAXIFS($F$21:$F$170,$H$21:$H$170,$H58,$F$21:$F$170,"<"&$F58),"0"),$N$21:$N$170,0)),"1º registro")) | L58: =IF(OR($H58="",$K58="1º registro"),"",IFERROR(($J58-$K58)/$K58,"")) | N58: =IF($H58="","",$H58&"|"&TEXT($F58,"0"))
D59: =IF($B59="","",IFERROR(INDEX($J$21:$J$170,MATCH($B59&"|"&TEXT(_xlfn.MAXIFS($F$21:$F$170,$H$21:$H$170,$B59,$F$21:$F$170,"<="&EOMONTH(D$19,0)),"0"),$N$21:$N$170,0)),"-")) | K59: =IF($H59="","",IFERROR(INDEX($J$21:$J$170,MATCH($H59&"|"&TEXT(_xlfn.MAXIFS($F$21:$F$170,$H$21:$H$170,$H59,$F$21:$F$170,"<"&$F59),"0"),$N$21:$N$170,0)),"1º registro")) | L59: =IF(OR($H59="",$K59="1º registro"),"",IFERROR(($J59-$K59)/$K59,"")) | N59: =IF($H59="","",$H59&"|"&TEXT($F59,"0"))
...

Sheet PARÂMETROS
A1: ⚙ PARÂMETROS — CUSTOS DE PRODUÇÃO 4PIPE
A2: ⚠ ATENÇÃO: Altere os valores AZUIS nesta aba. Todos os custos de todas as abas serão atualizados automaticamente.
A3: ⬅ PAINEL | G3: 💲 CUSTO HH (R$/h): | H3: 40
A4: MATÉRIAS-PRIMAS — PU CAST / LBD (POLIURETANO FUNDIDO)
A5: # | B5: DESCRIÇÃO MATÉRIA-PRIMA | C5: FORNECEDOR / REF. | D5: DATA ATUALIZAÇÃO | E5: PREÇO (R$/kg) SEM IMPOSTO
A6: 1 | B6: 12-70 A PRÉ-POLÍMERO TDI | C6: COIM | D6: 46235 | E6: 39.93
A7: 2 | B7: 12-83 PRÉ-POLÍMERO TDI | C7: COIM | D7: 46236 | E7: 36.91
A8: 3 | B8: MOCA CURATIVO TDI | C8: COIM | D8: 46237 | E8: 30.89 | G8: COMPARATIVO BLOCO DE ESPUMA D26
A9: 4 | B9: 8086 PRÉ-POLÍMERO TDI | C9: LANXESS | D9: 46238 | E9: 17.66 | G9: DINATEC | H9: ARSAN
A10: 5 | B10: 18Q PRÉ-POLÍMERO MDI | C10: COIM | D10: 45658 | E10: 50.95 | G10: =$E$18 -> 438.3 | H10: 445
A11: 6 | B11: IMUCURE GS234-960 MDI | C11: COIM | D11: 45658 | E11: 44.74
A12: 7 | B12: IMUCURE GR 45 1,4 BUTANODIOL | C12: COIM | D12: 45658 | E12: 60.06
A13: 8 | B13: ATS 75 PRÉ-POLÍMERO (AMINO) TDI | C13: AMINO | D13: 46238 | E13: 34.13
A14: 9 | B14: ATP 85 PRÉ-POLÍMERO (AMINO) TDI | C14: AMINO | D14: 46239 | E14: 21.53
A15: 10 | B15: ATS 85 PRÉ-POLÍMERO (AMINO) TDI | C15: AMINO | D15: 46240 | E15: 34.13
A16: MATÉRIAS-PRIMAS — ESPUMA (BLOCOS / ENVASE A+B) | G16: REVISAO MAIO/2026 - EM ANALISE COMERCIAL - COM IMPOSTO
A17: # | B17: DESCRIÇÃO MATÉRIA-PRIMA | C17: FORNECEDOR / REF. | D17: DATA ATUALIZAÇÃO | E17: PREÇO (R$/kg) 05/2026 SEM IMPOSTO | G17: # | H17: DESCRIÇÃO MATÉRIA-PRIMA | I17: FORNECEDOR / REF. | J17: DATA ATUALIZAÇÃO | K17: PREÇO (R$/kg)
A18: 8 | B18: BLOCO ESPUMA D26 (DINATEC) | C18: CBP | D18: 46266 | E18: 438.3 | G18: 8 | H18: BLOCO ESPUMA D26 (DINATEC) | I18: DINATEC | J18: 46143 | K18: 936
A19: 9 | B19: BLOCO ESPUMA D45 (DINATEC) | C19: DINATEC | D19: 46235 | E19: 1205.52 | G19: 9 | H19: BLOCO ESPUMA D45 (DINATEC) | I19: DINATEC | J19: 46143 | K19: 1050
A20: 10 | B20: BLOCO ESPUMA D60 (DINATEC) | C20: DINATEC | D20: 46235 | E20: 1607.36 | G20: 10 | H20: BLOCO ESPUMA D60 (DINATEC) | I20: DINATEC | J20: 46143 | K20: 1350
A21: 11 | B21: BLOCO ESPUMA D80 (DINATEC) | C21: DINATEC | D21: 46235 | E21: 2143.15 | G21: 11 | H21: BLOCO ESPUMA D80 (DINATEC) | I21: DINATEC | J21: 46143 | K21: 1718
A22: 12 | B22: ELASTOMERO 385 TECPUR (kg) | C22: TECPUR | D22: 46235 | E22: 42.37 | G22: 12 | H22: ELASTOMERO TECPUR (kg) | I22: TECPUR | J22: 46143 | K22: 64.4
A23: 13 | B23: SISTEMA AMINO 2471 A ALTA (kg) | C23: AMINO | D23: 46235 | E23: 19.59 | G23: 13 | H23: SISTEMA AMINO A ALTA (kg) | I23: AMINO | J23: 46143 | K23: 26.62
A24: 14 | B24: SISTEMA AMINO 2475 A MÉDIA (kg) | C24: AMINO | D24: 46235 | E24: 19.59 | G24: 14 | H24: SISTEMA AMINO A MÉDIA (kg) | I24: AMINO | J24: 46143 | K24: 26.62
A25: 15 | B25: SISTEMA AMINO 122 B ISO (kg) | C25: AMINO | D25: 46235 | E25: 19.59 | G25: 15 | H25: SISTEMA AMINO B ISO (kg) | I25: AMINO | J25: 46143 | K25: 26.62
A26: 16 | B26: PIGMENTO (kg) - ASTA QUIMICA | C26: ASTA | D26: 46235 | E26: 89.3
A27: 17 | B27: CORDA OLHAL (metro) | C27: COMERCIAL | D27: 45597 | E27: 3
A28: 18 | B28: ESCOVA FINA HLR (metro) | C28: CARDAS BRASIL | D28: 46235 | E28: 142.88
A29: 19 | B29: ESCOVA GROSSA HLR (metro) | C29: CARDAS BRASIL | D29: 46235 | E29: 179.34
A30: 20 | B30: VELCRO HLR V (metro) | C30: COMERCIAL | D30: 45597 | E30: 5.84
A31: 21 | B31: COLA SAPATEIRO (kg) | C31: COMERCIAL | D31: 45658 | E31: 15.15
A32: 22 | B32: MANTA SILICONE (kg) | C32: PERFITECNICA | D32: 46235 | E32: 157.31
A33: 23 | B33: IMÃ 22 X 10MM SAMÁRIO (un) | C33: OXIMAG/MAGTEK | D33: 46235 | E33: 53.8
A34: 24 | B34: IMÃ 8 X 5MM SAMÁRIO (un) | C34: OXIMAG/MAGTEK | D34: 46235 | E34: 3.39
A36: 🔵 AZUL = Input editável | ⚫ PRETO = Fórmula automática | 🟡 Fundo amarelo = Atenção
A39: COMPONENTES CORPO DO PIG — TUBO, FLANGE, PARAFUSO, PORCA, ARRUELA (POR DN) — Fonte: DETALHAMENTO_MANDRIL.xlsx (consolidado)
A40: DN | B40: DESCRIÇÃO TUBO | C40: CUSTO TUBO (R$) | D40: CUSTO FLANGE UN. (R$) | E40: CUSTO FLANGE SOLDA (R$) | F40: CUSTO PARAFUSO UN. (R$) | G40: CUSTO PORCA UN. (R$) | H40: CUSTO ARRUELA UN. (R$)
A41: 6 | B41: Tubo DN 1.1/2'' sch 40 | C41: 21.6 | D41: 24 | E41: 27 | F41: 0.77 | G41: 0.9 | H41: 0.3
A42: 8 | B42: Tubo DN 1.1/2'' sch 40 | C42: 25.2 | D42: 30 | E42: 37 | F42: 1.34 | G42: 1 | H42: 0.43
A43: 10 | B43: Tubo DN 3'' sch 40 | C43: 81 | D43: 37 | E43: 47 | F43: 2.56 | G43: 1.5 | H43: 0.66
...

Sheet LBD
A1: 🔧 MANDRIL — DETALHAMENTO DE CUSTOS (POLIURETANO + CORPO DE PIG + FIXAÇÃO) — LBD-DG2-DS4
A2: ⚠ Preços de matéria-prima vêm de PARÂMETROS!$F$6. HH (mão de obra) vem de PARÂMETROS!$I$3 — mudando esse valor, o Custo Total de todas as linhas atualiza sozinho.
A3: ⬅ PAINEL
A4: MODELO | B4: DN | C4: DISCO SELO (12-70) | G4: DISCO GUIA (ATS 85) | K4: DISCO ESPAÇADOR (ATP 85) | O4: TUBO | T4: FLANGE BUMPER | Z4: BUMPER (ATP 85 — ELASTÔMERO) | AD4: FLANGE SOLDA | AJ4: FIXAÇÃO (PARAFUSO) | AO4: FIXAÇÃO (ARRUELA) | AT4: FIXAÇÃO (PORCA) | AY4: TOTAIS | BC4: MÃO DE OBRA (HH) / CICLO / ESCALONADO
C5: PESO UNID. (DS) | D5: PESO TOTAL (4X DS) | E5: CUSTO UNID. DS | F5: CUSTO TOTAL DS (4X) | G5: PESO UNID. (DG) | H5: PESO TOTAL (2X DG) | I5: CUSTO UNID. DG | J5: CUSTO TOTAL DG (2X) | K5: PESO UNID. (DE) | L5: PESO TOTAL (6X DE) | M5: CUSTO UNID. DE | N5: CUSTO TOTAL DE (6X) | O5: MATERIAL/DESCRIÇÃO | P5: DIMENSÃO/ESPEC. | Q5: QTD | R5: FORNECEDOR | S5: VALOR (CUSTO TOTAL TUBO) | T5: MATERIAL/DESCRIÇÃO | U5: DIMENSÃO/ESPEC. | V5: QTD | W5: FORNECEDOR | X5: VALOR UNIT. | Y5: CUSTO TOTAL (2X) | Z5: PESO UNID. | AA5: PESO TOTAL (2X) | AB5: CUSTO UNID. | AC5: CUSTO TOTAL (2X) | AD5: MATERIAL/DESCRIÇÃO | AE5: DIMENSÃO/ESPEC. | AF5: QTD | AG5: FORNECEDOR | AH5: VALOR UNIT. | AI5: CUSTO TOTAL (2X) | AJ5: MATERIAL/DESCRIÇÃO | AK5: DIMENSÃO/ESPEC. | AL5: QTD | AM5: VALOR UNIT. | AN5: VALOR TOTAL (CONJ.) | AO5: MATERIAL/DESCRIÇÃO | AP5: DIMENSÃO/ESPEC. | AQ5: QTD | AR5: VALOR UNIT. | AS5: VALOR TOTAL (CONJ.) | AT5: MATERIAL/DESCRIÇÃO | AU5: DIMENSÃO/ESPEC. | AV5: QTD | AW5: VALOR UNIT. | AX5: VALOR TOTAL (CONJ.) | AY5: CUSTO TOTAL PU (DS+DG+DE) | AZ5: CUSTO TOTAL CORPO (TUBO+FLANGES+BUMPER) | BA5: CUSTO TOTAL FIXAÇÃLO (PARAFUSO+PORCA+ARRUELA) | BB5: CUSTO TOTAL GERAL | BC5: HH (R$/h) | BD5: CICLO TOTAL | BE5: CUSTO HH CICLO | BF5: QNT PCS | BG5: CUSTO HH ESC/LOTE | BH5: CUSTO TOTAL LBD (MP + HH) | BI5: ALOJAMENTO | BJ5: CUSTO TOTAL + ALOJAMENTO
A6: LBD-DG2-DS4 | B6: 2 | E6: =IFERROR(SUMIFS('PU CAST'!$AI$10:$AI$150,'PU CAST'!$AA$10:$AA$150,"DS",'PU CAST'!$AK$10:$AK$150,$B6),0) -> 20.733333 | F6: =E6*4 -> 82.933333 | I6: =IFERROR(SUMIFS('PU CAST'!$AI$10:$AI$150,'PU CAST'!$AA$10:$AA$150,"DG",'PU CAST'!$AK$10:$AK$150,$B6),0) -> 21.173333 | J6: =I6*2 -> 42.346667 | M6: =IFERROR(SUMIFS('PU CAST'!$AI$10:$AI$150,'PU CAST'!$AA$10:$AA$150,"DE",'PU CAST'!$AK$10:$AK$150,$B6),0) -> 19.433333 | N6: =M6*6 -> 116.6 | Y6: =X6*2 -> 0 | AC6: =AB6*2 -> 0 | AI6: =AH6*2 -> 0 | AY6: =F6+J6+N6 -> 241.88 | AZ6: =S6+Y6+AC6+AI6 -> 0 | BA6: =AN6+AS6+AX6 -> 0 | BB6: =AY6+AZ6+BA6 -> 241.88 | BC6: =PARÂMETROS!$H$3 -> 40 | BD6: 0.19513889 | BE6: =(BD6*BC6)*24 -> 187.33333 | BF6: 1 | BG6: =BE6/BF6 -> 187.33333 | BH6: =BB6+BG6 -> 429.21333 | BI6: 100 | BJ6: =BH6+BI6 -> 529.21333
A7: LBD-DG2-DS4 | B7: 3 | E7: =IFERROR(SUMIFS('PU CAST'!$AI$10:$AI$150,'PU CAST'!$AA$10:$AA$150,"DS",'PU CAST'!$AK$10:$AK$150,$B7),0) -> 21.133333 | F7: =E7*4 -> 84.533333 | I7: =IFERROR(SUMIFS('PU CAST'!$AI$10:$AI$150,'PU CAST'!$AA$10:$AA$150,"DG",'PU CAST'!$AK$10:$AK$150,$B7),0) -> 22.633333 | J7: =I7*2 -> 45.266667 | M7: =IFERROR(SUMIFS('PU CAST'!$AI$10:$AI$150,'PU CAST'!$AA$10:$AA$150,"DE",'PU CAST'!$AK$10:$AK$150,$B7),0) -> 19.633333 | N7: =M7*6 -> 117.8 | Y7: =X7*2 -> 0 | AC7: =AB7*2 -> 0 | AI7: =AH7*2 -> 0 | AY7: =F7+J7+N7 -> 247.6 | AZ7: =S7+Y7+AC7+AI7 -> 0 | BA7: =AN7+AS7+AX7 -> 0 | BB7: =AY7+AZ7+BA7 -> 247.6 | BC7: =PARÂMETROS!$H$3 -> 40 | BD7: 0.19513889 | BE7: =(BD7*BC7)*24 -> 187.33333 | BF7: 1 | BG7: =BE7/BF7 -> 187.33333 | BH7: =BB7+BG7 -> 434.93333 | BI7: 100 | BJ7: =BH7+BI7 -> 534.93333
A8: LBD-DG2-DS4 | B8: 4 | E8: =IFERROR(SUMIFS('PU CAST'!$AI$10:$AI$150,'PU CAST'!$AA$10:$AA$150,"DS",'PU CAST'!$AK$10:$AK$150,$B8),0) -> 23.333333 | F8: =E8*4 -> 93.333333 | I8: =IFERROR(SUMIFS('PU CAST'!$AI$10:$AI$150,'PU CAST'!$AA$10:$AA$150,"DG",'PU CAST'!$AK$10:$AK$150,$B8),0) -> 24.053333 | J8: =I8*2 -> 48.106667 | M8: =IFERROR(SUMIFS('PU CAST'!$AI$10:$AI$150,'PU CAST'!$AA$10:$AA$150,"DE",'PU CAST'!$AK$10:$AK$150,$B8),0) -> 19.833333 | N8: =M8*6 -> 119 | Y8: =X8*2 -> 0 | AC8: =AB8*2 -> 0 | AI8: =AH8*2 -> 0 | AY8: =F8+J8+N8 -> 260.44 | AZ8: =S8+Y8+AC8+AI8 -> 0 | BA8: =AN8+AS8+AX8 -> 0 | BB8: =AY8+AZ8+BA8 -> 260.44 | BC8: =PARÂMETROS!$H$3 -> 40 | BD8: 0.19513889 | BE8: =(BD8*BC8)*24 -> 187.33333 | BF8: 1 | BG8: =BE8/BF8 -> 187.33333 | BH8: =BB8+BG8 -> 447.77333 | BI8: 100 | BJ8: =BH8+BI8 -> 547.77333
A9: LBD-DG2-DS4 | B9: 6 | C9: =D9/4 -> 0.185 | D9: =0.185*4 -> 0.74 | E9: =IFERROR(SUMIFS('PU CAST'!$AI$10:$AI$150,'PU CAST'!$AA$10:$AA$150,"DS",'PU CAST'!$AK$10:$AK$150,$B9),0) -> 28.921045 | F9: =E9*4 -> 115.68418 | G9: =H9/2 -> 0.292 | H9: =2*0.292 -> 0.584 | I9: =IFERROR(SUMIFS('PU CAST'!$AI$10:$AI$150,'PU CAST'!$AA$10:$AA$150,"DG",'PU CAST'!$AK$10:$AK$150,$B9),0) -> 28.299859 | J9: =I9*2 -> 56.599718 | K9: =L9/6 -> 0.105 | L9: =6*0.105 -> 0.63 | M9: =IFERROR(SUMIFS('PU CAST'!$AI$10:$AI$150,'PU CAST'!$AA$10:$AA$150,"DE",'PU CAST'!$AK$10:$AK$150,$B9),0) -> 23.696106 | N9: =M9*6 -> 142.17664 | O9: Tubo DN 1.1/2'' sch 40 | P9: Ø 48,3 mm x Comp. 282,4 mm | Q9: 1 | R9: Sucata MC | S9: =INDEX(PARÂMETROS!$B$83:$B$101,MATCH($B9,PARÂMETROS!$A$83:$A$101,0)) -> 21.6 | T9: Flange DN6" BUMPER | U9: Ø95 x 60 x 1/4 | V9: 1 | W9: OXIMETAL | X9: =INDEX(PARÂMETROS!$C$83:$C$101,MATCH($B9,PARÂMETROS!$A$83:$A$101,0)) -> 22 | Y9: =X9*2 -> 44 | Z9: =AA9/2 -> 0.105 | AA9: =2*0.105 -> 0.21 | AB9: =Z9*PARÂMETROS!$E$6 -> 4.19265 | AC9: =AB9*2 -> 8.3853 | AD9: Flange DN6" BUMPER | AE9: Ø95 x 60 x 1/4 | AF9: 1 | AG9: OXIMETAL | AH9: =INDEX(PARÂMETROS!$D$83:$D$101,MATCH($B9,PARÂMETROS!$A$83:$A$101,0)) -> 22 | AI9: =AH9*2 -> 44 | AJ9: Parafuso Sextavado Aço Carbono | AK9: 1/2" × 5,5" | AL9: 12 | AM9: =INDEX(PARÂMETROS!$E$83:$E$101,MATCH($B9,PARÂMETROS!$A$83:$A$101,0)) -> 7 | AN9: =AM9*AL9 -> 84 | AO9: Arruela lisa 1/2" | AP9: 1/2'' | AQ9: 12 | AR9: =INDEX(PARÂMETROS!$F$83:$F$101,MATCH($B9,PARÂMETROS!$A$83:$A$101,0)) -> 0.6 | AS9: =AR9*AQ9 -> 7.2 | AT9: Porcas Travantes Parlock 1/2" | AU9: 1/2'' | AV9: 12 | AW9: =INDEX(PARÂMETROS!$G$83:$G$101,MATCH($B9,PARÂMETROS!$A$83:$A$101,0)) -> 0.8 | AX9: =AW9*AV9 -> 9.6 | AY9: =F9+J9+N9 -> 314.46054 | AZ9: =S9+Y9+AC9+AI9 -> 117.9853 | BA9: =AN9+AS9+AX9 -> 100.8 | BB9: =AY9+AZ9+BA9 -> 533.24584 | BC9: =PARÂMETROS!$H$3 -> 40 | BD9: 0.19513889 | BE9: =(BD9*BC9)*24 -> 187.33333 | BF9: 1 | BG9: =BE9/BF9 -> 187.33333 | BH9: =BB9+BG9 -> 720.57917 | BI9: 100 | BJ9: =BH9+BI9 -> 820.57917
A10: LBD-DG2-DS4 | B10: 8 | C10: =D10/4 -> 0.416 | D10: =0.416*4 -> 1.664 | E10: =IFERROR(SUMIFS('PU CAST'!$AI$10:$AI$150,'PU CAST'!$AA$10:$AA$150,"DS",'PU CAST'!$AK$10:$AK$150,$B10),0) -> 38.672909 | F10: =E10*4 -> 154.69164 | G10: =H10/2 -> 0.53 | H10: =2*0.53 -> 1.06 | I10: =IFERROR(SUMIFS('PU CAST'!$AI$10:$AI$150,'PU CAST'!$AA$10:$AA$150,"DG",'PU CAST'!$AK$10:$AK$150,$B10),0) -> 34.159181 | J10: =I10*2 -> 68.318362 | K10: =L10/6 -> 0.201 | L10: =6*0.201 -> 1.206 | M10: =IFERROR(SUMIFS('PU CAST'!$AI$10:$AI$150,'PU CAST'!$AA$10:$AA$150,"DE",'PU CAST'!$AK$10:$AK$150,$B10),0) -> 26.05953 | N10: =M10*6 -> 156.35718 | O10: Tubo DN 1.1/2'' sch 40 | P10: Ø 48,3 mm x Comp. 333,2 mm | Q10: 1 | R10: Sucata MC | S10: =INDEX(PARÂMETROS!$B$83:$B$101,MATCH($B10,PARÂMETROS!$A$83:$A$101,0)) -> 25.2 | T10: Flange DN8" BUMPER | U10: Ø120 x 60 x 1/4 | V10: 1 | W10: OXIMETAL | X10: =INDEX(PARÂMETROS!$C$83:$C$101,MATCH($B10,PARÂMETROS!$A$83:$A$101,0)) -> 30 | Y10: =X10*2 -> 60 | Z10: =AA10/2 -> 0.201 | AA10: =2*0.201 -> 0.402 | AB10: =Z10*PARÂMETROS!$E$6 -> 8.02593 | AC10: =AB10*2 -> 16.05186 | AD10: Flange DN8" BUMPER | AE10: Ø120 x 60 x 1/4 | AF10: 1 | AG10: OXIMETAL | AH10: =INDEX(PARÂMETROS!$D$83:$D$101,MATCH($B10,PARÂMETROS!$A$83:$A$101,0)) -> 30 | AI10: =AH10*2 -> 60 | AJ10: Parafuso Sextavado Aço Carbono | AK10: 1/2" × 6,5" | AL10: 16 | AM10: =INDEX(PARÂMETROS!$E$83:$E$101,MATCH($B10,PARÂMETROS!$A$83:$A$101,0)) -> 8.5 | AN10: =AM10*AL10 -> 136 | AO10: Arruela lisa 1/2" | AP10: 1/2'' | AQ10: 16 | AR10: =INDEX(PARÂMETROS!$F$83:$F$101,MATCH($B10,PARÂMETROS!$A$83:$A$101,0)) -> 0.6 | AS10: =AR10*AQ10 -> 9.6 | AT10: Porcas Travantes Parlock 1/2" | AU10: 1/2'' | AV10: 16 | AW10: =INDEX(PARÂMETROS!$G$83:$G$101,MATCH($B10,PARÂMETROS!$A$83:$A$101,0)) -> 0.8 | AX10: =AW10*AV10 -> 12.8 | AY10: =F10+J10+N10 -> 379.36718 | AZ10: =S10+Y10+AC10+AI10 -> 161.25186 | BA10: =AN10+AS10+AX10 -> 158.4 | BB10: =AY10+AZ10+BA10 -> 699.01904 | BC10: =PARÂMETROS!$H$3 -> 40 | BD10: 0.19513889 | BE10: =(BD10*BC10)*24 -> 187.33333 | BF10: 1 | BG10: =BE10/BF10 -> 187.33333 | BH10: =BB10+BG10 -> 886.35237 | BI10: 100 | BJ10: =BH10+BI10 -> 986.35237
A11: LBD-DG2-DS4 | B11: 10 | C11: =D11/4 -> 0.784 | D11: =4*0.784 -> 3.136 | E11: =IFERROR(SUMIFS('PU CAST'!$AI$10:$AI$150,'PU CAST'!$AA$10:$AA$150,"DS",'PU CAST'!$AK$10:$AK$150,$B11),0) -> 54.208345 | F11: =E11*4 -> 216.83338 | G11: =H11/2 -> 0.923 | H11: =2*0.923 -> 1.846 | I11: =IFERROR(SUMIFS('PU CAST'!$AI$10:$AI$150,'PU CAST'!$AA$10:$AA$150,"DG",'PU CAST'!$AK$10:$AK$150,$B11),0) -> 43.834448 | J11: =I11*2 -> 87.668896 | K11: =L11/6 -> 0.261 | L11: =6*0.261 -> 1.566 | M11: =IFERROR(SUMIFS('PU CAST'!$AI$10:$AI$150,'PU CAST'!$AA$10:$AA$150,"DE",'PU CAST'!$AK$10:$AK$150,$B11),0) -> 27.53667 | N11: =M11*6 -> 165.22002 | O11: Tubo DN 3'' sch 40 | P11: Ø 88,9 mm x Comp. 384,0 mm | Q11: 1 | R11: Sucata MC | S11: =INDEX(PARÂMETROS!$B$83:$B$101,MATCH($B11,PARÂMETROS!$A$83:$A$101,0)) -> 82.8 | T11: Flange DN10" BUMPER | U11: Ø140 x 100 x 1/4 | V11: 1 | W11: OXIMETAL | X11: =INDEX(PARÂMETROS!$C$83:$C$101,MATCH($B11,PARÂMETROS!$A$83:$A$101,0)) -> 36 | Y11: =X11*2 -> 72 | Z11: =AA11/2 -> 0.261 | AA11: =2*0.261 -> 0.522 | AB11: =Z11*PARÂMETROS!$E$6 -> 10.42173 | AC11: =AB11*2 -> 20.84346 | AD11: Flange DN10" BUMPER | AE11: Ø140 x 100 x 1/4 | AF11: 1 | AG11: OXIMETAL | AH11: =INDEX(PARÂMETROS!$D$83:$D$101,MATCH($B11,PARÂMETROS!$A$83:$A$101,0)) -> 36 | AI11: =AH11*2 -> 72 | AJ11: Parafuso Sextavado Aço Carbono | AK11: 1/2" × 7" | AL11: 16 | AM11: =INDEX(PARÂMETROS!$E$83:$E$101,MATCH($B11,PARÂMETROS!$A$83:$A$101,0)) -> 9.5 | AN11: =AM11*AL11 -> 152 | AO11: Arruela lisa 1/2" | AP11: 1/2'' | AQ11: 16 | AR11: =INDEX(PARÂMETROS!$F$83:$F$101,MATCH($B11,PARÂMETROS!$A$83:$A$101,0)) -> 0.6 | AS11: =AR11*AQ11 -> 9.6 | AT11: Porcas Travantes Parlock 1/2" | AU11: 1/2'' | AV11: 16 | AW11: =INDEX(PARÂMETROS!$G$83:$G$101,MATCH($B11,PARÂMETROS!$A$83:$A$101,0)) -> 0.8 | AX11: =AW11*AV11 -> 12.8 | AY11: =F11+J11+N11 -> 469.7223 | AZ11: =S11+Y11+AC11+AI11 -> 247.64346 | BA11: =AN11+AS11+AX11 -> 174.4 | BB11: =AY11+AZ11+BA11 -> 891.76576 | BC11: =PARÂMETROS!$H$3 -> 40 | BD11: 0.19513889 | BE11: =(BD11*BC11)*24 -> 187.33333 | BF11: 1 | BG11: =BE11/BF11 -> 187.33333 | BH11: =BB11+BG11 -> 1079.0991 | BI11: 120 | BJ11: =BH11+BI11 -> 1199.0991
