Workbook

Sheet GESTAO OPERACAO
A1: CLIENTE | B1: VENDEDOR | C1: TIPO DE PEDIDO | D1: CONTRATO | E1: PEDIDO COMPRA CLIENTE | F1: PROPOSTA | G1: Nº PEDIDO TOTVS | H1: DATA INCLUSÃO PEDIDO | I1: DATA SOLICITADA ENTREGA | J1: PRAZO TOTAL (DIAS CORRIDOS) | K1: MODALIDADE FRETE | L1: PAIS | M1: ESTADO | N1: CIDADE | O1: STATUS DO PEDIDO (INFORMAÇÕES) | P1: VALOR TOTAL PEDIDO | Q1: CRITICIDADE | R1: DATA INCLUSÃO PEDIDO | S1: STATUS PRODUÇÃO | T1: PREVISÃO DE LIBERAÇÃO (PCP) | U1: DATA EFETIVA DE LIBERAÇÃO (PCP) | V1: DATA SOLICITADA NO CLIENTE OU RETIRA | W1: PRAZO COMERCIAL DIAS CORRIDOS | X1: LEAD TIME PRODUÇÃO (INCLUSÃO X LIBERAÇÃO) DIAS CORRIDOS | Y1: ATRASO / ANTECIPAÇÃO LT PRODUCAO X PRAZO TOTAL DEMANDA | Z1: CUSTO PRODUÇÃO REAL (MP/SERVIÇOS) | AA1: TÉRMINO SEMANAL (CENÁRIO REAL) PCP | AB1: DATA EMISSÃO NF | AC1: VALOR NF EMITIDA | AD1: Nº NF | AE1: STATUS LOGISTICA | AF1: DATA PEDIDO EXPEDIDO | AG1: MODALIDADE FRETE | AH1: TRANSPORTADORA (CIF) | AI1: CUSTO FRETE PREVISTO | AJ1: CUSTO FRETE FINAL | AK1: CUSTO DO FRETE SOBRE A NOTA | AL1: DATA PREVISTA ENTREGA (CIF) COLETA (FOB) (TRANSPORTE) | AM1: DATA REAL ENTREGA / COLETA | AN1: LEAD TIME FRETE (SAIDA X CHEGADA) | AO1: OTD (On-Time Delivery) *ENTREGA NO PRAZO* | AP1: DATA SOLICITADA CLIENTE | AQ1: DATA ENTREGUE CLIENTE | AR1: LEAD TIME COMERCIAL (ENTREGA NO CLIENTE OU RETIRADA) *DIAS CORRIDOS * | AS1: LEAD TIME OPERAÇÃO (ENTREGA NO CLIENTE OU RETIRADA) * DIAS CORRIDOS * | AT1: DIAS ATRASO OU ANTECIPAÇÃO * DIAS CORRIDOS * | AU1: OBS | AV1: Status Final do Pedido (ALINHAMENTO) | AW1: VALOR NF EMITIDA | AX1: CUSTO PRODUÇÃO (MP E SERVIÇOS) | AY1: CUSTO HH | AZ1: CUSTO FRETE (CIF) | BA1: CUSTO TOTAL = PRODUÇÃO + HH + FRETE
A2: ECBSEA | B2: Elder | C2: Emergencial | D2: - | E2: 3500000083 | F2: QE2025-0140-1 - | G2: 185 | H2: 45700 | I2: 46055 | J2: =I2-H2 -> 355 | K2: FOB | L2: BRASIL | M2: RJ | N2: SÃO JOÃO DA BARRA | O2: OK | P2: 693900 | Q2: Alta | R2: =H2 -> 45700 | S2: FINALIZADO | T2: 46052 | U2: 46052 | V2: =I2 -> 46055 | W2: =V2-R2 -> 355 | X2: =U2-R2 -> 352 | Y2: =W2-X2 -> 3 | Z2: 79205.68 | AA2: SEMANA 04 / JAN / 2026 | AB2: 46052 | AC2: 693900 | AD2: 7305 | AE2: Entregue / Coletado | AF2: 46055 | AG2: =K2 -> FOB | AH2: 4PIPE HIDROPIG - ENGENHARIA INDUSTRIAL LTDA | AI2: =#REF! -> #REF! | AJ2: 0 | AK2: =AJ2/AC2 -> 0 | AL2: 46055 | AM2: 46055 | AN2: =AM2-AF2 -> 0 | AO2: SIM | AP2: =I2 -> 46055 | AQ2: =AM2 -> 46055 | AR2: =AP2-H2 -> 355 | AS2: =AM2-H2 -> 355 | AT2: =AR2-AS2 -> 0 | AV2: OK | AW2: =AC2 -> 693900 | AX2: =Z2 -> 79205.68 | AZ2: =AJ2 -> 0 | BA2: =AX2+AZ2 -> 79205.68
A3: MARS MEXICO | B3: Mateus - Exportação | C3: Emergencial | D3: - | E3: 1008072089 | F3: QE2025-0053-01 | G3: 2 (SERVIÇOS) | H3: 45954 | I3: 46050 | J3: =I3-H3 -> 96 | K3: CIF | L3: MEXICO | M3: EX | N3: TOLUCA | O3: OK | P3: 211335.42 | Q3: Alta | R3: =H3 -> 45954 | S3: FINALIZADO | T3: 46043 | U3: 46043 | V3: =I3 -> 46050 | W3: =V3-R3 -> 96 | X3: =U3-R3 -> 89 | Y3: =W3-X3 -> 7 | AA3: SEMANA 03 / JAN / 2026 | AB3: 46049 | AC3: 211335.42 | AD3: 6824 | AE3: Entregue / Coletado | AF3: 46051 | AG3: =K3 -> CIF | AH3: TSA LOGISTICA LTDA | AI3: =#REF! -> #REF! | AJ3: 9497.58 | AK3: =AJ3/AC3 -> 0.044940787 | AL3: 46086 | AM3: 46086 | AN3: =AM3-AF3 -> 35 | AP3: =I3 -> 46050 | AQ3: =AM3 -> 46086 | AR3: =AP3-H3 -> 96 | AS3: =AM3-H3 -> 132 | AT3: =AR3-AS3 -> -36 | AW3: =AC3 -> 211335.42 | AX3: =Z3 -> 0 | AZ3: =AJ3 -> 9497.58 | BA3: =AX3+AZ3 -> 9497.58
A4: SUBSEA7 | B4: Elias | C4: Pedido Padrão | D4: - | E4: 3100009464 | F4: QOG2025-0248 | G4: 106(261) | H4: 45957 | I4: 46006 | J4: =I4-H4 -> 49 | K4: FOB | L4: BRASIL | M4: ES | N4: ANCHIETA | O4: OK | P4: 229259.21 | Q4: Alta | R4: =H4 -> 45957 | S4: FINALIZADO | T4: 45994 | U4: =T4 -> 45994 | V4: =I4 -> 46006 | W4: =V4-R4 -> 49 | X4: =U4-R4 -> 37 | Y4: =W4-X4 -> 12 | AA4: NOVEMBRO/2025 | AB4: 46037 | AC4: 229259.21 | AD4: 7258 | AE4: Entregue / Coletado | AF4: 46029 | AG4: =K4 -> FOB | AH4: FELKA TRANSPORTES E LOGISTICA LIMITADA | AI4: =#REF! -> #REF! | AJ4: 0 | AK4: =AJ4/AC4 -> 0 | AL4: 45994 | AM4: 45994 | AN4: =AM4-AF4 -> -35 | AO4: SIM | AP4: =I4 -> 46006 | AQ4: =AM4 -> 45994 | AR4: =AP4-H4 -> 49 | AS4: =AM4-H4 -> 37 | AT4: =AR4-AS4 -> 12 | AV4: OK | AW4: =AC4 -> 229259.21 | AX4: =Z4 -> 0 | AZ4: =AJ4 -> 0 | BA4: =AX4+AZ4 -> 0
A5: PERENCO | B5: Elder | C5: Pedido Padrão | D5: - | E5: 123026825 | F5: QOG2025-0259-7 | G5: 146 | H5: 45972 | I5: 45994 | J5: =I5-H5 -> 22 | K5: FOB | L5: BRASIL | M5: RJ | N5: MACAÉ | O5: OK | P5: 81444 | Q5: Alta | R5: =H5 -> 45972 | S5: FINALIZADO | T5: 45993 | U5: 45993 | V5: 45994 | W5: =V5-R5 -> 22 | X5: =U5-R5 -> 21 | Y5: =W5-X5 -> 1 | AA5: DEZEMBRO/2025 | AB5: 45994 | AC5: 81844 | AD5: 7185 | AE5: Entregue / Coletado | AF5: 46045 | AG5: =K5 -> FOB | AH5: EXPRESSO PREDILETO TRANSPORTES, LOGISTIC | AI5: =#REF! -> #REF! | AJ5: 0 | AK5: =AJ5/AC5 -> 0 | AL5: 45993 | AM5: 45993 | AN5: =AM5-AF5 -> -52 | AO5: SIM | AP5: =I5 -> 45994 | AQ5: =AM5 -> 45993 | AR5: =AP5-H5 -> 22 | AS5: =AM5-H5 -> 21 | AT5: =AR5-AS5 -> 1 | AV5: OK | AW5: =AC5 -> 81844 | AX5: =Z5 -> 0 | AZ5: =AJ5 -> 0 | BA5: =AX5+AZ5 -> 0
A6: PERENCO | B6: Elder | C6: Pedido Padrão | D6: - | E6: 123026825 | F6: QOG2025-0259-7 | G6: 146 | H6: 45972 | I6: 46045 | J6: =I6-H6 -> 73 | K6: FOB | L6: BRASIL | M6: RJ | N6: MACAÉ | O6: OK | P6: 43278 | Q6: Alta | R6: =H6 -> 45972 | S6: FINALIZADO | T6: 46045 | U6: 46045 | V6: =I6 -> 46045 | W6: =V6-R6 -> 73 | X6: =U6-R6 -> 73 | Y6: =W6-X6 -> 0 | AA6: DEZEMBRO/2025 | AB6: 46045 | AC6: 43278 | AD6: 7288 | AE6: Entregue / Coletado | AF6: 46045 | AG6: =K6 -> FOB | AH6: EXPRESSO PREDILETO TRANSPORTES, LOGISTIC | AI6: =#REF! -> #REF! | AJ6: 0 | AK6: =AJ6/AC6 -> 0 | AL6: 46045 | AM6: 46045 | AN6: =AM6-AF6 -> 0 | AO6: SIM | AP6: =I6 -> 46045 | AQ6: =AM6 -> 46045 | AR6: =AP6-H6 -> 73 | AS6: =AM6-H6 -> 73 | AT6: =AR6-AS6 -> 0 | AV6: OK | AW6: =AC6 -> 43278 | AX6: =Z6 -> 0 | AZ6: =AJ6 -> 0 | BA6: =AX6+AZ6 -> 0
A7: DANFOSS | B7: José Carlos | C7: Pedido Padrão | D7: - | E7: 4411884463 | F7: - | G7: 157 | H7: 45978 | I7: 46028 | J7: =I7-H7 -> 50 | K7: CIF | L7: BRASIL | M7: SP | N7: GUARATINGUETA | O7: OK | P7: 1077 | Q7: Baixa | R7: =H7 -> 45978 | S7: FINALIZADO | T7: 45999 | U7: =T7 -> 45999 | V7: =I7 -> 46028 | W7: =V7-R7 -> 50 | X7: =U7-R7 -> 21 | Y7: =W7-X7 -> 29 | AA7: DEZEMBRO/2025 | AB7: 46027 | AC7: 1077 | AD7: 7230 | AE7: Entregue / Coletado | AF7: 46028 | AG7: =K7 -> CIF | AH7: 4PIPE HIDROPIG - ENGENHARIA INDUSTRIAL LTDA | AI7: =#REF! -> #REF! | AJ7: 0 | AK7: =AJ7/AC7 -> 0 | AL7: 46028 | AM7: 46028 | AN7: =AM7-AF7 -> 0 | AO7: SIM | AP7: =I7 -> 46028 | AQ7: =AM7 -> 46028 | AR7: =AP7-H7 -> 50 | AS7: =AM7-H7 -> 50 | AT7: =AR7-AS7 -> 0 | AV7: OK | AW7: =AC7 -> 1077 | AX7: =Z7 -> 0 | AZ7: =AJ7 -> 0 | BA7: =AX7+AZ7 -> 0
A8: DANFOSS | B8: José Carlos | C8: Pedido Padrão | D8: - | E8: 4411896430 | F8: - | G8: 158 | H8: 45978 | I8: 46028 | J8: =I8-H8 -> 50 | K8: CIF | L8: BRASIL | M8: SP | N8: GUARATINGUETA | O8: OK | P8: 11790 | Q8: Baixa | R8: =H8 -> 45978 | S8: FINALIZADO | T8: 45999 | U8: =T8 -> 45999 | V8: =I8 -> 46028 | W8: =V8-R8 -> 50 | X8: =U8-R8 -> 21 | Y8: =W8-X8 -> 29 | AA8: DEZEMBRO/2025 | AB8: 46027 | AC8: 11790 | AD8: 7229 | AE8: Entregue / Coletado | AF8: 46028 | AG8: =K8 -> CIF | AH8: 4PIPE HIDROPIG - ENGENHARIA INDUSTRIAL LTDA | AI8: =#REF! -> #REF! | AJ8: 0 | AK8: =AJ8/AC8 -> 0 | AL8: 46028 | AM8: 46028 | AN8: =AM8-AF8 -> 0 | AO8: SIM | AP8: =I8 -> 46028 | AQ8: =AM8 -> 46028 | AR8: =AP8-H8 -> 50 | AS8: =AM8-H8 -> 50 | AT8: =AR8-AS8 -> 0 | AV8: OK | AW8: =AC8 -> 11790 | AX8: =Z8 -> 0 | AZ8: =AJ8 -> 0 | BA8: =AX8+AZ8 -> 0
A9: CATTALINI | B9: Isaias | C9: Pedido Padrão | D9: 113/2023 | E9: 4500009499 | F9: - | G9: 162 | H9: 45979 | I9: 46010 | J9: =I9-H9 -> 31 | K9: CIF | L9: BRASIL | M9: PR | N9: PARANAGUA | O9: OK | P9: 19374.84 | Q9: Média | R9: =H9 -> 45979 | S9: FINALIZADO | T9: 46042 | U9: 46041 | V9: =I9 -> 46010 | W9: =V9-R9 -> 31 | X9: =U9-R9 -> 62 | Y9: =W9-X9 -> -31 | Z9: 8834.86 | AA9: SEMANA 02 / JAN / 2026 | AB9: 46043 | AC9: 20437.6 | AD9: 7276 | AE9: Entregue / Coletado | AF9: 46043 | AG9: =K9 -> CIF | AH9: RODONAVES TRANSPORTES ENCOM LTDA | AI9: =#REF! -> #REF! | AJ9: 334.63 | AK9: =AJ9/AC9 -> 0.016373253 | AL9: 46052 | AM9: 46048 | AN9: =AM9-AF9 -> 5 | AO9: NÃO | AP9: =I9 -> 46010 | AQ9: =AM9 -> 46048 | AR9: =AP9-H9 -> 31 | AS9: =AM9-H9 -> 69 | AT9: =AR9-AS9 -> -38 | AU9: atraso maxbor | AV9: CRÍTICO | AW9: =AC9 -> 20437.6 | AX9: =Z9 -> 8834.86 | AZ9: =AJ9 -> 334.63 | BA9: =AX9+AZ9 -> 9169.49
A10: TOTAL EP DO BRASIL | B10: Elder | C10: Pedido Padrão | D10: - | E10: 4500176958 | F10: 4PIPE000014 | G10: 184/235 | H10: 45993 | I10: 46035 | J10: =I10-H10 -> 42 | K10: CIF | L10: BRASIL | M10: RJ | N10: CAJU | O10: OK | P10: 7335 | Q10: Alta | R10: =H10 -> 45993 | S10: FINALIZADO | T10: 46009 | U10: 46009 | V10: =I10 -> 46035 | W10: =V10-R10 -> 42 | X10: =U10-R10 -> 16 | Y10: =W10-X10 -> 26 | AA10: DEZEMBRO/2025 | AB10: 46031 | AC10: 7335 | AD10: 7239 | AE10: Entregue / Coletado | AF10: 46035 | AG10: =K10 -> CIF | AH10: 4PIPE HIDROPIG - ENGENHARIA INDUSTRIAL LTDA | AI10: =#REF! -> #REF! | AJ10: 0 | AK10: =AJ10/AC10 -> 0 | AL10: 46035 | AM10: 46035 | AN10: =AM10-AF10 -> 0 | AO10: SIM | AP10: =I10 -> 46035 | AQ10: =AM10 -> 46035 | AR10: =AP10-H10 -> 42 | AS10: =AM10-H10 -> 42 | AT10: =AR10-AS10 -> 0 | AV10: OK | AW10: =AC10 -> 7335 | AX10: =Z10 -> 0 | AZ10: =AJ10 -> 0 | BA10: =AX10+AZ10 -> 0
A11: D&D INGENIERIA CONSTRUCCION | B11: Mateus - Exportação | C11: Pedido Padrão | D11: - | E11: 0412-25 | F11: 4PIPE000096 | G11: 191 | H11: 45996 | I11: 46013 | J11: =I11-H11 -> 17 | K11: FOB | L11: CHILE | M11: EX | N11: PROVIDENCIA | O11: OK | P11: 18670.77 | Q11: Alta | R11: =H11 -> 45996 | S11: FINALIZADO | T11: 46013 | U11: =T11 -> 46013 | V11: =I11 -> 46013 | W11: =V11-R11 -> 17 | X11: =U11-R11 -> 17 | Y11: =W11-X11 -> 0 | AA11: DEZEMBRO/2025 | AB11: 46028 | AC11: 18670.77 | AD11: 7232 | AE11: Entregue / Coletado | AF11: 46029 | AG11: =K11 -> FOB | AH11: TRANS-FERRARI TRANSPORTE E LOGISTICA LTD | AI11: =#REF! -> #REF! | AJ11: 0 | AK11: =AJ11/AC11 -> 0 | AL11: 46014 | AM11: 46014 | AN11: =AM11-AF11 -> -15 | AO11: NÃO | AP11: =I11 -> 46013 | AQ11: =AM11 -> 46014 | AR11: =AP11-H11 -> 17 | AS11: =AM11-H11 -> 18 | AT11: =AR11-AS11 -> -1 | AV11: ATENÇÃO | AW11: =AC11 -> 18670.77 | AX11: =Z11 -> 0 | AZ11: =AJ11 -> 0 | BA11: =AX11+AZ11 -> 0
A12: VOPAK SANTOS | B12: José Carlos | C12: Pedido Padrão | D12: - | E12: P6913483 | F12: 4PIPE000152 | G12: 192 (226) | H12: 45996 | I12: 46048 | J12: =I12-H12 -> 52 | K12: CIF | L12: BRASIL | M12: SP | N12: SANTOS | O12: OK | P12: 36862.2 | Q12: Alta | R12: =H12 -> 45996 | S12: FINALIZADO | T12: 46048 | U12: 46045 | V12: =I12 -> 46048 | W12: =V12-R12 -> 52 | X12: =U12-R12 -> 49 | Y12: =W12-X12 -> 3 | Z12: 7919.93 | AA12: SEMANA 03 / JAN / 2026 | AB12: 46045 | AC12: 36862.2 | AD12: 7287 | AE12: Entregue / Coletado | AF12: 46048 | AG12: =K12 -> CIF | AH12: 4PIPE HIDROPIG - ENGENHARIA INDUSTRIAL LTDA | AI12: =#REF! -> #REF! | AJ12: 0 | AK12: =AJ12/AC12 -> 0 | AL12: 46048 | AM12: 46048 | AN12: =AM12-AF12 -> 0 | AO12: SIM | AP12: =I12 -> 46048 | AQ12: =AM12 -> 46048 | AR12: =AP12-H12 -> 52 | AS12: =AM12-H12 -> 52 | AT12: =AR12-AS12 -> 0 | AV12: OK | AW12: =AC12 -> 36862.2 | AX12: =Z12 -> 7919.93 | AZ12: =AJ12 -> 0 | BA12: =AX12+AZ12 -> 7919.93
A13: BAKER HUGHES | B13: Elder | C13: Pedido Padrão | D13: - | E13: 555730763 | F13: - | G13: 194 | H13: 45999 | I13: 46035 | J13: =I13-H13 -> 36 | K13: CIF | L13: BRASIL | M13: RJ | N13: NITERÓI | O13: OK | P13: 5253 | Q13: Média | R13: =H13 -> 45999 | S13: FINALIZADO | T13: 46009 | U13: =T13 -> 46009 | V13: =I13 -> 46035 | W13: =V13-R13 -> 36 | X13: =U13-R13 -> 10 | Y13: =W13-X13 -> 26 | AA13: DEZEMBRO/2025 | AB13: 46034 | AC13: 5253 | AD13: 7244 | AE13: Entregue / Coletado | AF13: 46035 | AG13: =K13 -> CIF | AH13: 4PIPE HIDROPIG - ENGENHARIA INDUSTRIAL LTDA | AI13: =#REF! -> #REF! | AJ13: 0 | AK13: =AJ13/AC13 -> 0 | AL13: 46035 | AM13: 46035 | AN13: =AM13-AF13 -> 0 | AO13: SIM | AP13: =I13 -> 46035 | AQ13: =AM13 -> 46035 | AR13: =AP13-H13 -> 36 | AS13: =AM13-H13 -> 36 | AT13: =AR13-AS13 -> 0 | AV13: OK | AW13: =AC13 -> 5253 | AX13: =Z13 -> 0 | AZ13: =AJ13 -> 0 | BA13: =AX13+AZ13 -> 0
A14: BAKER HUGHES | B14: Elder | C14: Pedido Padrão | D14: - | E14: 555730764 | F14: - | G14: 195 | H14: 45999 | I14: 46035 | J14: =I14-H14 -> 36 | K14: CIF | L14: BRASIL | M14: RJ | N14: NITERÓI | O14: OK | P14: 22541 | Q14: Média | R14: =H14 -> 45999 | S14: FINALIZADO | T14: =T13 -> 46009 | U14: =T14 -> 46009 | V14: =I14 -> 46035 | W14: =V14-R14 -> 36 | X14: =U14-R14 -> 10 | Y14: =W14-X14 -> 26 | AA14: DEZEMBRO/2025 | AB14: 46034 | AC14: 22541 | AD14: 7245 | AE14: Entregue / Coletado | AF14: 46035 | AG14: =K14 -> CIF | AH14: 4PIPE HIDROPIG - ENGENHARIA INDUSTRIAL LTDA | AI14: =#REF! -> #REF! | AJ14: 0 | AK14: =AJ14/AC14 -> 0 | AL14: 46035 | AM14: 46035 | AN14: =AM14-AF14 -> 0 | AO14: SIM | AP14: =I14 -> 46035 | AQ14: =AM14 -> 46035 | AR14: =AP14-H14 -> 36 | AS14: =AM14-H14 -> 36 | AT14: =AR14-AS14 -> 0 | AV14: OK | AW14: =AC14 -> 22541 | AX14: =Z14 -> 0 | AZ14: =AJ14 -> 0 | BA14: =AX14+AZ14 -> 0
A15: PETROBRAS MACAÉ | B15: Elder | C15: Pedido Padrão | D15: - | F15: 4PIPE000097 | G15: 205 | H15: 46002 | I15: 46091 | J15: =I15-H15 -> 89 | K15: CIF | L15: BRASIL | M15: RJ | N15: MACAÉ | O15: OK | P15: 3873.04 | Q15: Baixa | R15: =H15 -> 46002 | S15: FINALIZADO | T15: 46027 | U15: 46028 | V15: =I15 -> 46091 | W15: =V15-R15 -> 89 | X15: =U15-R15 -> 26 | Y15: =W15-X15 -> 63 | Z15: 175.08 | AA15: SEMANA 01 / JAN / 2026 | AB15: 46043 | AC15: 3873.06 | AD15: 7280 | AE15: Entregue / Coletado | AF15: 46045 | AG15: =K15 -> CIF | AH15: EMPRESA DE TRANSPORTES MARTINS LTDA | AI15: =#REF! -> #REF! | AJ15: 216.09 | AK15: =AJ15/AC15 -> 0.055793094 | AL15: 46052 | AM15: 46052 | AN15: =AM15-AF15 -> 7 | AO15: SIM | AP15: =I15 -> 46091 | AQ15: =AM15 -> 46052 | AR15: =AP15-H15 -> 89 | AS15: =AM15-H15 -> 50 | AT15: =AR15-AS15 -> 39 | AV15: OK | AW15: =AC15 -> 3873.06 | AX15: =Z15 -> 175.08 | AZ15: =AJ15 -> 216.09 | BA15: =AX15+AZ15 -> 391.17
A16: BAKER HUGHES | B16: Elder | C16: Pedido Padrão | D16: - | E16: 950263111 | F16: - | G16: 203 | H16: 46006 | I16: 46035 | J16: =I16-H16 -> 29 | K16: CIF | L16: BRASIL | M16: RJ | N16: NITERÓI | O16: OK | P16: 11708.55 | Q16: Média | R16: =H16 -> 46006 | S16: FINALIZADO | T16: 46013 | U16: =T16 -> 46013 | V16: =I16 -> 46035 | W16: =V16-R16 -> 29 | X16: =U16-R16 -> 7 | Y16: =W16-X16 -> 22 | AA16: DEZEMBRO/2025 | AB16: 46034 | AC16: 11708.55 | AD16: 7241 | AE16: Entregue / Coletado | AF16: 46034 | AG16: =K16 -> CIF | AH16: 4PIPE HIDROPIG - ENGENHARIA INDUSTRIAL LTDA | AI16: =#REF! -> #REF! | AJ16: 0 | AK16: =AJ16/AC16 -> 0 | AL16: 46035 | AM16: 46035 | AN16: =AM16-AF16 -> 1 | AO16: SIM | AP16: =I16 -> 46035 | AQ16: =AM16 -> 46035 | AR16: =AP16-H16 -> 29 | AS16: =AM16-H16 -> 29 | AT16: =AR16-AS16 -> 0 | AV16: OK | AW16: =AC16 -> 11708.55 | AX16: =Z16 -> 0 | AZ16: =AJ16 -> 0 | BA16: =AX16+AZ16 -> 0
A17: BAKER HUGHES | B17: Elder | C17: Pedido Padrão | D17: - | E17: 950263145 | F17: - | G17: 204 | H17: 46006 | I17: 46035 | J17: =I17-H17 -> 29 | K17: CIF | L17: BRASIL | M17: RJ | N17: NITERÓI | O17: OK | P17: 8962.1 | Q17: Média | R17: =H17 -> 46006 | S17: FINALIZADO | T17: =T16 -> 46013 | U17: 46013 | V17: =I17 -> 46035 | W17: =V17-R17 -> 29 | X17: =U17-R17 -> 7 | Y17: =W17-X17 -> 22 | AA17: DEZEMBRO/2025 | AB17: 46034 | AC17: 8962.1 | AD17: 7242 | AE17: Entregue / Coletado | AF17: 46034 | AG17: =K17 -> CIF | AH17: 4PIPE HIDROPIG - ENGENHARIA INDUSTRIAL LTDA | AI17: =#REF! -> #REF! | AJ17: 0 | AK17: =AJ17/AC17 -> 0 | AL17: 46035 | AM17: 46035 | AN17: =AM17-AF17 -> 1 | AO17: SIM | AP17: =I17 -> 46035 | AQ17: =AM17 -> 46035 | AR17: =AP17-H17 -> 29 | AS17: =AM17-H17 -> 29 | AT17: =AR17-AS17 -> 0 | AV17: OK | AW17: =AC17 -> 8962.1 | AX17: =Z17 -> 0 | AZ17: =AJ17 -> 0 | BA17: =AX17+AZ17 -> 0
A18: PETROBRAS MACAÉ | B18: Elder | C18: Pedido Padrão | D18: - | E18: 4514848558 | F18: - | G18: 206 | H18: 46006 | I18: 46035 | J18: =I18-H18 -> 29 | K18: CIF | L18: BRASIL | M18: RJ | N18: MACAÉ | O18: OK | P18: 17871.1 | Q18: Média | R18: =H18 -> 46006 | S18: FINALIZADO | T18: 46034 | U18: 46034 | V18: =I18 -> 46035 | W18: =V18-R18 -> 29 | X18: =U18-R18 -> 28 | Y18: =W18-X18 -> 1 | Z18: 1700.73 | AA18: SEMANA 01 / JAN / 2026 | AB18: 46036 | AC18: 17871.1 | AD18: 7250 | AE18: Entregue / Coletado | AF18: 46038 | AG18: =K18 -> CIF | AH18: EMPRESA DE TRANSPORTES MARTINS LTDA | AI18: =#REF! -> #REF! | AJ18: 550.49 | AK18: =AJ18/AC18 -> 0.030803364 | AL18: 46045 | AM18: 46045 | AN18: =AM18-AF18 -> 7 | AO18: NÃO | AP18: =I18 -> 46035 | AQ18: =AM18 -> 46045 | AR18: =AP18-H18 -> 29 | AS18: =AM18-H18 -> 39 | AT18: =AR18-AS18 -> -10 | AU18: ATRASO PRODUÇÃO DEVIDO A PAUSA DO RECESSO FIM DE ANO. | AV18: ATENÇÃO | AW18: =AC18 -> 17871.1 | AX18: =Z18 -> 1700.73 | AZ18: =AJ18 -> 550.49 | BA18: =AX18+AZ18 -> 2251.22
A19: PETROBRAS MACAÉ | B19: José Carlos | C19: Pedido Padrão | D19: 4600677427 | E19: 4514868591 | F19: - | G19: 208 /424 | H19: 46006 | I19: 46036 | J19: =I19-H19 -> 30 | K19: CIF | L19: BRASIL | M19: SP | N19: CUBATÃO | O19: OK | P19: 2123.54 | Q19: Média | R19: =H19 -> 46006 | S19: FINALIZADO | T19: 46028 | U19: 46028 | V19: =I19 -> 46036 | W19: =V19-R19 -> 30 | X19: =U19-R19 -> 22 | Y19: =W19-X19 -> 8 | Z19: 207.93 | AA19: SEMANA 01 / JAN / 2026 | AB19: 46104 | AC19: 2123.54 | AD19: 7440 | AE19: Entregue / Coletado | AF19: 46104 | AG19: =K19 -> CIF | AH19: 4PIPE HIDROPIG - ENGENHARIA INDUSTRIAL LTDA | AI19: =#REF! -> #REF! | AJ19: 0 | AK19: =AJ19/AC19 -> 0 | AL19: 46028 | AM19: 46105 | AN19: =AM19-AF19 -> 1 | AO19: SIM | AP19: 46105 | AQ19: =AM19 -> 46105 | AR19: =AP19-H19 -> 99 | AS19: =AM19-H19 -> 99 | AT19: =AR19-AS19 -> 0 | AU19: recusa na entrega em janeiro /// entrega feita em março /// prazo entrega ajustado na gestao para não prejudicar o OTD | AV19: CRÍTICO | AW19: =AC19 -> 2123.54 | AX19: =Z19 -> 207.93 | AZ19: =AJ19 -> 0 | BA19: =AX19+AZ19 -> 207.93
A20: TRANSPETRO CARAGUA | B20: José Carlos | C20: Reforma | D20: - | G20: N/A | H20: 46006 | I20: 46052 | J20: =I20-H20 -> 46 | K20: CIF | M20: SP | O20: OK | P20: 91000 | Q20: Alta | R20: =H20 -> 46006 | S20: FINALIZADO | T20: 46041 | U20: 46042 | V20: =I20 -> 46052 | W20: =V20-R20 -> 46 | X20: =U20-R20 -> 36 | Y20: =W20-X20 -> 10 | AA20: SEMANA 02 / JAN / 2026 | AB20: 46042 | AC20: 91000 | AD20: 7270 | AE20: Entregue / Coletado | AF20: 46043 | AG20: =K20 -> CIF | AH20: 4PIPE HIDROPIG - ENGENHARIA INDUSTRIAL LTDA | AI20: =#REF! -> #REF! | AJ20: 0 | AK20: =AJ20/AC20 -> 0 | AL20: 46044 | AM20: 46044 | AN20: =AM20-AF20 -> 1 | AO20: SIM | AP20: =I20 -> 46052 | AQ20: =AM20 -> 46044 | AR20: =AP20-H20 -> 46 | AS20: =AM20-H20 -> 38 | AT20: =AR20-AS20 -> 8 | AU20: comunicação produção (liderança x operação), impactando planejamento realizado... Discutir com lideres causa x plano de ação | AV20: ATENÇÃO | AW20: 0 | AX20: =Z20 -> 0 | AZ20: =AJ20 -> 0 | BA20: =AX20+AZ20 -> 0
A21: PETROBRAS MACAÉ | B21: Elder | C21: Pedido Padrão | D21: 4600677427 | E21: 4514868099 | F21: - | G21: 209 | H21: 46007 | I21: 46036 | J21: =I21-H21 -> 29 | K21: CIF | L21: BRASIL | M21: RJ | N21: MACAÉ | O21: OK | P21: 3130.16 | Q21: Média | R21: =H21 -> 46007 | S21: FINALIZADO | T21: 46028 | U21: 46028 | V21: =I21 -> 46036 | W21: =V21-R21 -> 29 | X21: =U21-R21 -> 21 | Y21: =W21-X21 -> 8 | Z21: 1001.37 | AA21: SEMANA 01 / JAN / 2026 | AB21: 46029 | AC21: 3130.16 | AD21: 7235 | AE21: Entregue / Coletado | AF21: 46045 | AG21: CIF | AH21: EMPRESA DE TRANSPORTES MARTINS LTDA | AI21: =#REF! -> #REF! | AJ21: 500 | AK21: =AJ21/AC21 -> 0.15973624 | AL21: 46050 | AM21: 46050 | AN21: =AM21-AF21 -> 5 | AO21: SIM | AP21: =I21 -> 46036 | AQ21: =AM21 -> 46050 | AR21: =AP21-H21 -> 29 | AS21: =AM21-H21 -> 43 | AT21: =AR21-AS21 -> -14 | AV21: ATENÇÃO | AW21: =AC21 -> 3130.16 | AX21: =Z21 -> 1001.37 | AZ21: =AJ21 -> 500 | BA21: =AX21+AZ21 -> 1501.37
A22: ERAM | B22: Mateus - Exportação | C22: Pedido Padrão | D22: - | E22: - | F22: 4PIPE00078 | G22: 210 | H22: 46007 | I22: 46079 | J22: =I22-H22 -> 72 | K22: CIF | L22: ARGENTINA | M22: EX | N22: BUENOS AIRES | O22: OK | P22: 87407.33 | Q22: Alta | R22: =H22 -> 46007 | S22: FINALIZADO | T22: 46079 | U22: 46079 | V22: =I22 -> 46079 | W22: =V22-R22 -> 72 | X22: =U22-R22 -> 72 | Y22: =W22-X22 -> 0 | Z22: 32373.63 | AA22: SEMANA 04 / FEV / 2026 | AB22: 46080 | AC22: 94904.81 | AD22: 7377 | AE22: Entregue / Coletado | AF22: 46084 | AG22: FOB | AH22: TRANSPORTES VITANGELO MUNHOZ LOGISTICA | AI22: =#REF! -> #REF! | AJ22: 0 | AK22: =AJ22/AC22 -> 0 | AL22: 46084 | AM22: 46079 | AN22: =AM22-AF22 -> -5 | AO22: SIM | AP22: =I22 -> 46079 | AQ22: =AM22 -> 46079 | AR22: =AP22-H22 -> 72 | AS22: =AM22-H22 -> 72 | AT22: =AR22-AS22 -> 0 | AV22: OK | AW22: =AC22 -> 94904.81 | AX22: =Z22 -> 32373.63 | AZ22: =AJ22 -> 0 | BA22: =AX22+AZ22 -> 32373.63
A23: NOVELIS | B23: José Carlos | C23: Pedido Padrão | D23: - | E23: 496601 | F23: 4PIPE000141 | G23: 212 | H23: 46007 | I23: 46052 | J23: =I23-H23 -> 45 | K23: FOB | L23: BRASIL | M23: SP | N23: PINDAMONHANGABA | O23: OK | P23: 6178 | Q23: Baixa | R23: =H23 -> 46007 | S23: FINALIZADO | T23: 46042 | U23: 46031 | V23: =I23 -> 46052 | W23: =V23-R23 -> 45 | X23: =U23-R23 -> 24 | Y23: =W23-X23 -> 21 | Z23: 302.11 | AA23: SEMANA 01 / JAN / 2026 | AB23: 46035 | AC23: 6178 | AD23: 7249 | AE23: Entregue / Coletado | AF23: 46045 | AG23: =K23 -> FOB | AH23: NOVELIS DO BRASIL LTDA. | AI23: =#REF! -> #REF! | AJ23: 0 | AK23: =AJ23/AC23 -> 0 | AL23: 46034 | AM23: 46034 | AN23: =AM23-AF23 -> -11 | AO23: SIM | AP23: =I23 -> 46052 | AQ23: =AM23 -> 46034 | AR23: =AP23-H23 -> 45 | AS23: =AM23-H23 -> 27 | AT23: =AR23-AS23 -> 18 | AV23: OK | AW23: =AC23 -> 6178 | AX23: =Z23 -> 302.11 | AZ23: =AJ23 -> 0 | BA23: =AX23+AZ23 -> 302.11
A24: BAKER | B24: Elder | C24: Pedido Padrão | D24: - | E24: 555731050 | F24: - | G24: 213 | H24: 46007 | I24: 46042 | J24: =I24-H24 -> 35 | K24: CIF | L24: BRASIL | M24: RJ | N24: NITERÓI | O24: OK | P24: 60588 | Q24: Média | R24: =H24 -> 46007 | S24: FINALIZADO | T24: 46037 | U24: 46037 | V24: =I24 -> 46042 | W24: =V24-R24 -> 35 | X24: =U24-R24 -> 30 | Y24: =W24-X24 -> 5 | Z24: 2931.69 | AA24: SEMANA 02 / JAN / 2026 | AB24: 46042 | AC24: 60588 | AD24: 7267 | AE24: Entregue / Coletado | AF24: 46043 | AG24: =K24 -> CIF | AH24: 4PIPE HIDROPIG - ENGENHARIA INDUSTRIAL LTDA | AI24: =#REF! -> #REF! | AJ24: 0 | AK24: =AJ24/AC24 -> 0 | AL24: 46043 | AM24: 46043 | AN24: =AM24-AF24 -> 0 | AO24: NÃO | AP24: =I24 -> 46042 | AQ24: =AM24 -> 46043 | AR24: =AP24-H24 -> 35 | AS24: =AM24-H24 -> 36 | AT24: =AR24-AS24 -> -1 | AU24: ATRASO PRODUÇÃO DEVIDO A PAUSA DO RECESSO FIM DE ANO. | AV24: ATENÇÃO | AW24: =AC24 -> 60588 | AX24: =Z24 -> 2931.69 | AZ24: =AJ24 -> 0 | BA24: =AX24+AZ24 -> 2931.69
A25: OIL STATES | B25: Elder | C25: Pedido Padrão | D25: - | E25: 060385-2 | F25: 4PIPE000177 | G25: 221 | H25: 46007 | I25: 46051 | J25: =I25-H25 -> 44 | K25: FOB | M25: RJ | N25: MACAÉ | O25: OK | P25: 13489 | Q25: Média | R25: =H25 -> 46007 | S25: FINALIZADO | T25: 46050 | U25: 46050 | V25: =I25 -> 46051 | W25: =V25-R25 -> 44 | X25: =U25-R25 -> 43 | Y25: =W25-X25 -> 1 | Z25: 9027.89 | AA25: SEMANA 04 / JAN / 2026 | AB25: 46058 | AC25: 13524.59 | AD25: 7318 | AE25: Entregue / Coletado | AF25: 46059 | AG25: =K25 -> FOB | AH25: THS TRANSPORTE E LOGISTICA LTDA - EPP | AI25: =#REF! -> #REF! | AJ25: 0 | AK25: =AJ25/AC25 -> 0 | AL25: 46051 | AM25: 46051 | AN25: =AM25-AF25 -> -8 | AO25: SIM | AP25: =I25 -> 46051 | AQ25: =AM25 -> 46051 | AR25: =AP25-H25 -> 44 | AS25: =AM25-H25 -> 44 | AT25: =AR25-AS25 -> 0 | AU25: REVISAR CUSTOS PRODUÇÃO/COMERCIAL | AV25: CRÍTICO | AW25: =AC25 -> 13524.59 | AX25: =Z25 -> 9027.89 | AZ25: =AJ25 -> 0 | BA25: =AX25+AZ25 -> 9027.89
A26: LOGUM | B26: Mateus - Exportação | C26: Reforma | D26: - | E26: 4500013180 | F26: 4PIPE000157 | G26: 218 | H26: 46013 | I26: 46052 | J26: =I26-H26 -> 39 | K26: FOB | L26: BRASIL | M26: SP | N26: CUMBICA | O26: OK | P26: 7105.7 | Q26: Alta | R26: =H26 -> 46013 | S26: FINALIZADO | T26: 46043 | U26: 46038 | V26: =I26 -> 46052 | W26: =V26-R26 -> 39 | X26: =U26-R26 -> 25 | Y26: =W26-X26 -> 14 | Z26: 1056.86 | AA26: SEMANA 02 / JAN / 2026 | AB26: 46042 | AC26: 8578.5 | AD26: 7274 | AE26: Entregue / Coletado | AF26: 46043 | AG26: =K26 -> FOB | AH26: LOGUM LOGISTICA S A | AI26: =#REF! -> #REF! | AJ26: 0 | AK26: =AJ26/AC26 -> 0 | AL26: 46043 | AM26: 46043 | AN26: =AM26-AF26 -> 0 | AO26: SIM | AP26: =I26 -> 46052 | AQ26: =AM26 -> 46043 | AR26: =AP26-H26 -> 39 | AS26: =AM26-H26 -> 30 | AT26: =AR26-AS26 -> 9 | AV26: OK | AW26: =AC26 -> 8578.5 | AX26: =Z26 -> 1056.86 | AZ26: =AJ26 -> 0 | BA26: =AX26+AZ26 -> 1056.86
A27: AURORA | B27: Isaias | C27: Pedido Padrão | D27: - | E27: 4448633 | F27: 4PIPE000187 | G27: 219 | H27: 46013 | I27: 46048 | J27: =I27-H27 -> 35 | K27: CIF | L27: BRASIL | M27: SC | N27: ABELARDO LUZ | O27: OK | P27: 8353.2 | Q27: Média | R27: =H27 -> 46013 | S27: FINALIZADO | T27: 46029 | U27: 46030 | V27: =I27 -> 46048 | W27: =V27-R27 -> 35 | X27: =U27-R27 -> 17 | Y27: =W27-X27 -> 18 | Z27: 172.18 | AA27: SEMANA 01 / JAN / 2026 | AB27: 46035 | AC27: 8353.2 | AD27: 7247 | AE27: Entregue / Coletado | AF27: 46036 | AG27: =K27 -> CIF | AH27: RODONAVES TRANSPORTES ENCOM LTDA | AI27: =#REF! -> #REF! | AJ27: 198.22 | AK27: =AJ27/AC27 -> 0.023729828 | AL27: 46048 | AM27: 46043 | AN27: =AM27-AF27 -> 7 | AO27: SIM | AP27: =I27 -> 46048 | AQ27: =AM27 -> 46043 | AR27: =AP27-H27 -> 35 | AS27: =AM27-H27 -> 30 | AT27: =AR27-AS27 -> 5 | AV27: OK | AW27: =AC27 -> 8353.2 | AX27: =Z27 -> 172.18 | AZ27: =AJ27 -> 198.22 | BA27: =AX27+AZ27 -> 370.4 | BB27: VENDA CUSTO BAIXO
A28: ULTRACARGO | B28: Saulo | C28: Pedido Padrão | D28: - | E28: 5700023797 | F28: 4PIPE000190 | G28: 220 | H28: 46013 | I28: 46048 | J28: =I28-H28 -> 35 | K28: CIF | L28: BRASIL | M28: PE | N28: IPOJUCA | O28: OK | P28: 3507 | Q28: Média | R28: =H28 -> 46013 | S28: FINALIZADO | T28: 46035 | U28: 46031 | V28: =I28 -> 46048 | W28: =V28-R28 -> 35 | X28: =U28-R28 -> 18 | Y28: =W28-X28 -> 17 | Z28: 391.82 | AA28: SEMANA 01 / JAN / 2026 | AB28: 46035 | AC28: 3507 | AD28: 7248 | AE28: Entregue / Coletado | AF28: 46036 | AG28: =K28 -> CIF | AH28: RODONAVES TRANSPORTES MULTIMODAL LTDA | AI28: =#REF! -> #REF! | AJ28: 183.52 | AK28: =AJ28/AC28 -> 0.052329626 | AL28: 46045 | AM28: 46043 | AN28: =AM28-AF28 -> 7 | AO28: SIM | AP28: =I28 -> 46048 | AQ28: =AM28 -> 46043 | AR28: =AP28-H28 -> 35 | AS28: =AM28-H28 -> 30 | AT28: =AR28-AS28 -> 5 | AV28: OK | AW28: =AC28 -> 3507 | AX28: =Z28 -> 391.82 | AZ28: =AJ28 -> 183.52 | BA28: =AX28+AZ28 -> 575.34
A29: AURORA | B29: Isaias | C29: Pedido Padrão | D29: - | E29: 4452851 | F29: 4PIPE000181 | G29: 223 | H29: 46027 | I29: 46050 | J29: =I29-H29 -> 23 | K29: CIF | L29: BRASIL | M29: SC | N29: CHAPECÓ | O29: OK | P29: 3510 | Q29: Média | R29: =H29 -> 46027 | S29: FINALIZADO | T29: 46036 | U29: 46037 | V29: =I29 -> 46050 | W29: =V29-R29 -> 23 | X29: =U29-R29 -> 10 | Y29: =W29-X29 -> 13 | Z29: 102.4 | AA29: SEMANA 02 / JAN / 2026 | AB29: 46038 | AC29: 3510 | AD29: 7260 | AE29: Entregue / Coletado | AF29: 46038 | AG29: =K29 -> CIF | AH29: RODONAVES TRANSPORTES ENCOM LTDA | AI29: =#REF! -> #REF! | AJ29: 369.95 | AK29: =AJ29/AC29 -> 0.10539886 | AL29: 46048 | AM29: 46050 | AN29: =AM29-AF29 -> 12 | AO29: SIM | AP29: =I29 -> 46050 | AQ29: =AM29 -> 46050 | AR29: =AP29-H29 -> 23 | AS29: =AM29-H29 -> 23 | AT29: =AR29-AS29 -> 0 | AV29: OK | AW29: =AC29 -> 3510 | AX29: =Z29 -> 102.4 | AZ29: =AJ29 -> 369.95 | BA29: =AX29+AZ29 -> 472.35
A30: CARMO ENERGY | B30: Rui | C30: Pedido Padrão | D30: - | E30: 4300000145 | F30: 4PIPE000184 | G30: 225 | H30: 46027 | I30: 46051 | J30: =I30-H30 -> 24 | K30: CIF | L30: BRASIL | M30: SE | N30: JAPARATUBA | O30: OK | P30: 6440 | Q30: Média | R30: =H30 -> 46027 | S30: FINALIZADO | T30: 46038 | U30: 46037 | V30: =I30 -> 46051 | W30: =V30-R30 -> 24 | X30: =U30-R30 -> 10 | Y30: =W30-X30 -> 14 | Z30: 414.94 | AA30: SEMANA 02 / JAN / 2026 | AB30: 46038 | AC30: 6440.02 | AD30: 7261 | AE30: Entregue / Coletado | AF30: 46041 | AG30: =K30 -> CIF | AH30: GRU AVIAT CARGO EXPRESS TRANSPORTES LTDA | AI30: =#REF! -> #REF! | AJ30: 817.79 | AK30: =AJ30/AC30 -> 0.12698563 | AL30: 46049 | AM30: 46052 | AN30: =AM30-AF30 -> 11 | AO30: NÃO | AP30: =I30 -> 46051 | AQ30: =AM30 -> 46052 | AR30: =AP30-H30 -> 24 | AS30: =AM30-H30 -> 25 | AT30: =AR30-AS30 -> -1 | AV30: ATENÇÃO | AW30: =AC30 -> 6440.02 | AX30: =Z30 -> 414.94 | AZ30: =AJ30 -> 817.79 | BA30: =AX30+AZ30 -> 1232.73
A31: 3R BRAVA | B31: Saulo | C31: Pedido Padrão | D31: - | E31: 218155 | F31: 4PIPE000171 | G31: 227 | H31: 46027 | I31: 46062 | J31: =I31-H31 -> 35 | K31: CIF | L31: BRASIL | M31: RN | N31: MOSSÓRO | O31: OK | P31: 26000 | Q31: Média | R31: =H31 -> 46027 | S31: FINALIZADO | T31: 46038 | U31: 46041 | V31: =I31 -> 46062 | W31: =V31-R31 -> 35 | X31: =U31-R31 -> 14 | Y31: =W31-X31 -> 21 | Z31: 3909.86 | AA31: SEMANA 02 / JAN / 2026 | AB31: 46042 | AC31: 26000 | AD31: 7275 | AE31: Entregue / Coletado | AF31: 46045 | AG31: =K31 -> CIF | AH31: AVIAT CARGO EXPRESS TRANSPORTES LTDA | AI31: =#REF! -> #REF! | AJ31: 1721.29 | AK31: =AJ31/AC31 -> 0.066203462 | AL31: 46058 | AM31: 46052 | AN31: =AM31-AF31 -> 7 | AO31: SIM | AP31: =I31 -> 46062 | AQ31: =AM31 -> 46052 | AR31: =AP31-H31 -> 35 | AS31: =AM31-H31 -> 25 | AT31: =AR31-AS31 -> 10 | AV31: OK | AW31: =AC31 -> 26000 | AX31: =Z31 -> 3909.86 | AZ31: =AJ31 -> 1721.29 | BA31: =AX31+AZ31 -> 5631.15
A32: PERENCO | B32: Elder | C32: Pedido Padrão | D32: - | E32: 123027795 | F32: 4PIPE000168-1 | G32: 228 | H32: 46027 | I32: 46052 | J32: =I32-H32 -> 25 | K32: FOB | L32: BRASIL | M32: RJ | N32: SÃO JOÃO DA BARRA | O32: OK | P32: 25019.64 | Q32: Alta | R32: =H32 -> 46027 | S32: FINALIZADO | T32: 46045 | U32: 46045 | V32: =I32 -> 46052 | W32: =V32-R32 -> 25 | X32: =U32-R32 -> 18 | Y32: =W32-X32 -> 7 | Z32: 5940 | AA32: SEMANA 03 / JAN / 2026 | AB32: 46044 | AC32: 25019.63 | AD32: 7292 | AE32: Entregue / Coletado | AF32: 46045 | AG32: =K32 -> FOB | AH32: EXPRESSO PREDILETO TRANSPORTES, LOGISTIC | AI32: =#REF! -> #REF! | AJ32: 0 | AK32: =AJ32/AC32 -> 0 | AL32: 46045 | AM32: 46045 | AN32: =AM32-AF32 -> 0 | AO32: SIM | AP32: =I32 -> 46052 | AQ32: =AM32 -> 46045 | AR32: =AP32-H32 -> 25 | AS32: =AM32-H32 -> 18 | AT32: =AR32-AS32 -> 7 | AV32: OK | AW32: =AC32 -> 25019.63 | AX32: =Z32 -> 5940 | AZ32: =AJ32 -> 0 | BA32: =AX32+AZ32 -> 5940
A33: PERENCO | B33: Elder | C33: Pedido Padrão | D33: - | E33: 123027809 | F33: 4PIPE000183 | G33: 253 | H33: 46027 | I33: 46036 | J33: =I33-H33 -> 9 | K33: FOB | L33: BRASIL | M33: RJ | N33: SÃO JOÃO DA BARRA | O33: OK | P33: 10559.12 | Q33: Alta | R33: =H33 -> 46027 | S33: FINALIZADO | T33: 46036 | U33: 46036 | V33: =I33 -> 46036 | W33: =V33-R33 -> 9 | X33: =U33-R33 -> 9 | Y33: =W33-X33 -> 0 | Z33: 1478.75 | AA33: SEMANA 02 / JAN / 2026 | AB33: 46036 | AC33: 10559.12 | AD33: 7253 | AE33: Entregue / Coletado | AF33: 46036 | AG33: =K33 -> FOB | AH33: EXPRESSO PREDILETO TRANSPORTES, LOGISTIC | AI33: =#REF! -> #REF! | AJ33: 0 | AK33: =AJ33/AC33 -> 0 | AL33: 46036 | AM33: =AF33 -> 46036 | AN33: =AM33-AF33 -> 0 | AO33: SIM | AP33: =I33 -> 46036 | AQ33: =AM33 -> 46036 | AR33: =AP33-H33 -> 9 | AS33: =AM33-H33 -> 9 | AT33: =AR33-AS33 -> 0 | AV33: OK | AW33: =AC33 -> 10559.12 | AX33: =Z33 -> 1478.75 | AZ33: =AJ33 -> 0 | BA33: =AX33+AZ33 -> 1478.75
A34: PERENCO | B34: Elder | C34: Pedido Padrão | D34: - | E34: 123027809 | F34: 4PIPE000183 | G34: 262 | H34: 46027 | I34: 46052 | J34: =I34-H34 -> 25 | K34: FOB | L34: BRASIL | M34: RJ | N34: SÃO JOÃO DA BARRA | O34: OK | P34: 1468.5 | Q34: Alta | R34: =H34 -> 46027 | S34: FINALIZADO | T34: 46045 | U34: 46045 | V34: =I34 -> 46052 | W34: =V34-R34 -> 25 | X34: =U34-R34 -> 18 | Y34: =W34-X34 -> 7 | Z34: 928 | AA34: SEMANA 03 / JAN / 2026 | AB34: 46045 | AC34: 1516.23 | AD34: 7291 | AE34: Entregue / Coletado | AF34: 46045 | AG34: =K34 -> FOB | AH34: EXPRESSO PREDILETO TRANSPORTES, LOGISTIC | AI34: =#REF! -> #REF! | AJ34: 0 | AK34: =AJ34/AC34 -> 0 | AL34: 46045 | AM34: 46045 | AN34: =AM34-AF34 -> 0 | AO34: SIM | AP34: =I34 -> 46052 | AQ34: =AM34 -> 46045 | AR34: =AP34-H34 -> 25 | AS34: =AM34-H34 -> 18 | AT34: =AR34-AS34 -> 7 | AV34: OK | AW34: =AC34 -> 1516.23 | AX34: =Z34 -> 928 | AZ34: =AJ34 -> 0 | BA34: =AX34+AZ34 -> 928
A35: 3R BRAVA BAHIA | B35: Rui | C35: Pedido Padrão | E35: 212242 | F35: 4PIPE000126 | G35: 230 | H35: 46028 | I35: 46065 | J35: =I35-H35 -> 37 | K35: CIF | L35: BRASIL | M35: BA | N35: SÃO FRANCISCO DO CONDE | O35: OK | P35: 2926.8 | Q35: Média | R35: =H35 -> 46028 | S35: FINALIZADO | T35: 46038 | U35: 46038 | V35: =I35 -> 46065 | W35: =V35-R35 -> 37 | X35: =U35-R35 -> 10 | Y35: =W35-X35 -> 27 | Z35: 301.41 | AA35: SEMANA 02 / JAN / 2026 | AB35: 46041 | AC35: 2926.8 | AD35: 7264 | AE35: Entregue / Coletado | AF35: 46044 | AG35: =K35 -> CIF | AH35: MODULAR TRANSPORTES LTDA | AI35: =#REF! -> #REF! | AJ35: 207.66 | AK35: =AJ35/AC35 -> 0.07095121 | AL35: 46065 | AM35: 46050 | AN35: =AM35-AF35 -> 6 | AO35: SIM | AP35: =I35 -> 46065 | AQ35: =AM35 -> 46050 | AR35: =AP35-H35 -> 37 | AS35: =AM35-H35 -> 22 | AT35: =AR35-AS35 -> 15 | AV35: OK | AW35: =AC35 -> 2926.8 | AX35: =Z35 -> 301.41 | AZ35: =AJ35 -> 207.66 | BA35: =AX35+AZ35 -> 509.07
A36: TRANSPETRO CAMAÇARI | B36: Rui | C36: Pedido Padrão | E36: 4501917517 | F36: - | G36: 231 | H36: 46028 | I36: 46087 | J36: =I36-H36 -> 59 | K36: CIF | L36: BRASIL | M36: BA | N36: CAMAÇARI | O36: OK | P36: 1252.41 | Q36: Média | R36: =H36 -> 46028 | S36: FINALIZADO | T36: 46041 | U36: 46043 | V36: =I36 -> 46087 | W36: =V36-R36 -> 59 | X36: =U36-R36 -> 15 | Y36: =W36-X36 -> 44 | Z36: 426.42 | AA36: SEMANA 02 / JAN / 2026 | AB36: 46043 | AC36: 1252.41 | AD36: 7278 | AE36: Entregue / Coletado | AF36: 46044 | AG36: =K36 -> CIF | AH36: MODULAR TRANSPORTES LTDA | AI36: =#REF! -> #REF! | AJ36: 234.75 | AK36: =AJ36/AC36 -> 0.18743862 | AL36: 46065 | AM36: 46050 | AN36: =AM36-AF36 -> 6 | AO36: SIM | AP36: =I36 -> 46087 | AQ36: =AM36 -> 46050 | AR36: =AP36-H36 -> 59 | AS36: =AM36-H36 -> 22 | AT36: =AR36-AS36 -> 37 | AU36: CUSTO BAIXO VENDA | AV36: ATENÇÃO | AW36: =AC36 -> 1252.41 | AX36: =Z36 -> 426.42 | AZ36: =AJ36 -> 234.75 | BA36: =AX36+AZ36 -> 661.17
A37: PETRORECONCAVO | B37: Rui | C37: Pedido Padrão | D37: 4600000028 | E37: 4500063626 | F37: - | G37: 232 | H37: 46029 | I37: 46052 | J37: =I37-H37 -> 23 | K37: FOB | L37: BRASIL | M37: BA | N37: IPOJUCA | O37: OK | P37: 620.29 | Q37: Média | R37: =H37 -> 46029 | S37: FINALIZADO | T37: 46038 | U37: 46038 | V37: =I37 -> 46052 | W37: =V37-R37 -> 23 | X37: =U37-R37 -> 9 | Y37: =W37-X37 -> 14 | Z37: 45.19 | AA37: SEMANA 02 / JAN / 2026 | AB37: 46041 | AC37: 620.29 | AD37: 7263 | AE37: Entregue / Coletado | AF37: 46050 | AG37: =K37 -> FOB | AH37: RAJAN TRANSPORTES COMERCIO E INDUSTRIA | AI37: =#REF! -> #REF! | AJ37: 0 | AK37: =AJ37/AC37 -> 0 | AL37: 46043 | AM37: 46043 | AN37: =AM37-AF37 -> -7 | AO37: SIM | AP37: =I37 -> 46052 | AQ37: =AM37 -> 46043 | AR37: =AP37-H37 -> 23 | AS37: =AM37-H37 -> 14 | AT37: =AR37-AS37 -> 9 | AV37: OK | AW37: =AC37 -> 620.29 | AX37: =Z37 -> 45.19 | AZ37: =AJ37 -> 0 | BA37: =AX37+AZ37 -> 45.19
A38: PETRORECONCAVO | B38: Saulo | C38: Pedido Padrão | D38: 4600000028 | E38: 4500064718 | F38: - | G38: 233 | H38: 46029 | I38: 46057 | J38: =I38-H38 -> 28 | K38: FOB | L38: BRASIL | M38: RN | N38: ROSADO | O38: OK | P38: 19360.52 | Q38: Média | R38: =H38 -> 46029 | S38: FINALIZADO | T38: 46042 | U38: 46043 | V38: =I38 -> 46057 | W38: =V38-R38 -> 28 | X38: =U38-R38 -> 14 | Y38: =W38-X38 -> 14 | Z38: 4110.9 | AA38: SEMANA 02 / JAN / 2026 | AB38: 46043 | AC38: 19360.52 | AD38: 7279 | AE38: Entregue / Coletado | AF38: 46051 | AG38: =K38 -> FOB | AH38: RAJAN TRANSPORTES COMERCIO E INDUSTRIA | AI38: =#REF! -> #REF! | AJ38: 0 | AK38: =AJ38/AC38 -> 0 | AL38: 46043 | AM38: 46043 | AN38: =AM38-AF38 -> -8 | AO38: SIM | AP38: =I38 -> 46057 | AQ38: =AM38 -> 46043 | AR38: =AP38-H38 -> 28 | AS38: =AM38-H38 -> 14 | AT38: =AR38-AS38 -> 14 | AV38: OK | AW38: =AC38 -> 19360.52 | AX38: =Z38 -> 4110.9 | AZ38: =AJ38 -> 0 | BA38: =AX38+AZ38 -> 4110.9
A39: SACOR | B39: Elder | C39: Pedido Padrão | D39: - | E39: 5132 | F39: 4PIPE000199 | G39: 236 | H39: 46030 | I39: 46037 | J39: =I39-H39 -> 7 | K39: FOB | L39: BRASIL | M39: RJ | N39: DUQUE DE CAXIAS | O39: OK | P39: 2554 | Q39: Baixa | R39: =H39 -> 46030 | S39: FINALIZADO | T39: 46035 | U39: 46031 | V39: =I39 -> 46037 | W39: =V39-R39 -> 7 | X39: =U39-R39 -> 1 | Y39: =W39-X39 -> 6 | Z39: 0 | AA39: SEMANA 01 / JAN / 2026 | AB39: 46035 | AC39: 2554 | AD39: 7246 | AE39: Entregue / Coletado | AF39: 46035 | AG39: =K39 -> FOB | AH39: EMPRESA DE TRANSPORTES MARTINS LTDA | AI39: =#REF! -> #REF! | AJ39: 0 | AK39: =AJ39/AC39 -> 0 | AL39: 46034 | AM39: 46034 | AN39: =AM39-AF39 -> -1 | AO39: SIM | AP39: =I39 -> 46037 | AQ39: =AM39 -> 46034 | AR39: =AP39-H39 -> 7 | AS39: =AM39-H39 -> 4 | AT39: =AR39-AS39 -> 3 | AV39: OK | AW39: =AC39 -> 2554 | AX39: =Z39 -> 0 | AZ39: =AJ39 -> 0 | BA39: =AX39+AZ39 -> 0
A40: WHITEFLY TRR | B40: Elder | C40: Pedido Padrão | D40: - | E40: 48 | F40: 4PIPE000207 | G40: 238 | H40: 46030 | I40: 46073 | J40: =I40-H40 -> 43 | K40: FOB | L40: BRASIL | M40: RJ | N40: MACAÉ | O40: OK | P40: 3196.8 | Q40: Média | R40: =H40 -> 46030 | S40: FINALIZADO | T40: 46059 | U40: 46058 | V40: =I40 -> 46073 | W40: =V40-R40 -> 43 | X40: =U40-R40 -> 28 | Y40: =W40-X40 -> 15 | Z40: 139.65 | AA40: SEMANA 01 / FEV / 2026 | AB40: 46064 | AC40: 3196.8 | AD40: 7333 | AE40: Entregue / Coletado | AF40: 46065 | AG40: =K40 -> FOB | AH40: BRASPRESS TRANSPORTES URGENTES LTDA | AI40: =#REF! -> #REF! | AJ40: 0 | AK40: =AJ40/AC40 -> 0 | AL40: 46064 | AM40: 46064 | AN40: =AM40-AF40 -> -1 | AO40: SIM | AP40: =I40 -> 46073 | AQ40: =AM40 -> 46064 | AR40: =AP40-H40 -> 43 | AS40: =AM40-H40 -> 34 | AT40: =AR40-AS40 -> 9 | AV40: OK | AW40: =AC40 -> 3196.8 | AX40: =Z40 -> 139.65 | AZ40: =AJ40 -> 0 | BA40: =AX40+AZ40 -> 139.65
...

Sheet DASHBOARD COMERCIAL
B2: DASHBOARD COMERCIAL
B4: Ano de Análise: | C4: 2026 | D4: Mês de Análise: | E4: Todos
B6: INDICADORES GERAIS
B7: Total de Pedidos | C7: {=SUMPRODUCT((($C$4="Todos")+(YEAR('GESTAO OPERACAO'!$H$2:$H$632)=$C$4)>0)*(($E$4="Todos")+(MONTH('GESTAO OPERACAO'!$H$2:$H$632)=IFERROR(MATCH($E$4,{"Janeiro";"Fevereiro";"Março";"Abril";"Maio";"Junho";"Julho";"Agosto";"Setembro";"Outubro";"Novembro";"Dezembro"},0),0))>0)*('GESTAO OPERACAO'!$H$2:$H$632>0))} -> 426 | D7: Valor Total (R$) | E7: {=SUMPRODUCT((($C$4="Todos")+(YEAR('GESTAO OPERACAO'!$H$2:$H$632)=$C$4)>0)*(($E$4="Todos")+(MONTH('GESTAO OPERACAO'!$H$2:$H$632)=IFERROR(MATCH($E$4,{"Janeiro";"Fevereiro";"Março";"Abril";"Maio";"Junho";"Julho";"Agosto";"Setembro";"Outubro";"Novembro";"Dezembro"},0),0))>0)*('GESTAO OPERACAO'!$H$2:$H$632>0)*IFERROR('GESTAO OPERACAO'!$P$2:$P$632*1,0))} -> 15225527 | F7: Ticket Médio (R$) | G7: =IFERROR(E7/C7,0) -> 35740.673
B9: RESUMO MENSAL - PEDIDOS INCLUÍDOS
B10: Mês | C10: Qtd Pedidos | D10: Valor Total | E10: Ticket Médio
B11: Janeiro | C11: {=(($E$4="Todos")+($E$4="Janeiro")>0)*SUMPRODUCT((($C$4="Todos")+(YEAR('GESTAO OPERACAO'!$H$2:$H$632)=$C$4)>0)*(MONTH('GESTAO OPERACAO'!$H$2:$H$632)=1)*('GESTAO OPERACAO'!$H$2:$H$632>0))} -> 47 | D11: {=(($E$4="Todos")+($E$4="Janeiro")>0)*SUMPRODUCT((($C$4="Todos")+(YEAR('GESTAO OPERACAO'!$H$2:$H$632)=$C$4)>0)*(MONTH('GESTAO OPERACAO'!$H$2:$H$632)=1)*('GESTAO OPERACAO'!$H$2:$H$632>0)*IFERROR('GESTAO OPERACAO'!$P$2:$P$632*1,0))} -> 672366.08 | E11: =IFERROR(D11/C11,0) -> 14305.661
B12: Fevereiro | C12: {=(($E$4="Todos")+($E$4="Fevereiro")>0)*SUMPRODUCT((($C$4="Todos")+(YEAR('GESTAO OPERACAO'!$H$2:$H$632)=$C$4)>0)*(MONTH('GESTAO OPERACAO'!$H$2:$H$632)=2)*('GESTAO OPERACAO'!$H$2:$H$632>0))} -> 45 | D12: {=(($E$4="Todos")+($E$4="Fevereiro")>0)*SUMPRODUCT((($C$4="Todos")+(YEAR('GESTAO OPERACAO'!$H$2:$H$632)=$C$4)>0)*(MONTH('GESTAO OPERACAO'!$H$2:$H$632)=2)*('GESTAO OPERACAO'!$H$2:$H$632>0)*IFERROR('GESTAO OPERACAO'!$P$2:$P$632*1,0))} -> 555067.83 | E12: =IFERROR(D12/C12,0) -> 12334.841
B13: Março | C13: {=(($E$4="Todos")+($E$4="Março")>0)*SUMPRODUCT((($C$4="Todos")+(YEAR('GESTAO OPERACAO'!$H$2:$H$632)=$C$4)>0)*(MONTH('GESTAO OPERACAO'!$H$2:$H$632)=3)*('GESTAO OPERACAO'!$H$2:$H$632>0))} -> 61 | D13: {=(($E$4="Todos")+($E$4="Março")>0)*SUMPRODUCT((($C$4="Todos")+(YEAR('GESTAO OPERACAO'!$H$2:$H$632)=$C$4)>0)*(MONTH('GESTAO OPERACAO'!$H$2:$H$632)=3)*('GESTAO OPERACAO'!$H$2:$H$632>0)*IFERROR('GESTAO OPERACAO'!$P$2:$P$632*1,0))} -> 2824354.8 | E13: =IFERROR(D13/C13,0) -> 46300.898
B14: Abril | C14: {=(($E$4="Todos")+($E$4="Abril")>0)*SUMPRODUCT((($C$4="Todos")+(YEAR('GESTAO OPERACAO'!$H$2:$H$632)=$C$4)>0)*(MONTH('GESTAO OPERACAO'!$H$2:$H$632)=4)*('GESTAO OPERACAO'!$H$2:$H$632>0))} -> 56 | D14: {=(($E$4="Todos")+($E$4="Abril")>0)*SUMPRODUCT((($C$4="Todos")+(YEAR('GESTAO OPERACAO'!$H$2:$H$632)=$C$4)>0)*(MONTH('GESTAO OPERACAO'!$H$2:$H$632)=4)*('GESTAO OPERACAO'!$H$2:$H$632>0)*IFERROR('GESTAO OPERACAO'!$P$2:$P$632*1,0))} -> 1595738.1 | E14: =IFERROR(D14/C14,0) -> 28495.324
B15: Maio | C15: {=(($E$4="Todos")+($E$4="Maio")>0)*SUMPRODUCT((($C$4="Todos")+(YEAR('GESTAO OPERACAO'!$H$2:$H$632)=$C$4)>0)*(MONTH('GESTAO OPERACAO'!$H$2:$H$632)=5)*('GESTAO OPERACAO'!$H$2:$H$632>0))} -> 59 | D15: {=(($E$4="Todos")+($E$4="Maio")>0)*SUMPRODUCT((($C$4="Todos")+(YEAR('GESTAO OPERACAO'!$H$2:$H$632)=$C$4)>0)*(MONTH('GESTAO OPERACAO'!$H$2:$H$632)=5)*('GESTAO OPERACAO'!$H$2:$H$632>0)*IFERROR('GESTAO OPERACAO'!$P$2:$P$632*1,0))} -> 2521919.9 | E15: =IFERROR(D15/C15,0) -> 42744.404
B16: Junho | C16: {=(($E$4="Todos")+($E$4="Junho")>0)*SUMPRODUCT((($C$4="Todos")+(YEAR('GESTAO OPERACAO'!$H$2:$H$632)=$C$4)>0)*(MONTH('GESTAO OPERACAO'!$H$2:$H$632)=6)*('GESTAO OPERACAO'!$H$2:$H$632>0))} -> 54 | D16: {=(($E$4="Todos")+($E$4="Junho")>0)*SUMPRODUCT((($C$4="Todos")+(YEAR('GESTAO OPERACAO'!$H$2:$H$632)=$C$4)>0)*(MONTH('GESTAO OPERACAO'!$H$2:$H$632)=6)*('GESTAO OPERACAO'!$H$2:$H$632>0)*IFERROR('GESTAO OPERACAO'!$P$2:$P$632*1,0))} -> 919297.98 | E16: =IFERROR(D16/C16,0) -> 17024.037
B17: Julho | C17: {=(($E$4="Todos")+($E$4="Julho")>0)*SUMPRODUCT((($C$4="Todos")+(YEAR('GESTAO OPERACAO'!$H$2:$H$632)=$C$4)>0)*(MONTH('GESTAO OPERACAO'!$H$2:$H$632)=7)*('GESTAO OPERACAO'!$H$2:$H$632>0))} -> 46 | D17: {=(($E$4="Todos")+($E$4="Julho")>0)*SUMPRODUCT((($C$4="Todos")+(YEAR('GESTAO OPERACAO'!$H$2:$H$632)=$C$4)>0)*(MONTH('GESTAO OPERACAO'!$H$2:$H$632)=7)*('GESTAO OPERACAO'!$H$2:$H$632>0)*IFERROR('GESTAO OPERACAO'!$P$2:$P$632*1,0))} -> 540937.7 | E17: =IFERROR(D17/C17,0) -> 11759.515
B18: Agosto | C18: {=(($E$4="Todos")+($E$4="Agosto")>0)*SUMPRODUCT((($C$4="Todos")+(YEAR('GESTAO OPERACAO'!$H$2:$H$632)=$C$4)>0)*(MONTH('GESTAO OPERACAO'!$H$2:$H$632)=8)*('GESTAO OPERACAO'!$H$2:$H$632>0))} -> 50 | D18: {=(($E$4="Todos")+($E$4="Agosto")>0)*SUMPRODUCT((($C$4="Todos")+(YEAR('GESTAO OPERACAO'!$H$2:$H$632)=$C$4)>0)*(MONTH('GESTAO OPERACAO'!$H$2:$H$632)=8)*('GESTAO OPERACAO'!$H$2:$H$632>0)*IFERROR('GESTAO OPERACAO'!$P$2:$P$632*1,0))} -> 5498383.4 | E18: =IFERROR(D18/C18,0) -> 109967.67
B19: Setembro | C19: {=(($E$4="Todos")+($E$4="Setembro")>0)*SUMPRODUCT((($C$4="Todos")+(YEAR('GESTAO OPERACAO'!$H$2:$H$632)=$C$4)>0)*(MONTH('GESTAO OPERACAO'!$H$2:$H$632)=9)*('GESTAO OPERACAO'!$H$2:$H$632>0))} -> 8 | D19: {=(($E$4="Todos")+($E$4="Setembro")>0)*SUMPRODUCT((($C$4="Todos")+(YEAR('GESTAO OPERACAO'!$H$2:$H$632)=$C$4)>0)*(MONTH('GESTAO OPERACAO'!$H$2:$H$632)=9)*('GESTAO OPERACAO'!$H$2:$H$632>0)*IFERROR('GESTAO OPERACAO'!$P$2:$P$632*1,0))} -> 97461.04 | E19: =IFERROR(D19/C19,0) -> 12182.63
B20: Outubro | C20: {=(($E$4="Todos")+($E$4="Outubro")>0)*SUMPRODUCT((($C$4="Todos")+(YEAR('GESTAO OPERACAO'!$H$2:$H$632)=$C$4)>0)*(MONTH('GESTAO OPERACAO'!$H$2:$H$632)=10)*('GESTAO OPERACAO'!$H$2:$H$632>0))} -> 0 | D20: {=(($E$4="Todos")+($E$4="Outubro")>0)*SUMPRODUCT((($C$4="Todos")+(YEAR('GESTAO OPERACAO'!$H$2:$H$632)=$C$4)>0)*(MONTH('GESTAO OPERACAO'!$H$2:$H$632)=10)*('GESTAO OPERACAO'!$H$2:$H$632>0)*IFERROR('GESTAO OPERACAO'!$P$2:$P$632*1,0))} -> 0 | E20: =IFERROR(D20/C20,0) -> 0
B21: Novembro | C21: {=(($E$4="Todos")+($E$4="Novembro")>0)*SUMPRODUCT((($C$4="Todos")+(YEAR('GESTAO OPERACAO'!$H$2:$H$632)=$C$4)>0)*(MONTH('GESTAO OPERACAO'!$H$2:$H$632)=11)*('GESTAO OPERACAO'!$H$2:$H$632>0))} -> 0 | D21: {=(($E$4="Todos")+($E$4="Novembro")>0)*SUMPRODUCT((($C$4="Todos")+(YEAR('GESTAO OPERACAO'!$H$2:$H$632)=$C$4)>0)*(MONTH('GESTAO OPERACAO'!$H$2:$H$632)=11)*('GESTAO OPERACAO'!$H$2:$H$632>0)*IFERROR('GESTAO OPERACAO'!$P$2:$P$632*1,0))} -> 0 | E21: =IFERROR(D21/C21,0) -> 0
B22: Dezembro | C22: {=(($E$4="Todos")+($E$4="Dezembro")>0)*SUMPRODUCT((($C$4="Todos")+(YEAR('GESTAO OPERACAO'!$H$2:$H$632)=$C$4)>0)*(MONTH('GESTAO OPERACAO'!$H$2:$H$632)=12)*('GESTAO OPERACAO'!$H$2:$H$632>0))} -> 0 | D22: {=(($E$4="Todos")+($E$4="Dezembro")>0)*SUMPRODUCT((($C$4="Todos")+(YEAR('GESTAO OPERACAO'!$H$2:$H$632)=$C$4)>0)*(MONTH('GESTAO OPERACAO'!$H$2:$H$632)=12)*('GESTAO OPERACAO'!$H$2:$H$632>0)*IFERROR('GESTAO OPERACAO'!$P$2:$P$632*1,0))} -> 0 | E22: =IFERROR(D22/C22,0) -> 0
B23: TOTAL GERAL | C23: =SUM(C11:C22) -> 426 | D23: =SUM(D11:D22) -> 15225527 | E23: =IFERROR(D23/C23,0) -> 35740.673
B25: PEDIDOS INCLUÍDOS POR MÊS E SEMANA
B26: Mês | C26: Semana | D26: Período | E26: Qtd Pedidos | F26: Valor Total
B27: Janeiro | C27: Semana 1 | D27: =IF($C$4="Todos","Semana 1",TEXT(DATE($C$4,1,1),"dd/mm")&" - "&TEXT((DATE($C$4,1,1)+MOD(7-WEEKDAY(DATE($C$4,1,1),2),7)),"dd/mm")) -> 01/01 - 04/01 | E27: {=(($E$4="Todos")+($E$4="Janeiro")>0)*SUMPRODUCT(IFERROR((($C$4="Todos")+(YEAR('GESTAO OPERACAO'!$H$2:$H$632)=$C$4)>0)*('GESTAO OPERACAO'!$H$2:$H$632>0)*(MONTH('GESTAO OPERACAO'!$H$2:$H$632)=1)*((INT((DAY('GESTAO OPERACAO'!$H$2:$H$632)+WEEKDAY(DATE(YEAR('GESTAO OPERACAO'!$H$2:$H$632),1,1),2)-2)/7)+1)=1),0))} -> 0 | F27: {=(($E$4="Todos")+($E$4="Janeiro")>0)*SUMPRODUCT(IFERROR((($C$4="Todos")+(YEAR('GESTAO OPERACAO'!$H$2:$H$632)=$C$4)>0)*('GESTAO OPERACAO'!$H$2:$H$632>0)*(MONTH('GESTAO OPERACAO'!$H$2:$H$632)=1)*((INT((DAY('GESTAO OPERACAO'!$H$2:$H$632)+WEEKDAY(DATE(YEAR('GESTAO OPERACAO'!$H$2:$H$632),1,1),2)-2)/7)+1)=1)*('GESTAO OPERACAO'!$P$2:$P$632*1),0))} -> 0
B28: Janeiro | C28: Semana 2 | D28: =IF($C$4="Todos","Semana 2",IF(((DATE($C$4,1,1)+MOD(7-WEEKDAY(DATE($C$4,1,1),2),7)+1)+0)>EOMONTH(DATE($C$4,1,1),0),"-",TEXT(((DATE($C$4,1,1)+MOD(7-WEEKDAY(DATE($C$4,1,1),2),7)+1)+0),"dd/mm")&" - "&TEXT(MIN(((DATE($C$4,1,1)+MOD(7-WEEKDAY(DATE($C$4,1,1),2),7)+1)+0)+6,EOMONTH(DATE($C$4,1,1),0)),"dd/mm"))) -> 05/01 - 11/01 | E28: {=(($E$4="Todos")+($E$4="Janeiro")>0)*SUMPRODUCT(IFERROR((($C$4="Todos")+(YEAR('GESTAO OPERACAO'!$H$2:$H$632)=$C$4)>0)*('GESTAO OPERACAO'!$H$2:$H$632>0)*(MONTH('GESTAO OPERACAO'!$H$2:$H$632)=1)*((INT((DAY('GESTAO OPERACAO'!$H$2:$H$632)+WEEKDAY(DATE(YEAR('GESTAO OPERACAO'!$H$2:$H$632),1,1),2)-2)/7)+1)=2),0))} -> 18 | F28: {=(($E$4="Todos")+($E$4="Janeiro")>0)*SUMPRODUCT(IFERROR((($C$4="Todos")+(YEAR('GESTAO OPERACAO'!$H$2:$H$632)=$C$4)>0)*('GESTAO OPERACAO'!$H$2:$H$632>0)*(MONTH('GESTAO OPERACAO'!$H$2:$H$632)=1)*((INT((DAY('GESTAO OPERACAO'!$H$2:$H$632)+WEEKDAY(DATE(YEAR('GESTAO OPERACAO'!$H$2:$H$632),1,1),2)-2)/7)+1)=2)*('GESTAO OPERACAO'!$P$2:$P$632*1),0))} -> 152296.17
B29: Janeiro | C29: Semana 3 | D29: =IF($C$4="Todos","Semana 3",IF(((DATE($C$4,1,1)+MOD(7-WEEKDAY(DATE($C$4,1,1),2),7)+1)+7)>EOMONTH(DATE($C$4,1,1),0),"-",TEXT(((DATE($C$4,1,1)+MOD(7-WEEKDAY(DATE($C$4,1,1),2),7)+1)+7),"dd/mm")&" - "&TEXT(MIN(((DATE($C$4,1,1)+MOD(7-WEEKDAY(DATE($C$4,1,1),2),7)+1)+7)+6,EOMONTH(DATE($C$4,1,1),0)),"dd/mm"))) -> 12/01 - 18/01 | E29: {=(($E$4="Todos")+($E$4="Janeiro")>0)*SUMPRODUCT(IFERROR((($C$4="Todos")+(YEAR('GESTAO OPERACAO'!$H$2:$H$632)=$C$4)>0)*('GESTAO OPERACAO'!$H$2:$H$632>0)*(MONTH('GESTAO OPERACAO'!$H$2:$H$632)=1)*((INT((DAY('GESTAO OPERACAO'!$H$2:$H$632)+WEEKDAY(DATE(YEAR('GESTAO OPERACAO'!$H$2:$H$632),1,1),2)-2)/7)+1)=3),0))} -> 8 | F29: {=(($E$4="Todos")+($E$4="Janeiro")>0)*SUMPRODUCT(IFERROR((($C$4="Todos")+(YEAR('GESTAO OPERACAO'!$H$2:$H$632)=$C$4)>0)*('GESTAO OPERACAO'!$H$2:$H$632>0)*(MONTH('GESTAO OPERACAO'!$H$2:$H$632)=1)*((INT((DAY('GESTAO OPERACAO'!$H$2:$H$632)+WEEKDAY(DATE(YEAR('GESTAO OPERACAO'!$H$2:$H$632),1,1),2)-2)/7)+1)=3)*('GESTAO OPERACAO'!$P$2:$P$632*1),0))} -> 221233.03
B30: Janeiro | C30: Semana 4 | D30: =IF($C$4="Todos","Semana 4",IF(((DATE($C$4,1,1)+MOD(7-WEEKDAY(DATE($C$4,1,1),2),7)+1)+14)>EOMONTH(DATE($C$4,1,1),0),"-",TEXT(((DATE($C$4,1,1)+MOD(7-WEEKDAY(DATE($C$4,1,1),2),7)+1)+14),"dd/mm")&" - "&TEXT(MIN(((DATE($C$4,1,1)+MOD(7-WEEKDAY(DATE($C$4,1,1),2),7)+1)+14)+6,EOMONTH(DATE($C$4,1,1),0)),"dd/mm"))) -> 19/01 - 25/01 | E30: {=(($E$4="Todos")+($E$4="Janeiro")>0)*SUMPRODUCT(IFERROR((($C$4="Todos")+(YEAR('GESTAO OPERACAO'!$H$2:$H$632)=$C$4)>0)*('GESTAO OPERACAO'!$H$2:$H$632>0)*(MONTH('GESTAO OPERACAO'!$H$2:$H$632)=1)*((INT((DAY('GESTAO OPERACAO'!$H$2:$H$632)+WEEKDAY(DATE(YEAR('GESTAO OPERACAO'!$H$2:$H$632),1,1),2)-2)/7)+1)=4),0))} -> 10 | F30: {=(($E$4="Todos")+($E$4="Janeiro")>0)*SUMPRODUCT(IFERROR((($C$4="Todos")+(YEAR('GESTAO OPERACAO'!$H$2:$H$632)=$C$4)>0)*('GESTAO OPERACAO'!$H$2:$H$632>0)*(MONTH('GESTAO OPERACAO'!$H$2:$H$632)=1)*((INT((DAY('GESTAO OPERACAO'!$H$2:$H$632)+WEEKDAY(DATE(YEAR('GESTAO OPERACAO'!$H$2:$H$632),1,1),2)-2)/7)+1)=4)*('GESTAO OPERACAO'!$P$2:$P$632*1),0))} -> 100567.6
B31: Janeiro | C31: Semana 5 | D31: =IF($C$4="Todos","Semana 5+",IF(((DATE($C$4,1,1)+MOD(7-WEEKDAY(DATE($C$4,1,1),2),7)+1)+21)>EOMONTH(DATE($C$4,1,1),0),"-",TEXT(((DATE($C$4,1,1)+MOD(7-WEEKDAY(DATE($C$4,1,1),2),7)+1)+21),"dd/mm")&" - "&TEXT(EOMONTH(DATE($C$4,1,1),0),"dd/mm"))) -> 26/01 - 31/01 | E31: {=(($E$4="Todos")+($E$4="Janeiro")>0)*SUMPRODUCT(IFERROR((($C$4="Todos")+(YEAR('GESTAO OPERACAO'!$H$2:$H$632)=$C$4)>0)*('GESTAO OPERACAO'!$H$2:$H$632>0)*(MONTH('GESTAO OPERACAO'!$H$2:$H$632)=1)*((INT((DAY('GESTAO OPERACAO'!$H$2:$H$632)+WEEKDAY(DATE(YEAR('GESTAO OPERACAO'!$H$2:$H$632),1,1),2)-2)/7)+1)>=5),0))} -> 11 | F31: {=(($E$4="Todos")+($E$4="Janeiro")>0)*SUMPRODUCT(IFERROR((($C$4="Todos")+(YEAR('GESTAO OPERACAO'!$H$2:$H$632)=$C$4)>0)*('GESTAO OPERACAO'!$H$2:$H$632>0)*(MONTH('GESTAO OPERACAO'!$H$2:$H$632)=1)*((INT((DAY('GESTAO OPERACAO'!$H$2:$H$632)+WEEKDAY(DATE(YEAR('GESTAO OPERACAO'!$H$2:$H$632),1,1),2)-2)/7)+1)>=5)*('GESTAO OPERACAO'!$P$2:$P$632*1),0))} -> 198269.28
B32: Total Janeiro | E32: =SUM(E27:E31) -> 47 | F32: =SUM(F27:F31) -> 672366.08
B33: Fevereiro | C33: Semana 1 | D33: =IF($C$4="Todos","Semana 1",TEXT(DATE($C$4,2,1),"dd/mm")&" - "&TEXT((DATE($C$4,2,1)+MOD(7-WEEKDAY(DATE($C$4,2,1),2),7)),"dd/mm")) -> 01/02 - 01/02 | E33: {=(($E$4="Todos")+($E$4="Fevereiro")>0)*SUMPRODUCT(IFERROR((($C$4="Todos")+(YEAR('GESTAO OPERACAO'!$H$2:$H$632)=$C$4)>0)*('GESTAO OPERACAO'!$H$2:$H$632>0)*(MONTH('GESTAO OPERACAO'!$H$2:$H$632)=2)*((INT((DAY('GESTAO OPERACAO'!$H$2:$H$632)+WEEKDAY(DATE(YEAR('GESTAO OPERACAO'!$H$2:$H$632),2,1),2)-2)/7)+1)=1),0))} -> 0 | F33: {=(($E$4="Todos")+($E$4="Fevereiro")>0)*SUMPRODUCT(IFERROR((($C$4="Todos")+(YEAR('GESTAO OPERACAO'!$H$2:$H$632)=$C$4)>0)*('GESTAO OPERACAO'!$H$2:$H$632>0)*(MONTH('GESTAO OPERACAO'!$H$2:$H$632)=2)*((INT((DAY('GESTAO OPERACAO'!$H$2:$H$632)+WEEKDAY(DATE(YEAR('GESTAO OPERACAO'!$H$2:$H$632),2,1),2)-2)/7)+1)=1)*('GESTAO OPERACAO'!$P$2:$P$632*1),0))} -> 0
B34: Fevereiro | C34: Semana 2 | D34: =IF($C$4="Todos","Semana 2",IF(((DATE($C$4,2,1)+MOD(7-WEEKDAY(DATE($C$4,2,1),2),7)+1)+0)>EOMONTH(DATE($C$4,2,1),0),"-",TEXT(((DATE($C$4,2,1)+MOD(7-WEEKDAY(DATE($C$4,2,1),2),7)+1)+0),"dd/mm")&" - "&TEXT(MIN(((DATE($C$4,2,1)+MOD(7-WEEKDAY(DATE($C$4,2,1),2),7)+1)+0)+6,EOMONTH(DATE($C$4,2,1),0)),"dd/mm"))) -> 02/02 - 08/02 | E34: {=(($E$4="Todos")+($E$4="Fevereiro")>0)*SUMPRODUCT(IFERROR((($C$4="Todos")+(YEAR('GESTAO OPERACAO'!$H$2:$H$632)=$C$4)>0)*('GESTAO OPERACAO'!$H$2:$H$632>0)*(MONTH('GESTAO OPERACAO'!$H$2:$H$632)=2)*((INT((DAY('GESTAO OPERACAO'!$H$2:$H$632)+WEEKDAY(DATE(YEAR('GESTAO OPERACAO'!$H$2:$H$632),2,1),2)-2)/7)+1)=2),0))} -> 17 | F34: {=(($E$4="Todos")+($E$4="Fevereiro")>0)*SUMPRODUCT(IFERROR((($C$4="Todos")+(YEAR('GESTAO OPERACAO'!$H$2:$H$632)=$C$4)>0)*('GESTAO OPERACAO'!$H$2:$H$632>0)*(MONTH('GESTAO OPERACAO'!$H$2:$H$632)=2)*((INT((DAY('GESTAO OPERACAO'!$H$2:$H$632)+WEEKDAY(DATE(YEAR('GESTAO OPERACAO'!$H$2:$H$632),2,1),2)-2)/7)+1)=2)*('GESTAO OPERACAO'!$P$2:$P$632*1),0))} -> 125361.71
B35: Fevereiro | C35: Semana 3 | D35: =IF($C$4="Todos","Semana 3",IF(((DATE($C$4,2,1)+MOD(7-WEEKDAY(DATE($C$4,2,1),2),7)+1)+7)>EOMONTH(DATE($C$4,2,1),0),"-",TEXT(((DATE($C$4,2,1)+MOD(7-WEEKDAY(DATE($C$4,2,1),2),7)+1)+7),"dd/mm")&" - "&TEXT(MIN(((DATE($C$4,2,1)+MOD(7-WEEKDAY(DATE($C$4,2,1),2),7)+1)+7)+6,EOMONTH(DATE($C$4,2,1),0)),"dd/mm"))) -> 09/02 - 15/02 | E35: {=(($E$4="Todos")+($E$4="Fevereiro")>0)*SUMPRODUCT(IFERROR((($C$4="Todos")+(YEAR('GESTAO OPERACAO'!$H$2:$H$632)=$C$4)>0)*('GESTAO OPERACAO'!$H$2:$H$632>0)*(MONTH('GESTAO OPERACAO'!$H$2:$H$632)=2)*((INT((DAY('GESTAO OPERACAO'!$H$2:$H$632)+WEEKDAY(DATE(YEAR('GESTAO OPERACAO'!$H$2:$H$632),2,1),2)-2)/7)+1)=3),0))} -> 12 | F35: {=(($E$4="Todos")+($E$4="Fevereiro")>0)*SUMPRODUCT(IFERROR((($C$4="Todos")+(YEAR('GESTAO OPERACAO'!$H$2:$H$632)=$C$4)>0)*('GESTAO OPERACAO'!$H$2:$H$632>0)*(MONTH('GESTAO OPERACAO'!$H$2:$H$632)=2)*((INT((DAY('GESTAO OPERACAO'!$H$2:$H$632)+WEEKDAY(DATE(YEAR('GESTAO OPERACAO'!$H$2:$H$632),2,1),2)-2)/7)+1)=3)*('GESTAO OPERACAO'!$P$2:$P$632*1),0))} -> 235703.97
B36: Fevereiro | C36: Semana 4 | D36: =IF($C$4="Todos","Semana 4",IF(((DATE($C$4,2,1)+MOD(7-WEEKDAY(DATE($C$4,2,1),2),7)+1)+14)>EOMONTH(DATE($C$4,2,1),0),"-",TEXT(((DATE($C$4,2,1)+MOD(7-WEEKDAY(DATE($C$4,2,1),2),7)+1)+14),"dd/mm")&" - "&TEXT(MIN(((DATE($C$4,2,1)+MOD(7-WEEKDAY(DATE($C$4,2,1),2),7)+1)+14)+6,EOMONTH(DATE($C$4,2,1),0)),"dd/mm"))) -> 16/02 - 22/02 | E36: {=(($E$4="Todos")+($E$4="Fevereiro")>0)*SUMPRODUCT(IFERROR((($C$4="Todos")+(YEAR('GESTAO OPERACAO'!$H$2:$H$632)=$C$4)>0)*('GESTAO OPERACAO'!$H$2:$H$632>0)*(MONTH('GESTAO OPERACAO'!$H$2:$H$632)=2)*((INT((DAY('GESTAO OPERACAO'!$H$2:$H$632)+WEEKDAY(DATE(YEAR('GESTAO OPERACAO'!$H$2:$H$632),2,1),2)-2)/7)+1)=4),0))} -> 5 | F36: {=(($E$4="Todos")+($E$4="Fevereiro")>0)*SUMPRODUCT(IFERROR((($C$4="Todos")+(YEAR('GESTAO OPERACAO'!$H$2:$H$632)=$C$4)>0)*('GESTAO OPERACAO'!$H$2:$H$632>0)*(MONTH('GESTAO OPERACAO'!$H$2:$H$632)=2)*((INT((DAY('GESTAO OPERACAO'!$H$2:$H$632)+WEEKDAY(DATE(YEAR('GESTAO OPERACAO'!$H$2:$H$632),2,1),2)-2)/7)+1)=4)*('GESTAO OPERACAO'!$P$2:$P$632*1),0))} -> 24041.36
B37: Fevereiro | C37: Semana 5 | D37: =IF($C$4="Todos","Semana 5+",IF(((DATE($C$4,2,1)+MOD(7-WEEKDAY(DATE($C$4,2,1),2),7)+1)+21)>EOMONTH(DATE($C$4,2,1),0),"-",TEXT(((DATE($C$4,2,1)+MOD(7-WEEKDAY(DATE($C$4,2,1),2),7)+1)+21),"dd/mm")&" - "&TEXT(EOMONTH(DATE($C$4,2,1),0),"dd/mm"))) -> 23/02 - 28/02 | E37: {=(($E$4="Todos")+($E$4="Fevereiro")>0)*SUMPRODUCT(IFERROR((($C$4="Todos")+(YEAR('GESTAO OPERACAO'!$H$2:$H$632)=$C$4)>0)*('GESTAO OPERACAO'!$H$2:$H$632>0)*(MONTH('GESTAO OPERACAO'!$H$2:$H$632)=2)*((INT((DAY('GESTAO OPERACAO'!$H$2:$H$632)+WEEKDAY(DATE(YEAR('GESTAO OPERACAO'!$H$2:$H$632),2,1),2)-2)/7)+1)>=5),0))} -> 11 | F37: {=(($E$4="Todos")+($E$4="Fevereiro")>0)*SUMPRODUCT(IFERROR((($C$4="Todos")+(YEAR('GESTAO OPERACAO'!$H$2:$H$632)=$C$4)>0)*('GESTAO OPERACAO'!$H$2:$H$632>0)*(MONTH('GESTAO OPERACAO'!$H$2:$H$632)=2)*((INT((DAY('GESTAO OPERACAO'!$H$2:$H$632)+WEEKDAY(DATE(YEAR('GESTAO OPERACAO'!$H$2:$H$632),2,1),2)-2)/7)+1)>=5)*('GESTAO OPERACAO'!$P$2:$P$632*1),0))} -> 169960.79
B38: Total Fevereiro | E38: =SUM(E33:E37) -> 45 | F38: =SUM(F33:F37) -> 555067.83
B39: Março | C39: Semana 1 | D39: =IF($C$4="Todos","Semana 1",TEXT(DATE($C$4,3,1),"dd/mm")&" - "&TEXT((DATE($C$4,3,1)+MOD(7-WEEKDAY(DATE($C$4,3,1),2),7)),"dd/mm")) -> 01/03 - 01/03 | E39: {=(($E$4="Todos")+($E$4="Março")>0)*SUMPRODUCT(IFERROR((($C$4="Todos")+(YEAR('GESTAO OPERACAO'!$H$2:$H$632)=$C$4)>0)*('GESTAO OPERACAO'!$H$2:$H$632>0)*(MONTH('GESTAO OPERACAO'!$H$2:$H$632)=3)*((INT((DAY('GESTAO OPERACAO'!$H$2:$H$632)+WEEKDAY(DATE(YEAR('GESTAO OPERACAO'!$H$2:$H$632),3,1),2)-2)/7)+1)=1),0))} -> 0 | F39: {=(($E$4="Todos")+($E$4="Março")>0)*SUMPRODUCT(IFERROR((($C$4="Todos")+(YEAR('GESTAO OPERACAO'!$H$2:$H$632)=$C$4)>0)*('GESTAO OPERACAO'!$H$2:$H$632>0)*(MONTH('GESTAO OPERACAO'!$H$2:$H$632)=3)*((INT((DAY('GESTAO OPERACAO'!$H$2:$H$632)+WEEKDAY(DATE(YEAR('GESTAO OPERACAO'!$H$2:$H$632),3,1),2)-2)/7)+1)=1)*('GESTAO OPERACAO'!$P$2:$P$632*1),0))} -> 0
B40: Março | C40: Semana 2 | D40: =IF($C$4="Todos","Semana 2",IF(((DATE($C$4,3,1)+MOD(7-WEEKDAY(DATE($C$4,3,1),2),7)+1)+0)>EOMONTH(DATE($C$4,3,1),0),"-",TEXT(((DATE($C$4,3,1)+MOD(7-WEEKDAY(DATE($C$4,3,1),2),7)+1)+0),"dd/mm")&" - "&TEXT(MIN(((DATE($C$4,3,1)+MOD(7-WEEKDAY(DATE($C$4,3,1),2),7)+1)+0)+6,EOMONTH(DATE($C$4,3,1),0)),"dd/mm"))) -> 02/03 - 08/03 | E40: {=(($E$4="Todos")+($E$4="Março")>0)*SUMPRODUCT(IFERROR((($C$4="Todos")+(YEAR('GESTAO OPERACAO'!$H$2:$H$632)=$C$4)>0)*('GESTAO OPERACAO'!$H$2:$H$632>0)*(MONTH('GESTAO OPERACAO'!$H$2:$H$632)=3)*((INT((DAY('GESTAO OPERACAO'!$H$2:$H$632)+WEEKDAY(DATE(YEAR('GESTAO OPERACAO'!$H$2:$H$632),3,1),2)-2)/7)+1)=2),0))} -> 11 | F40: {=(($E$4="Todos")+($E$4="Março")>0)*SUMPRODUCT(IFERROR((($C$4="Todos")+(YEAR('GESTAO OPERACAO'!$H$2:$H$632)=$C$4)>0)*('GESTAO OPERACAO'!$H$2:$H$632>0)*(MONTH('GESTAO OPERACAO'!$H$2:$H$632)=3)*((INT((DAY('GESTAO OPERACAO'!$H$2:$H$632)+WEEKDAY(DATE(YEAR('GESTAO OPERACAO'!$H$2:$H$632),3,1),2)-2)/7)+1)=2)*('GESTAO OPERACAO'!$P$2:$P$632*1),0))} -> 644929.92
B41: Março | C41: Semana 3 | D41: =IF($C$4="Todos","Semana 3",IF(((DATE($C$4,3,1)+MOD(7-WEEKDAY(DATE($C$4,3,1),2),7)+1)+7)>EOMONTH(DATE($C$4,3,1),0),"-",TEXT(((DATE($C$4,3,1)+MOD(7-WEEKDAY(DATE($C$4,3,1),2),7)+1)+7),"dd/mm")&" - "&TEXT(MIN(((DATE($C$4,3,1)+MOD(7-WEEKDAY(DATE($C$4,3,1),2),7)+1)+7)+6,EOMONTH(DATE($C$4,3,1),0)),"dd/mm"))) -> 09/03 - 15/03 | E41: {=(($E$4="Todos")+($E$4="Março")>0)*SUMPRODUCT(IFERROR((($C$4="Todos")+(YEAR('GESTAO OPERACAO'!$H$2:$H$632)=$C$4)>0)*('GESTAO OPERACAO'!$H$2:$H$632>0)*(MONTH('GESTAO OPERACAO'!$H$2:$H$632)=3)*((INT((DAY('GESTAO OPERACAO'!$H$2:$H$632)+WEEKDAY(DATE(YEAR('GESTAO OPERACAO'!$H$2:$H$632),3,1),2)-2)/7)+1)=3),0))} -> 18 | F41: {=(($E$4="Todos")+($E$4="Março")>0)*SUMPRODUCT(IFERROR((($C$4="Todos")+(YEAR('GESTAO OPERACAO'!$H$2:$H$632)=$C$4)>0)*('GESTAO OPERACAO'!$H$2:$H$632>0)*(MONTH('GESTAO OPERACAO'!$H$2:$H$632)=3)*((INT((DAY('GESTAO OPERACAO'!$H$2:$H$632)+WEEKDAY(DATE(YEAR('GESTAO OPERACAO'!$H$2:$H$632),3,1),2)-2)/7)+1)=3)*('GESTAO OPERACAO'!$P$2:$P$632*1),0))} -> 1874789.1
B42: Março | C42: Semana 4 | D42: =IF($C$4="Todos","Semana 4",IF(((DATE($C$4,3,1)+MOD(7-WEEKDAY(DATE($C$4,3,1),2),7)+1)+14)>EOMONTH(DATE($C$4,3,1),0),"-",TEXT(((DATE($C$4,3,1)+MOD(7-WEEKDAY(DATE($C$4,3,1),2),7)+1)+14),"dd/mm")&" - "&TEXT(MIN(((DATE($C$4,3,1)+MOD(7-WEEKDAY(DATE($C$4,3,1),2),7)+1)+14)+6,EOMONTH(DATE($C$4,3,1),0)),"dd/mm"))) -> 16/03 - 22/03 | E42: {=(($E$4="Todos")+($E$4="Março")>0)*SUMPRODUCT(IFERROR((($C$4="Todos")+(YEAR('GESTAO OPERACAO'!$H$2:$H$632)=$C$4)>0)*('GESTAO OPERACAO'!$H$2:$H$632>0)*(MONTH('GESTAO OPERACAO'!$H$2:$H$632)=3)*((INT((DAY('GESTAO OPERACAO'!$H$2:$H$632)+WEEKDAY(DATE(YEAR('GESTAO OPERACAO'!$H$2:$H$632),3,1),2)-2)/7)+1)=4),0))} -> 11 | F42: {=(($E$4="Todos")+($E$4="Março")>0)*SUMPRODUCT(IFERROR((($C$4="Todos")+(YEAR('GESTAO OPERACAO'!$H$2:$H$632)=$C$4)>0)*('GESTAO OPERACAO'!$H$2:$H$632>0)*(MONTH('GESTAO OPERACAO'!$H$2:$H$632)=3)*((INT((DAY('GESTAO OPERACAO'!$H$2:$H$632)+WEEKDAY(DATE(YEAR('GESTAO OPERACAO'!$H$2:$H$632),3,1),2)-2)/7)+1)=4)*('GESTAO OPERACAO'!$P$2:$P$632*1),0))} -> 149303.85
